Workbook
Name SegmentaçãodeDados_ANO_EMISSOR1: #N/A
Name SegmentaçãodeDados_CARTEIRA1: #N/A
Name SegmentaçãodeDados_Cobrança: #N/A
Name SegmentaçãodeDados_Cobrança1: #N/A
Name SegmentaçãodeDados_EMPRESA: #N/A
Name SegmentaçãodeDados_EMPRESA2: #N/A
Name SegmentaçãodeDados_GRUPO2: #N/A
Name SegmentaçãodeDados_MÊS_EMISSOR1: #N/A
Name SegmentaçãodeDados_Status_de_Cobrança: #N/A
Name SegmentaçãodeDados_Status_de_Pagamento: #N/A
Name SegmentaçãodeDados_UNIDADE2: #N/A
Name SegmentaçãodeDados_VENDEDORES1: #N/A

Sheet OBSERVAÇÕES
B1: OBSERVAÇÕES
A3: 1 | B3: OS IMPUTS DEVERÃO SER LANÇADOS NA ABA "DADOS FINANCEIROS"
A5: 2 | B5: ATUALIZAÇÃO DA PLANILHA IR EM "DADOS" e DEPOIS NO ÍCONE "ATUALIZAR TUDO"
A11: 3 | B11: OS FILTROS AVANÇADOS ESTÃO CONECTADOS NAS SEGUINTES ABAS
C12: DASHBOARD
C13: PAINEL
C14: DADOS FINANCEIROS - TABELA
C15: ACOMPANHAMENTO - TABELA
C16: STATUS NEGOCIAÇÃO - TABELA
B18: QUALQUER FILTRO SE COMUNICARÁ COM AS ABAS
A20: 4 | B20: O RELATÓRIO DE COBRANÇA NÃO TEM VÍNCULO COM AS OUTRAS ABAS NA PLANILHA E É PREENCHIDO MANUALMENTE

Sheet DADOS FINANCEIROS
B2: DATA ATUAL | C2: DIA SEMANA
B3: =TODAY() -> 45795 | C3: =TEXT(B3,"DDDD") -> domingo
A5: DADOS FINANCEIROS | L5: ACOMPANHAMENTO DA COBRANÇA | S5: STATUS DE NEGOCIAÇÃO
A7: UNIDADE | B7: GRUPO | C7: EMPRESA | D7: DOC./NF | E7: DATA DE EMISSÃO | F7: VENCIMENTO ORIGINAL | G7: VENCIMENTO ATUAL | H7: VALOR ORIGINAL | I7: VENDEDORES | J7: CARTEIRA | K7: PAGO | L7: Status de Cobrança | M7: Status de Pagamento | N7: Dias em Atraso | O7: Faixa de Atraso | P7: Título Elegível | Q7: Valor a Faturar | R7: Bloqueio de sistema | S7: Statuts de Negociação | T7: Número de Negociações Feitas | U7: Acordo Fechado? | V7: Data de Negociação | W7: Data da Entrada/Primeira Parcela | X7: Título Quitado? (Sim/Não) | Y7: Valores Vencidos | Z7: Valores a Vencer
A8: Filial | C8: BemEstar | D8: 52 | E8: 45311 | F8: 45313 | G8: 45314 | H8: 1400 | I8: Felipe | J8: ANALISTA LUCAS | K8: NÃO | L8: Promessa de pagamento não cumprida | M8: =IF(K8="Sim", "Quitado", IF(F8<($B$3), "Vencido", IF(F8>=($B$3), "A Vencer", ""))) -> Vencido | N8: =IF(K8="Sim", 0, IF(F8<($B$3), $B$3-F8, IF(F8>=($B$3), F8-$B$3, ""))) -> 482 | O8: =IF(OR(M8="Quitado",M8="A Vencer"),"",IF(N8<=30,"0-30 dias",IF(N8<=60,"31-60 dias","61+ dias"))) -> 61+ dias | P8: =IF(O8="0-30 dias", "Atraso Recente", IF(O8="31-60 dias", "Atraso Médio", IF(O8="61+ dias", "Atraso Crítico", ""))) -> Atraso Crítico | Q8: - | R8: Sim | T8: 1 | U8: Sim | V8: 45740 | W8: 45772 | X8: Acompanhando | Y8: =IF(M8="vencido",H8, "0") -> 1400 | Z8: =IF(M8="A vencer",H8, "0") -> 0
A9: Matriz | B9: Gamma & CIA | C9: Gamma & CIA | D9: 33 | E9: 45337 | G9: 45339 | H9: 2000 | I9: Luana | J9: ANALISTA GUSTAVO | K9: NÃO | L9: Cliente em inadimplência sem previsão de pagamento | M9: =IF(K9="Sim", "Quitado", IF(F9<($B$3), "Vencido", IF(F9>=($B$3), "A Vencer", ""))) -> A Vencer | N9: =IF(K9="Sim", 0, IF(F9<($B$3), $B$3-F9, IF(F9>=($B$3), F9-$B$3, ""))) -> #VALUE! | O9: =IF(OR(M9="Quitado",M9="A Vencer"),"",IF(N9<=30,"0-30 dias",IF(N9<=60,"31-60 dias","61+ dias"))) | P9: =IF(O9="0-30 dias", "Atraso Recente", IF(O9="31-60 dias", "Atraso Médio", IF(O9="61+ dias", "Atraso Crítico", ""))) | Q9: - | R9: Sim | T9: 1 | U9: Sim | V9: 45740 | W9: 45772 | X9: Acompanhando | Y9: =IF(M9="vencido",H9, "0") -> 0 | Z9: =IF(M9="A vencer",H9, "0") -> 2000
A10: Matriz | C10: BemEstar | D10: 34 | E10: 45658 | F10: 45689 | G10: 45737 | H10: 2000 | I10: Luana | J10: ANALISTA GUSTAVO | K10: NÃO | L10: Pagamento em processo (aguardando confirmação bancária) | M10: =IF(K10="Sim", "Quitado", IF(F10<($B$3), "Vencido", IF(F10>=($B$3), "A Vencer", ""))) -> Vencido | N10: =IF(K10="Sim", 0, IF(F10<($B$3), $B$3-F10, IF(F10>=($B$3), F10-$B$3, ""))) -> 106 | O10: =IF(OR(M10="Quitado",M10="A Vencer"),"",IF(N10<=30,"0-30 dias",IF(N10<=60,"31-60 dias","61+ dias"))) -> 61+ dias | P10: =IF(O10="0-30 dias", "Atraso Recente", IF(O10="31-60 dias", "Atraso Médio", IF(O10="61+ dias", "Atraso Crítico", ""))) -> Atraso Crítico | Q10: - | R10: Sim | T10: 1 | U10: Sim | V10: 45740 | W10: 45772 | X10: Acompanhando | Y10: =IF(M10="vencido",H10, "0") -> 2000 | Z10: =IF(M10="A vencer",H10, "0") -> 0
A11: Matriz | B11: Alpha & CIA | C11: Alpha & CIA | D11: 1 | E11: 45658 | F11: 45690 | G11: 45737 | H11: 1000 | I11: João | J11: ANALISTA SIMONE | K11: NÃO | L11: Situação com comercial (aguardando análise comercial) | M11: =IF(K11="Sim", "Quitado", IF(F11<($B$3), "Vencido", IF(F11>=($B$3), "A Vencer", ""))) -> Vencido | N11: =IF(K11="Sim", 0, IF(F11<($B$3), $B$3-F11, IF(F11>=($B$3), F11-$B$3, ""))) -> 105 | O11: =IF(OR(M11="Quitado",M11="A Vencer"),"",IF(N11<=30,"0-30 dias",IF(N11<=60,"31-60 dias","61+ dias"))) -> 61+ dias | P11: =IF(O11="0-30 dias", "Atraso Recente", IF(O11="31-60 dias", "Atraso Médio", IF(O11="61+ dias", "Atraso Crítico", ""))) -> Atraso Crítico | Q11: - | R11: Sim | T11: 1 | U11: Sim | V11: 45740 | W11: 45772 | X11: Acompanhando | Y11: =IF(M11="vencido",H11, "0") -> 1000 | Z11: =IF(M11="A vencer",H11, "0") -> 0
A12: Matriz | B12: Alpha & CIA | C12: Beta | D12: 2 | E12: 45658 | F12: 45690 | G12: 45737 | H12: 1000 | I12: João | J12: ANALISTA SIMONE | K12: NÃO | L12: Aguardando aprovação de crédito | M12: =IF(K12="Sim", "Quitado", IF(F12<($B$3), "Vencido", IF(F12>=($B$3), "A Vencer", ""))) -> Vencido | N12: =IF(K12="Sim", 0, IF(F12<($B$3), $B$3-F12, IF(F12>=($B$3), F12-$B$3, ""))) -> 105 | O12: =IF(OR(M12="Quitado",M12="A Vencer"),"",IF(N12<=30,"0-30 dias",IF(N12<=60,"31-60 dias","61+ dias"))) -> 61+ dias | P12: =IF(O12="0-30 dias", "Atraso Recente", IF(O12="31-60 dias", "Atraso Médio", IF(O12="61+ dias", "Atraso Crítico", ""))) -> Atraso Crítico | Q12: - | R12: Sim | T12: 1 | U12: Sim | V12: 45740 | W12: 45802 | X12: Acompanhando | Y12: =IF(M12="vencido",H12, "0") -> 1000 | Z12: =IF(M12="A vencer",H12, "0") -> 0
A13: Filial | B13: Alpha & CIA | C13: Delta | D13: 3 | E13: 45659 | F13: 45690 | G13: 45737 | H13: 2500 | I13: Maria | J13: ANALISTA SIMONE | K13: NÃO | L13: Cliente não localizado | M13: =IF(K13="Sim", "Quitado", IF(F13<($B$3), "Vencido", IF(F13>=($B$3), "A Vencer", ""))) -> Vencido | N13: =IF(K13="Sim", 0, IF(F13<($B$3), $B$3-F13, IF(F13>=($B$3), F13-$B$3, ""))) -> 105 | O13: =IF(OR(M13="Quitado",M13="A Vencer"),"",IF(N13<=30,"0-30 dias",IF(N13<=60,"31-60 dias","61+ dias"))) -> 61+ dias | P13: =IF(O13="0-30 dias", "Atraso Recente", IF(O13="31-60 dias", "Atraso Médio", IF(O13="61+ dias", "Atraso Crítico", ""))) -> Atraso Crítico | Q13: - | R13: Sim | T13: 1 | U13: Sim | V13: 45740 | W13: 45802 | X13: Acompanhando | Y13: =IF(M13="vencido",H13, "0") -> 2500 | Z13: =IF(M13="A vencer",H13, "0") -> 0
A14: Filial | B14: Alpha & CIA | C14: Delta | D14: 4 | E14: 45659 | F14: 45690 | G14: 45737 | H14: 2500 | I14: Maria | J14: ANALISTA SIMONE | K14: NÃO | L14: Promessa de pagamento refeito | M14: =IF(K14="Sim", "Quitado", IF(F14<($B$3), "Vencido", IF(F14>=($B$3), "A Vencer", ""))) -> Vencido | N14: =IF(K14="Sim", 0, IF(F14<($B$3), $B$3-F14, IF(F14>=($B$3), F14-$B$3, ""))) -> 105 | O14: =IF(OR(M14="Quitado",M14="A Vencer"),"",IF(N14<=30,"0-30 dias",IF(N14<=60,"31-60 dias","61+ dias"))) -> 61+ dias | P14: =IF(O14="0-30 dias", "Atraso Recente", IF(O14="31-60 dias", "Atraso Médio", IF(O14="61+ dias", "Atraso Crítico", ""))) -> Atraso Crítico | Q14: - | R14: Sim | T14: 1 | U14: Sim | V14: 45740 | W14: 45802 | X14: Acompanhando | Y14: =IF(M14="vencido",H14, "0") -> 2500 | Z14: =IF(M14="A vencer",H14, "0") -> 0
A15: Matriz | B15: Alpha & CIA | C15: Theta | D15: 5 | E15: 45662 | F15: 45690 | G15: 45737 | H15: 3000 | I15: Carlos | J15: ANALISTA SIMONE | K15: NÃO | L15: Proposta de renegociação pendente | M15: =IF(K15="Sim", "Quitado", IF(F15<($B$3), "Vencido", IF(F15>=($B$3), "A Vencer", ""))) -> Vencido | N15: =IF(K15="Sim", 0, IF(F15<($B$3), $B$3-F15, IF(F15>=($B$3), F15-$B$3, ""))) -> 105 | O15: =IF(OR(M15="Quitado",M15="A Vencer"),"",IF(N15<=30,"0-30 dias",IF(N15<=60,"31-60 dias","61+ dias"))) -> 61+ dias | P15: =IF(O15="0-30 dias", "Atraso Recente", IF(O15="31-60 dias", "Atraso Médio", IF(O15="61+ dias", "Atraso Crítico", ""))) -> Atraso Crítico | Q15: - | R15: Sim | T15: 1 | U15: Sim | V15: 45740 | W15: 45802 | X15: Acompanhando | Y15: =IF(M15="vencido",H15, "0") -> 3000 | Z15: =IF(M15="A vencer",H15, "0") -> 0
A16: Matriz | B16: Alpha & CIA | C16: Zeta | D16: 6 | E16: 45662 | F16: 45690 | G16: 45737 | H16: 3000 | I16: Carlos | J16: ANALISTA SIMONE | K16: NÃO | L16: Bloqueio de sistema por inadimplência | M16: =IF(K16="Sim", "Quitado", IF(F16<($B$3), "Vencido", IF(F16>=($B$3), "A Vencer", ""))) -> Vencido | N16: =IF(K16="Sim", 0, IF(F16<($B$3), $B$3-F16, IF(F16>=($B$3), F16-$B$3, ""))) -> 105 | O16: =IF(OR(M16="Quitado",M16="A Vencer"),"",IF(N16<=30,"0-30 dias",IF(N16<=60,"31-60 dias","61+ dias"))) -> 61+ dias | P16: =IF(O16="0-30 dias", "Atraso Recente", IF(O16="31-60 dias", "Atraso Médio", IF(O16="61+ dias", "Atraso Crítico", ""))) -> Atraso Crítico | Q16: - | R16: Sim | T16: 1 | U16: Sim | V16: 45740 | W16: 45802 | X16: Acompanhando | Y16: =IF(M16="vencido",H16, "0") -> 3000 | Z16: =IF(M16="A vencer",H16, "0") -> 0
A17: Filial | C17: BemEstar | D17: 7 | E17: 45663 | F17: 45690 | G17: 45737 | H17: 1500 | I17: Ana | J17: ANALISTA SIMONE | K17: NÃO | L17: Acordo em andamento (aguardando pagamento) | M17: =IF(K17="Sim", "Quitado", IF(F17<($B$3), "Vencido", IF(F17>=($B$3), "A Vencer", ""))) -> Vencido | N17: =IF(K17="Sim", 0, IF(F17<($B$3), $B$3-F17, IF(F17>=($B$3), F17-$B$3, ""))) -> 105 | O17: =IF(OR(M17="Quitado",M17="A Vencer"),"",IF(N17<=30,"0-30 dias",IF(N17<=60,"31-60 dias","61+ dias"))) -> 61+ dias | P17: =IF(O17="0-30 dias", "Atraso Recente", IF(O17="31-60 dias", "Atraso Médio", IF(O17="61+ dias", "Atraso Crítico", ""))) -> Atraso Crítico | Q17: - | R17: Sim | T17: 1 | U17: Sim | V17: 45740 | W17: 45802 | X17: Acompanhando | Y17: =IF(M17="vencido",H17, "0") -> 1500 | Z17: =IF(M17="A vencer",H17, "0") -> 0
A18: Filial | C18: BemEstar | D18: 8 | E18: 45663 | F18: 45690 | G18: 45737 | H18: 1500 | I18: Ana | J18: ANALISTA SIMONE | K18: NÃO | L18: Negociação finalizada, pendente de pagamento | M18: =IF(K18="Sim", "Quitado", IF(F18<($B$3), "Vencido", IF(F18>=($B$3), "A Vencer", ""))) -> Vencido | N18: =IF(K18="Sim", 0, IF(F18<($B$3), $B$3-F18, IF(F18>=($B$3), F18-$B$3, ""))) -> 105 | O18: =IF(OR(M18="Quitado",M18="A Vencer"),"",IF(N18<=30,"0-30 dias",IF(N18<=60,"31-60 dias","61+ dias"))) -> 61+ dias | P18: =IF(O18="0-30 dias", "Atraso Recente", IF(O18="31-60 dias", "Atraso Médio", IF(O18="61+ dias", "Atraso Crítico", ""))) -> Atraso Crítico | Q18: - | R18: Sim | T18: 1 | U18: Sim | V18: 45740 | W18: 45802 | X18: Acompanhando | Y18: =IF(M18="vencido",H18, "0") -> 1500 | Z18: =IF(M18="A vencer",H18, "0") -> 0
A19: Matriz | C19: BemEstar | D19: 9 | E19: 45667 | F19: 45698 | G19: 45737 | H19: 2200 | I19: Beatriz | J19: ANALISTA SIMONE | K19: NÃO | L19: Cliente em processo de análise para reativação | M19: =IF(K19="Sim", "Quitado", IF(F19<($B$3), "Vencido", IF(F19>=($B$3), "A Vencer", ""))) -> Vencido | N19: =IF(K19="Sim", 0, IF(F19<($B$3), $B$3-F19, IF(F19>=($B$3), F19-$B$3, ""))) -> 97 | O19: =IF(OR(M19="Quitado",M19="A Vencer"),"",IF(N19<=30,"0-30 dias",IF(N19<=60,"31-60 dias","61+ dias"))) -> 61+ dias | P19: =IF(O19="0-30 dias", "Atraso Recente", IF(O19="31-60 dias", "Atraso Médio", IF(O19="61+ dias", "Atraso Crítico", ""))) -> Atraso Crítico | Q19: - | R19: Sim | T19: 1 | U19: Sim | V19: 45740 | W19: 45802 | X19: Acompanhando | Y19: =IF(M19="vencido",H19, "0") -> 2200 | Z19: =IF(M19="A vencer",H19, "0") -> 0
A20: Matriz | C20: BemEstar | D20: 10 | E20: 45667 | F20: 45699 | G20: 45737 | H20: 2200 | I20: Beatriz | J20: ANALISTA SIMONE | K20: NÃO | L20: Acordo cumprido parcialmente | M20: =IF(K20="Sim", "Quitado", IF(F20<($B$3), "Vencido", IF(F20>=($B$3), "A Vencer", ""))) -> Vencido | N20: =IF(K20="Sim", 0, IF(F20<($B$3), $B$3-F20, IF(F20>=($B$3), F20-$B$3, ""))) -> 96 | O20: =IF(OR(M20="Quitado",M20="A Vencer"),"",IF(N20<=30,"0-30 dias",IF(N20<=60,"31-60 dias","61+ dias"))) -> 61+ dias | P20: =IF(O20="0-30 dias", "Atraso Recente", IF(O20="31-60 dias", "Atraso Médio", IF(O20="61+ dias", "Atraso Crítico", ""))) -> Atraso Crítico | Q20: - | R20: Sim | T20: 1 | U20: Sim | V20: 45740 | W20: 45802 | X20: Acompanhando | Y20: =IF(M20="vencido",H20, "0") -> 2200 | Z20: =IF(M20="A vencer",H20, "0") -> 0
A21: Filial | C21: BemEstar | D21: 11 | E21: 45669 | F21: 45700 | G21: 45701 | H21: 1000 | I21: Lucas | J21: ANALISTA SIMONE | K21: NÃO | L21: Aguardando liberação do financeiro | M21: =IF(K21="Sim", "Quitado", IF(F21<($B$3), "Vencido", IF(F21>=($B$3), "A Vencer", ""))) -> Vencido | N21: =IF(K21="Sim", 0, IF(F21<($B$3), $B$3-F21, IF(F21>=($B$3), F21-$B$3, ""))) -> 95 | O21: =IF(OR(M21="Quitado",M21="A Vencer"),"",IF(N21<=30,"0-30 dias",IF(N21<=60,"31-60 dias","61+ dias"))) -> 61+ dias | P21: =IF(O21="0-30 dias", "Atraso Recente", IF(O21="31-60 dias", "Atraso Médio", IF(O21="61+ dias", "Atraso Crítico", ""))) -> Atraso Crítico | Q21: - | R21: Sim | T21: 1 | U21: Sim | V21: 45740 | W21: 45802 | X21: Acompanhando | Y21: =IF(M21="vencido",H21, "0") -> 1000 | Z21: =IF(M21="A vencer",H21, "0") -> 0
A22: Filial | C22: MundoInovador | D22: 12 | E22: 45669 | F22: 45701 | G22: 45737 | H22: 1000 | I22: Lucas | J22: ANALISTA SIMONE | K22: NÃO | L22: Pagamento em processo (aguardando confirmação bancária) | M22: =IF(K22="Sim", "Quitado", IF(F22<($B$3), "Vencido", IF(F22>=($B$3), "A Vencer", ""))) -> Vencido | N22: =IF(K22="Sim", 0, IF(F22<($B$3), $B$3-F22, IF(F22>=($B$3), F22-$B$3, ""))) -> 94 | O22: =IF(OR(M22="Quitado",M22="A Vencer"),"",IF(N22<=30,"0-30 dias",IF(N22<=60,"31-60 dias","61+ dias"))) -> 61+ dias | P22: =IF(O22="0-30 dias", "Atraso Recente", IF(O22="31-60 dias", "Atraso Médio", IF(O22="61+ dias", "Atraso Crítico", ""))) -> Atraso Crítico | Q22: - | R22: Sim | T22: 1 | U22: Sim | V22: 45740 | W22: 45802 | X22: Acompanhando | Y22: =IF(M22="vencido",H22, "0") -> 1000 | Z22: =IF(M22="A vencer",H22, "0") -> 0
A23: Matriz | B23: Alpha & CIA | C23: Alpha & CIA | D23: 13 | E23: 45672 | F23: 45702 | G23: 45737 | H23: 1500 | I23: Carla | J23: ANALISTA SIMONE | K23: NÃO | L23: Cliente em inadimplência sem previsão de pagamento | M23: =IF(K23="Sim", "Quitado", IF(F23<($B$3), "Vencido", IF(F23>=($B$3), "A Vencer", ""))) -> Vencido | N23: =IF(K23="Sim", 0, IF(F23<($B$3), $B$3-F23, IF(F23>=($B$3), F23-$B$3, ""))) -> 93 | O23: =IF(OR(M23="Quitado",M23="A Vencer"),"",IF(N23<=30,"0-30 dias",IF(N23<=60,"31-60 dias","61+ dias"))) -> 61+ dias | P23: =IF(O23="0-30 dias", "Atraso Recente", IF(O23="31-60 dias", "Atraso Médio", IF(O23="61+ dias", "Atraso Crítico", ""))) -> Atraso Crítico | Q23: - | R23: Sim | T23: 1 | U23: Sim | V23: 45740 | W23: 45802 | X23: Acompanhando | Y23: =IF(M23="vencido",H23, "0") -> 1500 | Z23: =IF(M23="A vencer",H23, "0") -> 0
A24: Matriz | C24: MundoInovador | D24: 14 | E24: 45672 | F24: 45703 | G24: 45737 | H24: 1500 | I24: Carla | J24: ANALISTA SIMONE | K24: NÃO | L24: Pagamento em processo (aguardando confirmação bancária) | M24: =IF(K24="Sim", "Quitado", IF(F24<($B$3), "Vencido", IF(F24>=($B$3), "A Vencer", ""))) -> Vencido | N24: =IF(K24="Sim", 0, IF(F24<($B$3), $B$3-F24, IF(F24>=($B$3), F24-$B$3, ""))) -> 92 | O24: =IF(OR(M24="Quitado",M24="A Vencer"),"",IF(N24<=30,"0-30 dias",IF(N24<=60,"31-60 dias","61+ dias"))) -> 61+ dias | P24: =IF(O24="0-30 dias", "Atraso Recente", IF(O24="31-60 dias", "Atraso Médio", IF(O24="61+ dias", "Atraso Crítico", ""))) -> Atraso Crítico | Q24: - | R24: Sim | T24: 1 | U24: Sim | V24: 45740 | W24: 45802 | X24: Acompanhando | Y24: =IF(M24="vencido",H24, "0") -> 1500 | Z24: =IF(M24="A vencer",H24, "0") -> 0
A25: Filial | B25: Alpha & CIA | C25: Alpha & CIA | D25: 15 | E25: 45675 | F25: 45704 | G25: 45737 | H25: 3000 | I25: Roberto | J25: ANALISTA SIMONE | K25: NÃO | L25: Situação jurídica em andamento (em processo judicial) | M25: =IF(K25="Sim", "Quitado", IF(F25<($B$3), "Vencido", IF(F25>=($B$3), "A Vencer", ""))) -> Vencido | N25: =IF(K25="Sim", 0, IF(F25<($B$3), $B$3-F25, IF(F25>=($B$3), F25-$B$3, ""))) -> 91 | O25: =IF(OR(M25="Quitado",M25="A Vencer"),"",IF(N25<=30,"0-30 dias",IF(N25<=60,"31-60 dias","61+ dias"))) -> 61+ dias | P25: =IF(O25="0-30 dias", "Atraso Recente", IF(O25="31-60 dias", "Atraso Médio", IF(O25="61+ dias", "Atraso Crítico", ""))) -> Atraso Crítico | Q25: - | R25: Sim | T25: 1 | U25: Sim | V25: 45740 | W25: 45802 | X25: Acompanhando | Y25: =IF(M25="vencido",H25, "0") -> 3000 | Z25: =IF(M25="A vencer",H25, "0") -> 0
A26: Filial | C26: MundoInovador | D26: 16 | E26: 45675 | F26: 45705 | G26: 45737 | H26: 3000 | I26: Roberto | J26: ANALISTA SIMONE | K26: NÃO | L26: Cancelamento de cobrança solicitado | M26: =IF(K26="Sim", "Quitado", IF(F26<($B$3), "Vencido", IF(F26>=($B$3), "A Vencer", ""))) -> Vencido | N26: =IF(K26="Sim", 0, IF(F26<($B$3), $B$3-F26, IF(F26>=($B$3), F26-$B$3, ""))) -> 90 | O26: =IF(OR(M26="Quitado",M26="A Vencer"),"",IF(N26<=30,"0-30 dias",IF(N26<=60,"31-60 dias","61+ dias"))) -> 61+ dias | P26: =IF(O26="0-30 dias", "Atraso Recente", IF(O26="31-60 dias", "Atraso Médio", IF(O26="61+ dias", "Atraso Crítico", ""))) -> Atraso Crítico | Q26: - | R26: Sim | T26: 1 | U26: Sim | V26: 45740 | W26: 45802 | X26: Acompanhando | Y26: =IF(M26="vencido",H26, "0") -> 3000 | Z26: =IF(M26="A vencer",H26, "0") -> 0
A27: Matriz | B27: Alpha & CIA | C27: Alpha & CIA | D27: 17 | E27: 45677 | F27: 45706 | G27: 45737 | H27: 2800 | I27: Juliana | J27: ANALISTA SIMONE | K27: NÃO | L27: Cliente alegando dificuldades financeiras | M27: =IF(K27="Sim", "Quitado", IF(F27<($B$3), "Vencido", IF(F27>=($B$3), "A Vencer", ""))) -> Vencido | N27: =IF(K27="Sim", 0, IF(F27<($B$3), $B$3-F27, IF(F27>=($B$3), F27-$B$3, ""))) -> 89 | O27: =IF(OR(M27="Quitado",M27="A Vencer"),"",IF(N27<=30,"0-30 dias",IF(N27<=60,"31-60 dias","61+ dias"))) -> 61+ dias | P27: =IF(O27="0-30 dias", "Atraso Recente", IF(O27="31-60 dias", "Atraso Médio", IF(O27="61+ dias", "Atraso Crítico", ""))) -> Atraso Crítico | Q27: - | R27: Sim | T27: 1 | U27: Sim | V27: 45740 | W27: 45802 | X27: Acompanhando | Y27: =IF(M27="vencido",H27, "0") -> 2800 | Z27: =IF(M27="A vencer",H27, "0") -> 0
A28: Matriz | C28: MundoInovador | D28: 18 | E28: 45677 | F28: 45707 | G28: 45737 | H28: 2800 | I28: Juliana | J28: ANALISTA SIMONE | K28: NÃO | L28: Aguardando resolução interna da empresa | M28: =IF(K28="Sim", "Quitado", IF(F28<($B$3), "Vencido", IF(F28>=($B$3), "A Vencer", ""))) -> Vencido | N28: =IF(K28="Sim", 0, IF(F28<($B$3), $B$3-F28, IF(F28>=($B$3), F28-$B$3, ""))) -> 88 | O28: =IF(OR(M28="Quitado",M28="A Vencer"),"",IF(N28<=30,"0-30 dias",IF(N28<=60,"31-60 dias","61+ dias"))) -> 61+ dias | P28: =IF(O28="0-30 dias", "Atraso Recente", IF(O28="31-60 dias", "Atraso Médio", IF(O28="61+ dias", "Atraso Crítico", ""))) -> Atraso Crítico | Q28: - | R28: Sim | T28: 1 | U28: Sim | V28: 45740 | W28: 45802 | X28: Acompanhando | Y28: =IF(M28="vencido",H28, "0") -> 2800 | Z28: =IF(M28="A vencer",H28, "0") -> 0
A29: Filial | B29: Alpha & CIA | C29: Alpha & CIA | D29: 19 | E29: 45682 | F29: 45708 | G29: 45737 | H29: 1200 | I29: Gustavo | J29: ANALISTA SIMONE | K29: NÃO | L29: Promessa de pagamento não cumprida | M29: =IF(K29="Sim", "Quitado", IF(F29<($B$3), "Vencido", IF(F29>=($B$3), "A Vencer", ""))) -> Vencido | N29: =IF(K29="Sim", 0, IF(F29<($B$3), $B$3-F29, IF(F29>=($B$3), F29-$B$3, ""))) -> 87 | O29: =IF(OR(M29="Quitado",M29="A Vencer"),"",IF(N29<=30,"0-30 dias",IF(N29<=60,"31-60 dias","61+ dias"))) -> 61+ dias | P29: =IF(O29="0-30 dias", "Atraso Recente", IF(O29="31-60 dias", "Atraso Médio", IF(O29="61+ dias", "Atraso Crítico", ""))) -> Atraso Crítico | Q29: - | R29: Sim | T29: 1 | U29: Sim | V29: 45740 | W29: 45802 | X29: Acompanhando | Y29: =IF(M29="vencido",H29, "0") -> 1200 | Z29: =IF(M29="A vencer",H29, "0") -> 0
A30: Matriz | B30: Gamma & CIA | C30: Gamma & CIA | D30: 21 | E30: 45689 | F30: 45708 | G30: 45708 | H30: 2500 | I30: Fernanda | J30: ANALISTA SIMONE | K30: NÃO | L30: Acordo de pagamento pendente | M30: =IF(K30="Sim", "Quitado", IF(F30<($B$3), "Vencido", IF(F30>=($B$3), "A Vencer", ""))) -> Vencido | N30: =IF(K30="Sim", 0, IF(F30<($B$3), $B$3-F30, IF(F30>=($B$3), F30-$B$3, ""))) -> 87 | O30: =IF(OR(M30="Quitado",M30="A Vencer"),"",IF(N30<=30,"0-30 dias",IF(N30<=60,"31-60 dias","61+ dias"))) -> 61+ dias | P30: =IF(O30="0-30 dias", "Atraso Recente", IF(O30="31-60 dias", "Atraso Médio", IF(O30="61+ dias", "Atraso Crítico", ""))) -> Atraso Crítico | Q30: - | R30: Sim | T30: 1 | U30: Sim | V30: 45740 | W30: 45802 | X30: Acompanhando | Y30: =IF(M30="vencido",H30, "0") -> 2500 | Z30: =IF(M30="A vencer",H30, "0") -> 0
A31: Filial | C31: MundoInovador | D31: 20 | E31: 45682 | F31: 45709 | G31: 45709 | H31: 1200 | I31: Gustavo | J31: ANALISTA SIMONE | K31: NÃO | L31: Situação com comercial (aguardando análise comercial) | M31: =IF(K31="Sim", "Quitado", IF(F31<($B$3), "Vencido", IF(F31>=($B$3), "A Vencer", ""))) -> Vencido | N31: =IF(K31="Sim", 0, IF(F31<($B$3), $B$3-F31, IF(F31>=($B$3), F31-$B$3, ""))) -> 86 | O31: =IF(OR(M31="Quitado",M31="A Vencer"),"",IF(N31<=30,"0-30 dias",IF(N31<=60,"31-60 dias","61+ dias"))) -> 61+ dias | P31: =IF(O31="0-30 dias", "Atraso Recente", IF(O31="31-60 dias", "Atraso Médio", IF(O31="61+ dias", "Atraso Crítico", ""))) -> Atraso Crítico | Q31: - | R31: Sim | T31: 1 | U31: Sim | V31: 45740 | W31: 45802 | X31: Acompanhando | Y31: =IF(M31="vencido",H31, "0") -> 1200 | Z31: =IF(M31="A vencer",H31, "0") -> 0
A32: Matriz | C32: MundoInovador | D32: 22 | E32: 45689 | F32: 45709 | G32: 45709 | H32: 2500 | I32: Fernanda | J32: ANALISTA SIMONE | K32: NÃO | L32: Aguardando aprovação de crédito | M32: =IF(K32="Sim", "Quitado", IF(F32<($B$3), "Vencido", IF(F32>=($B$3), "A Vencer", ""))) -> Vencido | N32: =IF(K32="Sim", 0, IF(F32<($B$3), $B$3-F32, IF(F32>=($B$3), F32-$B$3, ""))) -> 86 | O32: =IF(OR(M32="Quitado",M32="A Vencer"),"",IF(N32<=30,"0-30 dias",IF(N32<=60,"31-60 dias","61+ dias"))) -> 61+ dias | P32: =IF(O32="0-30 dias", "Atraso Recente", IF(O32="31-60 dias", "Atraso Médio", IF(O32="61+ dias", "Atraso Crítico", ""))) -> Atraso Crítico | Q32: - | R32: Sim | T32: 1 | U32: Sim | V32: 45740 | W32: 45802 | X32: Acompanhando | Y32: =IF(M32="vencido",H32, "0") -> 2500 | Z32: =IF(M32="A vencer",H32, "0") -> 0
A33: Filial | B33: Gamma & CIA | C33: Gamma & CIA | D33: 23 | E33: 45690 | F33: 45710 | G33: 45710 | H33: 3000 | I33: Felipe | J33: ANALISTA SIMONE | K33: NÃO | L33: Cliente não localizado | M33: =IF(K33="Sim", "Quitado", IF(F33<($B$3), "Vencido", IF(F33>=($B$3), "A Vencer", ""))) -> Vencido | N33: =IF(K33="Sim", 0, IF(F33<($B$3), $B$3-F33, IF(F33>=($B$3), F33-$B$3, ""))) -> 85 | O33: =IF(OR(M33="Quitado",M33="A Vencer"),"",IF(N33<=30,"0-30 dias",IF(N33<=60,"31-60 dias","61+ dias"))) -> 61+ dias | P33: =IF(O33="0-30 dias", "Atraso Recente", IF(O33="31-60 dias", "Atraso Médio", IF(O33="61+ dias", "Atraso Crítico", ""))) -> Atraso Crítico | Q33: - | R33: Sim | T33: 1 | U33: Sim | V33: 45740 | W33: 45740 | X33: Acompanhando | Y33: =IF(M33="vencido",H33, "0") -> 3000 | Z33: =IF(M33="A vencer",H33, "0") -> 0
A34: Filial | C34: MundoInovador | D34: 24 | E34: 45690 | F34: 45711 | G34: 45711 | H34: 3000 | I34: Felipe | J34: ANALISTA GUSTAVO | K34: NÃO | L34: Promessa de pagamento refeito | M34: =IF(K34="Sim", "Quitado", IF(F34<($B$3), "Vencido", IF(F34>=($B$3), "A Vencer", ""))) -> Vencido | N34: =IF(K34="Sim", 0, IF(F34<($B$3), $B$3-F34, IF(F34>=($B$3), F34-$B$3, ""))) -> 84 | O34: =IF(OR(M34="Quitado",M34="A Vencer"),"",IF(N34<=30,"0-30 dias",IF(N34<=60,"31-60 dias","61+ dias"))) -> 61+ dias | P34: =IF(O34="0-30 dias", "Atraso Recente", IF(O34="31-60 dias", "Atraso Médio", IF(O34="61+ dias", "Atraso Crítico", ""))) -> Atraso Crítico | Q34: - | R34: Sim | T34: 1 | U34: Sim | V34: 45740 | W34: 45740 | X34: Acompanhando | Y34: =IF(M34="vencido",H34, "0") -> 3000 | Z34: =IF(M34="A vencer",H34, "0") -> 0
A35: Matriz | B35: Gamma & CIA | C35: Gamma & CIA | D35: 25 | E35: 45693 | F35: 45712 | G35: 45712 | H35: 1200 | I35: Camila | J35: ANALISTA GUSTAVO | K35: NÃO | L35: Proposta de renegociação pendente | M35: =IF(K35="Sim", "Quitado", IF(F35<($B$3), "Vencido", IF(F35>=($B$3), "A Vencer", ""))) -> Vencido | N35: =IF(K35="Sim", 0, IF(F35<($B$3), $B$3-F35, IF(F35>=($B$3), F35-$B$3, ""))) -> 83 | O35: =IF(OR(M35="Quitado",M35="A Vencer"),"",IF(N35<=30,"0-30 dias",IF(N35<=60,"31-60 dias","61+ dias"))) -> 61+ dias | P35: =IF(O35="0-30 dias", "Atraso Recente", IF(O35="31-60 dias", "Atraso Médio", IF(O35="61+ dias", "Atraso Crítico", ""))) -> Atraso Crítico | Q35: - | R35: Sim | T35: 1 | U35: Sim | V35: 45740 | W35: 45740 | X35: Acompanhando | Y35: =IF(M35="vencido",H35, "0") -> 1200 | Z35: =IF(M35="A vencer",H35, "0") -> 0
A36: Matriz | C36: MundoInovador | D36: 26 | E36: 45693 | F36: 45713 | G36: 45713 | H36: 1200 | I36: Camila | J36: ANALISTA GUSTAVO | K36: NÃO | L36: Bloqueio de sistema por inadimplência | M36: =IF(K36="Sim", "Quitado", IF(F36<($B$3), "Vencido", IF(F36>=($B$3), "A Vencer", ""))) -> Vencido | N36: =IF(K36="Sim", 0, IF(F36<($B$3), $B$3-F36, IF(F36>=($B$3), F36-$B$3, ""))) -> 82 | O36: =IF(OR(M36="Quitado",M36="A Vencer"),"",IF(N36<=30,"0-30 dias",IF(N36<=60,"31-60 dias","61+ dias"))) -> 61+ dias | P36: =IF(O36="0-30 dias", "Atraso Recente", IF(O36="31-60 dias", "Atraso Médio", IF(O36="61+ dias", "Atraso Crítico", ""))) -> Atraso Crítico | Q36: - | R36: Sim | T36: 1 | U36: Sim | V36: 45740 | W36: 45740 | X36: Acompanhando | Y36: =IF(M36="vencido",H36, "0") -> 1200 | Z36: =IF(M36="A vencer",H36, "0") -> 0
A37: Filial | B37: Gamma & CIA | C37: Gamma & CIA | D37: 27 | E37: 45694 | F37: 45714 | G37: 45714 | H37: 2000 | I37: Patrícia | J37: ANALISTA GUSTAVO | K37: NÃO | L37: Acordo em andamento (aguardando pagamento) | M37: =IF(K37="Sim", "Quitado", IF(F37<($B$3), "Vencido", IF(F37>=($B$3), "A Vencer", ""))) -> Vencido | N37: =IF(K37="Sim", 0, IF(F37<($B$3), $B$3-F37, IF(F37>=($B$3), F37-$B$3, ""))) -> 81 | O37: =IF(OR(M37="Quitado",M37="A Vencer"),"",IF(N37<=30,"0-30 dias",IF(N37<=60,"31-60 dias","61+ dias"))) -> 61+ dias | P37: =IF(O37="0-30 dias", "Atraso Recente", IF(O37="31-60 dias", "Atraso Médio", IF(O37="61+ dias", "Atraso Crítico", ""))) -> Atraso Crítico | Q37: - | R37: Sim | T37: 1 | U37: Sim | V37: 45740 | W37: 45740 | X37: Acompanhando | Y37: =IF(M37="vencido",H37, "0") -> 2000 | Z37: =IF(M37="A vencer",H37, "0") -> 0
A38: Filial | C38: MundoInovador | D38: 28 | E38: 45694 | F38: 45715 | G38: 45715 | H38: 2000 | I38: Patrícia | J38: ANALISTA GUSTAVO | K38: NÃO | L38: Negociação finalizada, pendente de pagamento | M38: =IF(K38="Sim", "Quitado", IF(F38<($B$3), "Vencido", IF(F38>=($B$3), "A Vencer", ""))) -> Vencido | N38: =IF(K38="Sim", 0, IF(F38<($B$3), $B$3-F38, IF(F38>=($B$3), F38-$B$3, ""))) -> 80 | O38: =IF(OR(M38="Quitado",M38="A Vencer"),"",IF(N38<=30,"0-30 dias",IF(N38<=60,"31-60 dias","61+ dias"))) -> 61+ dias | P38: =IF(O38="0-30 dias", "Atraso Recente", IF(O38="31-60 dias", "Atraso Médio", IF(O38="61+ dias", "Atraso Crítico", ""))) -> Atraso Crítico | Q38: - | R38: Sim | T38: 1 | U38: Sim | V38: 45740 | W38: 45740 | X38: Acompanhando | Y38: =IF(M38="vencido",H38, "0") -> 2000 | Z38: =IF(M38="A vencer",H38, "0") -> 0
A39: Matriz | B39: Gamma & CIA | C39: Gamma & CIA | D39: 29 | E39: 45698 | F39: 45715 | G39: 45715 | H39: 3200 | I39: Tiago | J39: ANALISTA GUSTAVO | K39: NÃO | L39: Cliente em processo de análise para reativação | M39: =IF(K39="Sim", "Quitado", IF(F39<($B$3), "Vencido", IF(F39>=($B$3), "A Vencer", ""))) -> Vencido | N39: =IF(K39="Sim", 0, IF(F39<($B$3), $B$3-F39, IF(F39>=($B$3), F39-$B$3, ""))) -> 80 | O39: =IF(OR(M39="Quitado",M39="A Vencer"),"",IF(N39<=30,"0-30 dias",IF(N39<=60,"31-60 dias","61+ dias"))) -> 61+ dias | P39: =IF(O39="0-30 dias", "Atraso Recente", IF(O39="31-60 dias", "Atraso Médio", IF(O39="61+ dias", "Atraso Crítico", ""))) -> Atraso Crítico | Q39: - | R39: Sim | T39: 1 | U39: Sim | V39: 45740 | W39: 45740 | X39: Acompanhando | Y39: =IF(M39="vencido",H39, "0") -> 3200 | Z39: =IF(M39="A vencer",H39, "0") -> 0
A40: Matriz | C40: SoftLink | D40: 30 | E40: 45698 | F40: 45715 | G40: 45715 | H40: 3200 | I40: Tiago | J40: ANALISTA GUSTAVO | K40: NÃO | L40: Acordo cumprido parcialmente | M40: =IF(K40="Sim", "Quitado", IF(F40<($B$3), "Vencido", IF(F40>=($B$3), "A Vencer", ""))) -> Vencido | N40: =IF(K40="Sim", 0, IF(F40<($B$3), $B$3-F40, IF(F40>=($B$3), F40-$B$3, ""))) -> 80 | O40: =IF(OR(M40="Quitado",M40="A Vencer"),"",IF(N40<=30,"0-30 dias",IF(N40<=60,"31-60 dias","61+ dias"))) -> 61+ dias | P40: =IF(O40="0-30 dias", "Atraso Recente", IF(O40="31-60 dias", "Atraso Médio", IF(O40="61+ dias", "Atraso Crítico", ""))) -> Atraso Crítico | Q40: - | R40: Sim | T40: 1 | U40: Sim | V40: 45740 | W40: 45740 | X40: Acompanhando | Y40: =IF(M40="vencido",H40, "0") -> 3200 | Z40: =IF(M40="A vencer",H40, "0") -> 0
A41: Filial | B41: Gamma & CIA | C41: Gamma & CIA | D41: 31 | E41: 45700 | F41: 45715 | G41: 45715 | H41: 1500 | I41: André | J41: ANALISTA GUSTAVO | K41: NÃO | L41: Aguardando liberação do financeiro | M41: =IF(K41="Sim", "Quitado", IF(F41<($B$3), "Vencido", IF(F41>=($B$3), "A Vencer", ""))) -> Vencido | N41: =IF(K41="Sim", 0, IF(F41<($B$3), $B$3-F41, IF(F41>=($B$3), F41-$B$3, ""))) -> 80 | O41: =IF(OR(M41="Quitado",M41="A Vencer"),"",IF(N41<=30,"0-30 dias",IF(N41<=60,"31-60 dias","61+ dias"))) -> 61+ dias | P41: =IF(O41="0-30 dias", "Atraso Recente", IF(O41="31-60 dias", "Atraso Médio", IF(O41="61+ dias", "Atraso Crítico", ""))) -> Atraso Crítico | Q41: - | R41: Sim | T41: 1 | U41: Sim | V41: 45740 | W41: 45740 | X41: Acompanhando | Y41: =IF(M41="vencido",H41, "0") -> 1500 | Z41: =IF(M41="A vencer",H41, "0") -> 0
A42: Filial | C42: SoftLink | D42: 32 | E42: 45700 | F42: 45715 | G42: 45715 | H42: 1500 | I42: André | J42: ANALISTA GUSTAVO | K42: NÃO | L42: Pagamento em processo (aguardando confirmação bancária) | M42: =IF(K42="Sim", "Quitado", IF(F42<($B$3), "Vencido", IF(F42>=($B$3), "A Vencer", ""))) -> Vencido | N42: =IF(K42="Sim", 0, IF(F42<($B$3), $B$3-F42, IF(F42>=($B$3), F42-$B$3, ""))) -> 80 | O42: =IF(OR(M42="Quitado",M42="A Vencer"),"",IF(N42<=30,"0-30 dias",IF(N42<=60,"31-60 dias","61+ dias"))) -> 61+ dias | P42: =IF(O42="0-30 dias", "Atraso Recente", IF(O42="31-60 dias", "Atraso Médio", IF(O42="61+ dias", "Atraso Crítico", ""))) -> Atraso Crítico | Q42: - | R42: Sim | T42: 1 | U42: Sim | V42: 45740 | W42: 45740 | X42: Acompanhando | Y42: =IF(M42="vencido",H42, "0") -> 1500 | Z42: =IF(M42="A vencer",H42, "0") -> 0
A43: Filial | B43: Gamma & CIA | C43: Gamma & CIA | D43: 35 | E43: 45706 | F43: 45715 | G43: 45715 | H43: 1000 | I43: Pedro | J43: ANALISTA GUSTAVO | K43: NÃO | L43: Situação jurídica em andamento (em processo judicial) | M43: =IF(K43="Sim", "Quitado", IF(F43<($B$3), "Vencido", IF(F43>=($B$3), "A Vencer", ""))) -> Vencido | N43: =IF(K43="Sim", 0, IF(F43<($B$3), $B$3-F43, IF(F43>=($B$3), F43-$B$3, ""))) -> 80 | O43: =IF(OR(M43="Quitado",M43="A Vencer"),"",IF(N43<=30,"0-30 dias",IF(N43<=60,"31-60 dias","61+ dias"))) -> 61+ dias | P43: =IF(O43="0-30 dias", "Atraso Recente", IF(O43="31-60 dias", "Atraso Médio", IF(O43="61+ dias", "Atraso Crítico", ""))) -> Atraso Crítico | Q43: - | R43: Sim | T43: 1 | U43: Sim | V43: 45740 | W43: 45740 | X43: Acompanhando | Y43: =IF(M43="vencido",H43, "0") -> 1000 | Z43: =IF(M43="A vencer",H43, "0") -> 0
...

Sheet MÊS EMISSOR
A1: Rótulos de Linha | B1: Soma de VALOR ORIGINAL
A2: fev-24 | B2: 2000
A3: fev-25 | B3: 85500
A4: jan-00 | B4: 0
A5: jan-24 | B5: 1400
A6: jan-25 | B6: 43400
A7: mar-25 | B7: 17500
A8: Total Geral | B8: 149800

Sheet MÊS ORIGINAL
A1: Rótulos de Linha | B1: Soma de VALOR ORIGINAL
B2: 2000
A3: fev-25 | B3: 80200
A4: jan-00 | B4: 0
A5: jan-24 | B5: 1400
A6: jan-25 | B6: 2000
A7: mar-25 | B7: 64200
A8: Total Geral | B8: 149800

Sheet MÊS ATUAL
A1: Rótulos de Linha | B1: Soma de VALOR ORIGINAL
A2: fev-24 | B2: 2000
A3: fev-25 | B3: 41000
A4: jan-00 | B4: 0
A5: jan-24 | B5: 1400
A6: jan-25 | B6: 2000
A7: mar-25 | B7: 103400
A8: Total Geral | B8: 149800

Sheet CARTEIRA
A1: Rótulos de Linha | B1: Soma de VALOR ORIGINAL
A2: 0 | B2: 0
A3: ANALISTA GUSTAVO | B3: 54600
A4: ANALISTA LUCAS | B4: 45600
A5: ANALISTA SIMONE | B5: 49600
A6: Total Geral | B6: 149800

Sheet VENDEDORES
A1: Rótulos de Linha | B1: Soma de VALOR ORIGINAL
A2: 0 | B2: 0
A3: Ana | B3: 6900
A4: André | B4: 4800
A5: Beatriz | B5: 9000
A6: Camila | B6: 5100
A7: Carla | B7: 8700
A8: Carlos | B8: 10700
A9: Felipe | B9: 7400
A10: Fernanda | B10: 10900
A11: Gustavo | B11: 5900
A12: João | B12: 5300
A13: Juliana | B13: 8400
A14: Luana | B14: 6200
... A23: Total Geral | B23: 149800

Sheet VALORES VENCIDO
A1: Rótulos de Linha | B1: Soma de Valores Vencidos2
A2: abr-25 | B2: 48100
A3: jan-00 | B3: 0
A4: mai-25 | B4: 43400
A5: mar-25 | B5: 53600
A6: Total Geral | B6: 145100

Sheet TÍTULO ELEGÍVEL
A1: Rótulos de Linha | B1: Contagem de DOC./NF
A2: 0 | B2: 166
B3: 2
A4: Atraso Crítico | B4: 42
A5: Atraso Médio | B5: 28
A6: Total Geral | B6: 238

Sheet STATUS DE PAGAMENTO
A1: Rótulos de Linha | B1: Contagem de DOC./NF
A2: 0 | B2: 166
A3: A Vencer | B3: 1
A4: Quitado | B4: 1
A5: Vencido | B5: 70
A6: Total Geral | B6: 238

Sheet STATUS DE COBRANÇA
A1: Rótulos de Linha | B1: Contagem de DOC./NF
A2: 0 | B2: 166
A3: Acordo cumprido parcialmente | B3: 2
A4: Acordo de pagamento pendente | B4: 2
A5: Acordo em andamento (aguardando pagamento) | B5: 7
A6: Aguardando aprovação de crédito | B6: 2
A7: Aguardando liberação do financeiro | B7: 2
A8: Aguardando resolução interna da empresa | B8: 2
A9: Bloqueio de sistema por inadimplência | B9: 3
A10: Cancelamento de cobrança solicitado | B10: 2
A11: Cliente alegando dificuldades financeiras | B11: 2
A12: Cliente em inadimplência sem previsão de pagamento | B12: 2
A13: Cliente em processo de análise para reativação | B13: 2
A14: Cliente não localizado | B14: 3
... A23: Total Geral | B23: 238

Sheet UNIDADE
A1: Rótulos de Linha | B1: Soma de VALOR ORIGINAL | C1: Soma de VALOR ORIGINAL2
A2: 0 | B2: 0 | C2: 0
A3: Filial | B3: 69700 | C3: 0.46528705
A4: Matriz | B4: 80100 | C4: 0.53471295
A5: Total Geral | B5: 149800 | C5: 1

Sheet GRUPO
A1: Rótulos de Linha | B1: Soma de VALOR ORIGINAL | C1: Soma de VALOR ORIGINAL2
A2: 0 | B2: 104800 | C2: 0.69959947
A3: Alpha & CIA | B3: 24300 | C3: 0.16221629
A4: Gamma & CIA | B4: 20700 | C4: 0.13818425
A5: Total Geral | B5: 149800 | C5: 1

Sheet EMPRESA - QUANTIDADE
A1: Rótulos de Linha | B1: Soma de DOC./NF
A2: 0 | B2: 0
A3: Alpha & CIA | B3: 124
A4: BemEstar | B4: 131
A5: Beta | B5: 2
A6: Delta | B6: 7
A7: Gamma & CIA | B7: 300
A8: GlobalTech | B8: 521
A9: InvestPro | B9: 454
A10: MundoInovador | B10: 180
A11: NovaHorizonte | B11: 594
A12: SoftLink | B12: 304
A13: Theta | B13: 5
A14: Zeta | B14: 6
A15: Total Geral | B15: 2628

Sheet EMPRESA - VALORES
A1: Rótulos de Linha | B1: Soma de VALOR ORIGINAL | C1: Soma de VALOR ORIGINAL2
A2: 0 | B2: 0 | C2: 0
A3: Alpha & CIA | B3: 12300 | C3: 0.082109479
A4: BemEstar | B4: 11800 | C4: 0.078771696
A5: Beta | B5: 1000 | C5: 0.0066755674
A6: Delta | B6: 5000 | C6: 0.033377837
A7: Gamma & CIA | B7: 20700 | C7: 0.13818425
A8: GlobalTech | B8: 21000 | C8: 0.14018692
A9: InvestPro | B9: 17800 | C9: 0.1188251
A10: MundoInovador | B10: 18200 | C10: 0.12149533
A11: NovaHorizonte | B11: 19900 | C11: 0.13284379
A12: SoftLink | B12: 16100 | C12: 0.10747664
A13: Theta | B13: 3000 | C13: 0.020026702
A14: Zeta | B14: 3000 | C14: 0.020026702
A15: Total Geral | B15: 149800 | C15: 1

Sheet $ COBRANÇAS
A1: Rótulos de Linha | B1: Soma de Valores Vencidos | C1: Soma de Valores Vencidos2
A2: Cobrança Ativa | B2: 61500 | C2: 0.42384562
A3: Cobrança Extrajudicial | B3: 80200 | C3: 0.55272226
A4: Cobrança Amigável | B4: 0 | C4: 0
A5: Cobrança Judicial | B5: 3400 | C5: 0.023432116
B6: 0 | C6: 0
A7: Total Geral | B7: 145100 | C7: 1

Sheet QTDE COBRANÇAS
A1: Rótulos de Linha | B1: Contagem de Cobrança | C1: Contagem de Cobrança2
B2: 166 | C2: 0.69747899
A3: Cobrança Ativa | B3: 28 | C3: 0.11764706
A4: Cobrança Extrajudicial | B4: 40 | C4: 0.16806723
A5: Cobrança Amigável | B5: 1 | C5: 0.0042016807
A6: Cobrança Judicial | B6: 3 | C6: 0.012605042
A7: Total Geral | B7: 238 | C7: 1

Sheet DADOS FINANCEIROS - TABELA
J1: DADOS FINANCEIROS | V1: ACOMPANHAMENTO DA COBRANÇA | AG1: STATUS DA NEGOCIAÇÃO
B3: Rótulos de Linha | C3: =Tabela1[[#Headers],[DOC./NF]] -> DOC./NF | D3: =Tabela1[[#Headers],[UNIDADE]] -> UNIDADE | E3: =Tabela1[[#Headers],[GRUPO]] -> GRUPO | F3: =Tabela1[[#Headers],[EMPRESA]] -> EMPRESA | G3: =Tabela1[[#Headers],[DATA DE EMISSÃO]] -> DATA DE EMISSÃO | H3: =Tabela1[[#Headers],[MÊS EMISSOR]] -> MÊS EMISSOR | I3: =Tabela1[[#Headers],[ANO EMISSOR]] -> ANO EMISSOR | J3: =Tabela1[[#Headers],[VENCIMENTO ORIGINAL]] -> VENCIMENTO ORIGINAL | K3: =Tabela1[[#Headers],[MÊS VENCIMENTO ORIGINAL]] -> MÊS VENCIMENTO ORIGINAL | L3: =Tabela1[[#Headers],[ANO VENCIMENTO ORIGINAL]] -> ANO VENCIMENTO ORIGINAL | M3: =Tabela1[[#Headers],[VENCIMENTO ATUAL]] -> VENCIMENTO ATUAL | N3: =Tabela1[[#Headers],[MÊS ATUAL]] -> MÊS ATUAL | O3: =Tabela1[[#Headers],[ANO ATUAL]] -> ANO ATUAL | P3: =Tabela1[[#Headers],[VALOR ORIGINAL]] -> VALOR ORIGINAL | Q3: =Tabela1[[#Headers],[VENDEDORES]] -> VENDEDORES | R3: =Tabela1[[#Headers],[CARTEIRA]] -> CARTEIRA | S3: =Tabela1[[#Headers],[PAGO]] -> PAGO | T3: =Tabela1[[#Headers],[Status de Cobrança]] -> Status de Cobrança | U3: =Tabela1[[#Headers],[Status de Pagamento]] -> Status de Pagamento | V3: =Tabela1[[#Headers],[Dias em Atraso]] -> Dias em Atraso | W3: =Tabela1[[#Headers],[Faixa de Atraso]] -> Faixa de Atraso | X3: =Tabela1[[#Headers],[Título Elegível]] -> Título Elegível | Y3: =Tabela1[[#Headers],[Valor a Faturar]] -> Valor a Faturar | Z3: =Tabela1[[#Headers],[Bloqueio de sistema ]] -> Bloqueio de sistema | AA3: =Tabela1[[#Headers],[Statuts de Negociação]] -> Statuts de Negociação | AB3: =Tabela1[[#Headers],[Número de Negociações Feitas]] -> Número de Negociações Feitas | AC3: =Tabela1[[#Headers],[Acordo Fechado?]] -> Acordo Fechado? | AD3: =Tabela1[[#Headers],[Data de Negociação]] -> Data de Negociação | AE3: =Tabela1[[#Headers],[MÊS NEGOCIAÇÃO]] -> MÊS NEGOCIAÇÃO | AF3: =Tabela1[[#Headers],[ANO NEGOCIAÇÃO]] -> ANO NEGOCIAÇÃO | AG3: =Tabela1[[#Headers],[Data da Entrada/Primeira Parcela]] -> Data da Entrada/Primeira Parcela | AH3: =Tabela1[[#Headers],[MÊS PRIMEIRA PARCELA]] -> MÊS PRIMEIRA PARCELA | AI3: =Tabela1[[#Headers],[ANO PRIMERA PARCELA]] -> ANO PRIMERA PARCELA | AJ3: =Tabela1[[#Headers],[Título Quitado? (Sim/Não)]] -> Título Quitado? (Sim/Não) | AK3: =Tabela1[[#Headers],[Valores Vencidos]] -> Valores Vencidos | AL3: =Tabela1[[#Headers],[Cobrança3]] -> Cobrança3
B4: 0 | C4: =IF(B4="","",IFERROR(VLOOKUP(B4,'ANÁLISE DE DADOS'!$A:$AM,1,0),"")) -> 0 | D4: =IF(B4="","",IFERROR(VLOOKUP(B4,'ANÁLISE DE DADOS'!$A:$AM,2,0),"")) -> 0 | E4: =IF(B4="","",IFERROR(VLOOKUP(B4,'ANÁLISE DE DADOS'!$A:$AM,3,0),"")) -> 0 | F4: =IF(B4="","",IFERROR(VLOOKUP(B4,'ANÁLISE DE DADOS'!$A:$AM,4,0),"")) -> 0 | G4: =IF(B4="","",IFERROR(VLOOKUP(B4,'ANÁLISE DE DADOS'!$A:$AM,5,0),"")) -> 0 | H4: =IF(B4="","",IFERROR(VLOOKUP(B4,'ANÁLISE DE DADOS'!$A:$AM,6,0),"")) -> jan-00 | I4: =IF(B4="","",IFERROR(VLOOKUP(B4,'ANÁLISE DE DADOS'!$A:$AM,7,0),"")) -> 1900 | J4: =IF(B4="","",IFERROR(VLOOKUP(B4,'ANÁLISE DE DADOS'!$A:$AM,8,0),"")) -> 0 | K4: =IF(B4="","",IFERROR(VLOOKUP(B4,'ANÁLISE DE DADOS'!$A:$AM,9,0),"")) -> jan-00 | L4: =IF(B4="","",IFERROR(VLOOKUP(B4,'ANÁLISE DE DADOS'!$A:$AM,10,0),"")) -> 1900 | M4: =IF(B4="","",IFERROR(VLOOKUP(B4,'ANÁLISE DE DADOS'!$A:$AM,11,0),"")) -> 0 | N4: =IF(B4="","",IFERROR(VLOOKUP(B4,'ANÁLISE DE DADOS'!$A:$AM,12,0),"")) -> jan-00 | O4: =IF(B4="","",IFERROR(VLOOKUP(B4,'ANÁLISE DE DADOS'!$A:$AM,13,0),"")) -> 1900 | P4: =IF(B4="","",IFERROR(VLOOKUP(B4,'ANÁLISE DE DADOS'!$A:$AM,14,0),"")) -> 0 | Q4: =IF(B4="","",IFERROR(VLOOKUP(B4,'ANÁLISE DE DADOS'!$A:$AM,15,0),"")) -> 0 | R4: =IF(B4="","",IFERROR(VLOOKUP(B4,'ANÁLISE DE DADOS'!$A:$AM,16,0),"")) -> 0 | S4: =IF(B4="","",IFERROR(VLOOKUP(B4,'ANÁLISE DE DADOS'!$A:$AM,17,0),"")) -> 0 | T4: =IF(B4="","",IFERROR(VLOOKUP(B4,'ANÁLISE DE DADOS'!$A:$AM,18,0),"")) -> 0 | U4: =IF(B4="","",IFERROR(VLOOKUP(B4,'ANÁLISE DE DADOS'!$A:$AM,19,0),"")) -> 0 | V4: =IF(B4="","",IFERROR(VLOOKUP(B4,'ANÁLISE DE DADOS'!$A:$AM,20,0),"")) -> 0 | W4: =IF(B4="","",IFERROR(VLOOKUP(B4,'ANÁLISE DE DADOS'!$A:$AM,21,0),"")) -> 0 | X4: =IF(B4="","",IFERROR(VLOOKUP(B4,'ANÁLISE DE DADOS'!$A:$AM,22,0),"")) -> 0 | Y4: =IF(B4="","",IFERROR(VLOOKUP(B4,'ANÁLISE DE DADOS'!$A:$AM,23,0),"")) -> 0 | Z4: =IF(B4="","",IFERROR(VLOOKUP(B4,'ANÁLISE DE DADOS'!$A:$AM,24,0),"")) -> 0 | AA4: =IF(B4="","",IFERROR(VLOOKUP(B4,'ANÁLISE DE DADOS'!$A:$AM,25,0),"")) -> 0 | AB4: =IF(B4="","",IFERROR(VLOOKUP(B4,'ANÁLISE DE DADOS'!$A:$AM,26,0),"")) -> 0 | AC4: =IF(B4="","",IFERROR(VLOOKUP(B4,'ANÁLISE DE DADOS'!$A:$AM,27,0),"")) -> 0 | AD4: =IF(B4="","",IFERROR(VLOOKUP(B4,'ANÁLISE DE DADOS'!$A:$AM,28,0),"")) -> 0 | AE4: =IF(B4="","",IFERROR(VLOOKUP(B4,'ANÁLISE DE DADOS'!$A:$AM,29,0),"")) -> jan-00 | AF4: =IF(B4="","",IFERROR(VLOOKUP(B4,'ANÁLISE DE DADOS'!$A:$AM,30,0),"")) -> 1900 | AG4: =IF(B4="","",IFERROR(VLOOKUP(B4,'ANÁLISE DE DADOS'!$A:$AM,31,0),"")) -> 0 | AH4: =IF(B4="","",IFERROR(VLOOKUP(B4,'ANÁLISE DE DADOS'!$A:$AM,32,0),"")) -> jan-00 | AI4: =IF(B4="","",IFERROR(VLOOKUP(B4,'ANÁLISE DE DADOS'!$A:$AM,33,0),"")) -> 1900 | AJ4: =IF(B4="","",IFERROR(VLOOKUP(B4,'ANÁLISE DE DADOS'!$A:$AM,34,0),"")) -> 0 | AK4: =IF(B4="","",IFERROR(VLOOKUP(B4,'ANÁLISE DE DADOS'!$A:$AM,35,0),"")) -> 0 | AL4: =IF(B4="","",IFERROR(VLOOKUP(B4,'ANÁLISE DE DADOS'!$A:$AM,36,0),"")) -> 0
B5: 1 | C5: =IF(B5="","",IFERROR(VLOOKUP(B5,'ANÁLISE DE DADOS'!$A:$AM,1,0),"")) -> 1 | D5: =IF(B5="","",IFERROR(VLOOKUP(B5,'ANÁLISE DE DADOS'!$A:$AM,2,0),"")) -> Matriz | E5: =IF(B5="","",IFERROR(VLOOKUP(B5,'ANÁLISE DE DADOS'!$A:$AM,3,0),"")) -> Alpha & CIA | F5: =IF(B5="","",IFERROR(VLOOKUP(B5,'ANÁLISE DE DADOS'!$A:$AM,4,0),"")) -> Alpha & CIA | G5: =IF(B5="","",IFERROR(VLOOKUP(B5,'ANÁLISE DE DADOS'!$A:$AM,5,0),"")) -> 45658 | H5: =IF(B5="","",IFERROR(VLOOKUP(B5,'ANÁLISE DE DADOS'!$A:$AM,6,0),"")) -> jan-25 | I5: =IF(B5="","",IFERROR(VLOOKUP(B5,'ANÁLISE DE DADOS'!$A:$AM,7,0),"")) -> 2025 | J5: =IF(B5="","",IFERROR(VLOOKUP(B5,'ANÁLISE DE DADOS'!$A:$AM,8,0),"")) -> 45690 | K5: =IF(B5="","",IFERROR(VLOOKUP(B5,'ANÁLISE DE DADOS'!$A:$AM,9,0),"")) -> fev-25 | L5: =IF(B5="","",IFERROR(VLOOKUP(B5,'ANÁLISE DE DADOS'!$A:$AM,10,0),"")) -> 2025 | M5: =IF(B5="","",IFERROR(VLOOKUP(B5,'ANÁLISE DE DADOS'!$A:$AM,11,0),"")) -> 45737 | N5: =IF(B5="","",IFERROR(VLOOKUP(B5,'ANÁLISE DE DADOS'!$A:$AM,12,0),"")) -> mar-25 | O5: =IF(B5="","",IFERROR(VLOOKUP(B5,'ANÁLISE DE DADOS'!$A:$AM,13,0),"")) -> 2025 | P5: =IF(B5="","",IFERROR(VLOOKUP(B5,'ANÁLISE DE DADOS'!$A:$AM,14,0),"")) -> 1000 | Q5: =IF(B5="","",IFERROR(VLOOKUP(B5,'ANÁLISE DE DADOS'!$A:$AM,15,0),"")) -> João | R5: =IF(B5="","",IFERROR(VLOOKUP(B5,'ANÁLISE DE DADOS'!$A:$AM,16,0),"")) -> ANALISTA SIMONE | S5: =IF(B5="","",IFERROR(VLOOKUP(B5,'ANÁLISE DE DADOS'!$A:$AM,17,0),"")) -> NÃO | T5: =IF(B5="","",IFERROR(VLOOKUP(B5,'ANÁLISE DE DADOS'!$A:$AM,18,0),"")) -> Situação com comercial (aguardando análise comercial) | U5: =IF(B5="","",IFERROR(VLOOKUP(B5,'ANÁLISE DE DADOS'!$A:$AM,19,0),"")) -> Vencido | V5: =IF(B5="","",IFERROR(VLOOKUP(B5,'ANÁLISE DE DADOS'!$A:$AM,20,0),"")) -> 105 | W5: =IF(B5="","",IFERROR(VLOOKUP(B5,'ANÁLISE DE DADOS'!$A:$AM,21,0),"")) -> 61+ dias | X5: =IF(B5="","",IFERROR(VLOOKUP(B5,'ANÁLISE DE DADOS'!$A:$AM,22,0),"")) -> Atraso Crítico | Y5: =IF(B5="","",IFERROR(VLOOKUP(B5,'ANÁLISE DE DADOS'!$A:$AM,23,0),"")) -> - | Z5: =IF(B5="","",IFERROR(VLOOKUP(B5,'ANÁLISE DE DADOS'!$A:$AM,24,0),"")) -> Sim | AA5: =IF(B5="","",IFERROR(VLOOKUP(B5,'ANÁLISE DE DADOS'!$A:$AM,25,0),"")) -> 0 | AB5: =IF(B5="","",IFERROR(VLOOKUP(B5,'ANÁLISE DE DADOS'!$A:$AM,26,0),"")) -> 1 | AC5: =IF(B5="","",IFERROR(VLOOKUP(B5,'ANÁLISE DE DADOS'!$A:$AM,27,0),"")) -> Sim | AD5: =IF(B5="","",IFERROR(VLOOKUP(B5,'ANÁLISE DE DADOS'!$A:$AM,28,0),"")) -> 45740 | AE5: =IF(B5="","",IFERROR(VLOOKUP(B5,'ANÁLISE DE DADOS'!$A:$AM,29,0),"")) -> mar-25 | AF5: =IF(B5="","",IFERROR(VLOOKUP(B5,'ANÁLISE DE DADOS'!$A:$AM,30,0),"")) -> 2025 | AG5: =IF(B5="","",IFERROR(VLOOKUP(B5,'ANÁLISE DE DADOS'!$A:$AM,31,0),"")) -> 45772 | AH5: =IF(B5="","",IFERROR(VLOOKUP(B5,'ANÁLISE DE DADOS'!$A:$AM,32,0),"")) -> abr-25 | AI5: =IF(B5="","",IFERROR(VLOOKUP(B5,'ANÁLISE DE DADOS'!$A:$AM,33,0),"")) -> 2025 | AJ5: =IF(B5="","",IFERROR(VLOOKUP(B5,'ANÁLISE DE DADOS'!$A:$AM,34,0),"")) -> Acompanhando | AK5: =IF(B5="","",IFERROR(VLOOKUP(B5,'ANÁLISE DE DADOS'!$A:$AM,35,0),"")) -> 1000 | AL5: =IF(B5="","",IFERROR(VLOOKUP(B5,'ANÁLISE DE DADOS'!$A:$AM,36,0),"")) -> 0
B6: 2 | C6: =IF(B6="","",IFERROR(VLOOKUP(B6,'ANÁLISE DE DADOS'!$A:$AM,1,0),"")) -> 2 | D6: =IF(B6="","",IFERROR(VLOOKUP(B6,'ANÁLISE DE DADOS'!$A:$AM,2,0),"")) -> Matriz | E6: =IF(B6="","",IFERROR(VLOOKUP(B6,'ANÁLISE DE DADOS'!$A:$AM,3,0),"")) -> Alpha & CIA | F6: =IF(B6="","",IFERROR(VLOOKUP(B6,'ANÁLISE DE DADOS'!$A:$AM,4,0),"")) -> Beta | G6: =IF(B6="","",IFERROR(VLOOKUP(B6,'ANÁLISE DE DADOS'!$A:$AM,5,0),"")) -> 45658 | H6: =IF(B6="","",IFERROR(VLOOKUP(B6,'ANÁLISE DE DADOS'!$A:$AM,6,0),"")) -> jan-25 | I6: =IF(B6="","",IFERROR(VLOOKUP(B6,'ANÁLISE DE DADOS'!$A:$AM,7,0),"")) -> 2025 | J6: =IF(B6="","",IFERROR(VLOOKUP(B6,'ANÁLISE DE DADOS'!$A:$AM,8,0),"")) -> 45690 | K6: =IF(B6="","",IFERROR(VLOOKUP(B6,'ANÁLISE DE DADOS'!$A:$AM,9,0),"")) -> fev-25 | L6: =IF(B6="","",IFERROR(VLOOKUP(B6,'ANÁLISE DE DADOS'!$A:$AM,10,0),"")) -> 2025 | M6: =IF(B6="","",IFERROR(VLOOKUP(B6,'ANÁLISE DE DADOS'!$A:$AM,11,0),"")) -> 45737 | N6: =IF(B6="","",IFERROR(VLOOKUP(B6,'ANÁLISE DE DADOS'!$A:$AM,12,0),"")) -> mar-25 | O6: =IF(B6="","",IFERROR(VLOOKUP(B6,'ANÁLISE DE DADOS'!$A:$AM,13,0),"")) -> 2025 | P6: =IF(B6="","",IFERROR(VLOOKUP(B6,'ANÁLISE DE DADOS'!$A:$AM,14,0),"")) -> 1000 | Q6: =IF(B6="","",IFERROR(VLOOKUP(B6,'ANÁLISE DE DADOS'!$A:$AM,15,0),"")) -> João | R6: =IF(B6="","",IFERROR(VLOOKUP(B6,'ANÁLISE DE DADOS'!$A:$AM,16,0),"")) -> ANALISTA SIMONE | S6: =IF(B6="","",IFERROR(VLOOKUP(B6,'ANÁLISE DE DADOS'!$A:$AM,17,0),"")) -> NÃO | T6: =IF(B6="","",IFERROR(VLOOKUP(B6,'ANÁLISE DE DADOS'!$A:$AM,18,0),"")) -> Aguardando aprovação de crédito | U6: =IF(B6="","",IFERROR(VLOOKUP(B6,'ANÁLISE DE DADOS'!$A:$AM,19,0),"")) -> Vencido | V6: =IF(B6="","",IFERROR(VLOOKUP(B6,'ANÁLISE DE DADOS'!$A:$AM,20,0),"")) -> 105 | W6: =IF(B6="","",IFERROR(VLOOKUP(B6,'ANÁLISE DE DADOS'!$A:$AM,21,0),"")) -> 61+ dias | X6: =IF(B6="","",IFERROR(VLOOKUP(B6,'ANÁLISE DE DADOS'!$A:$AM,22,0),"")) -> Atraso Crítico | Y6: =IF(B6="","",IFERROR(VLOOKUP(B6,'ANÁLISE DE DADOS'!$A:$AM,23,0),"")) -> - | Z6: =IF(B6="","",IFERROR(VLOOKUP(B6,'ANÁLISE DE DADOS'!$A:$AM,24,0),"")) -> Sim | AA6: =IF(B6="","",IFERROR(VLOOKUP(B6,'ANÁLISE DE DADOS'!$A:$AM,25,0),"")) -> 0 | AB6: =IF(B6="","",IFERROR(VLOOKUP(B6,'ANÁLISE DE DADOS'!$A:$AM,26,0),"")) -> 1 | AC6: =IF(B6="","",IFERROR(VLOOKUP(B6,'ANÁLISE DE DADOS'!$A:$AM,27,0),"")) -> Sim | AD6: =IF(B6="","",IFERROR(VLOOKUP(B6,'ANÁLISE DE DADOS'!$A:$AM,28,0),"")) -> 45740 | AE6: =IF(B6="","",IFERROR(VLOOKUP(B6,'ANÁLISE DE DADOS'!$A:$AM,29,0),"")) -> mar-25 | AF6: =IF(B6="","",IFERROR(VLOOKUP(B6,'ANÁLISE DE DADOS'!$A:$AM,30,0),"")) -> 2025 | AG6: =IF(B6="","",IFERROR(VLOOKUP(B6,'ANÁLISE DE DADOS'!$A:$AM,31,0),"")) -> 45802 | AH6: =IF(B6="","",IFERROR(VLOOKUP(B6,'ANÁLISE DE DADOS'!$A:$AM,32,0),"")) -> mai-25 | AI6: =IF(B6="","",IFERROR(VLOOKUP(B6,'ANÁLISE DE DADOS'!$A:$AM,33,0),"")) -> 2025 | AJ6: =IF(B6="","",IFERROR(VLOOKUP(B6,'ANÁLISE DE DADOS'!$A:$AM,34,0),"")) -> Acompanhando | AK6: =IF(B6="","",IFERROR(VLOOKUP(B6,'ANÁLISE DE DADOS'!$A:$AM,35,0),"")) -> 1000 | AL6: =IF(B6="","",IFERROR(VLOOKUP(B6,'ANÁLISE DE DADOS'!$A:$AM,36,0),"")) -> 0
B7: 3 | C7: =IF(B7="","",IFERROR(VLOOKUP(B7,'ANÁLISE DE DADOS'!$A:$AM,1,0),"")) -> 3 | D7: =IF(B7="","",IFERROR(VLOOKUP(B7,'ANÁLISE DE DADOS'!$A:$AM,2,0),"")) -> Filial | E7: =IF(B7="","",IFERROR(VLOOKUP(B7,'ANÁLISE DE DADOS'!$A:$AM,3,0),"")) -> Alpha & CIA | F7: =IF(B7="","",IFERROR(VLOOKUP(B7,'ANÁLISE DE DADOS'!$A:$AM,4,0),"")) -> Delta | G7: =IF(B7="","",IFERROR(VLOOKUP(B7,'ANÁLISE DE DADOS'!$A:$AM,5,0),"")) -> 45659 | H7: =IF(B7="","",IFERROR(VLOOKUP(B7,'ANÁLISE DE DADOS'!$A:$AM,6,0),"")) -> jan-25 | I7: =IF(B7="","",IFERROR(VLOOKUP(B7,'ANÁLISE DE DADOS'!$A:$AM,7,0),"")) -> 2025 | J7: =IF(B7="","",IFERROR(VLOOKUP(B7,'ANÁLISE DE DADOS'!$A:$AM,8,0),"")) -> 45690 | K7: =IF(B7="","",IFERROR(VLOOKUP(B7,'ANÁLISE DE DADOS'!$A:$AM,9,0),"")) -> fev-25 | L7: =IF(B7="","",IFERROR(VLOOKUP(B7,'ANÁLISE DE DADOS'!$A:$AM,10,0),"")) -> 2025 | M7: =IF(B7="","",IFERROR(VLOOKUP(B7,'ANÁLISE DE DADOS'!$A:$AM,11,0),"")) -> 45737 | N7: =IF(B7="","",IFERROR(VLOOKUP(B7,'ANÁLISE DE DADOS'!$A:$AM,12,0),"")) -> mar-25 | O7: =IF(B7="","",IFERROR(VLOOKUP(B7,'ANÁLISE DE DADOS'!$A:$AM,13,0),"")) -> 2025 | P7: =IF(B7="","",IFERROR(VLOOKUP(B7,'ANÁLISE DE DADOS'!$A:$AM,14,0),"")) -> 2500 | Q7: =IF(B7="","",IFERROR(VLOOKUP(B7,'ANÁLISE DE DADOS'!$A:$AM,15,0),"")) -> Maria | R7: =IF(B7="","",IFERROR(VLOOKUP(B7,'ANÁLISE DE DADOS'!$A:$AM,16,0),"")) -> ANALISTA SIMONE | S7: =IF(B7="","",IFERROR(VLOOKUP(B7,'ANÁLISE DE DADOS'!$A:$AM,17,0),"")) -> NÃO | T7: =IF(B7="","",IFERROR(VLOOKUP(B7,'ANÁLISE DE DADOS'!$A:$AM,18,0),"")) -> Cliente não localizado | U7: =IF(B7="","",IFERROR(VLOOKUP(B7,'ANÁLISE DE DADOS'!$A:$AM,19,0),"")) -> Vencido | V7: =IF(B7="","",IFERROR(VLOOKUP(B7,'ANÁLISE DE DADOS'!$A:$AM,20,0),"")) -> 105 | W7: =IF(B7="","",IFERROR(VLOOKUP(B7,'ANÁLISE DE DADOS'!$A:$AM,21,0),"")) -> 61+ dias | X7: =IF(B7="","",IFERROR(VLOOKUP(B7,'ANÁLISE DE DADOS'!$A:$AM,22,0),"")) -> Atraso Crítico | Y7: =IF(B7="","",IFERROR(VLOOKUP(B7,'ANÁLISE DE DADOS'!$A:$AM,23,0),"")) -> - | Z7: =IF(B7="","",IFERROR(VLOOKUP(B7,'ANÁLISE DE DADOS'!$A:$AM,24,0),"")) -> Sim | AA7: =IF(B7="","",IFERROR(VLOOKUP(B7,'ANÁLISE DE DADOS'!$A:$AM,25,0),"")) -> 0 | AB7: =IF(B7="","",IFERROR(VLOOKUP(B7,'ANÁLISE DE DADOS'!$A:$AM,26,0),"")) -> 1 | AC7: =IF(B7="","",IFERROR(VLOOKUP(B7,'ANÁLISE DE DADOS'!$A:$AM,27,0),"")) -> Sim | AD7: =IF(B7="","",IFERROR(VLOOKUP(B7,'ANÁLISE DE DADOS'!$A:$AM,28,0),"")) -> 45740 | AE7: =IF(B7="","",IFERROR(VLOOKUP(B7,'ANÁLISE DE DADOS'!$A:$AM,29,0),"")) -> mar-25 | AF7: =IF(B7="","",IFERROR(VLOOKUP(B7,'ANÁLISE DE DADOS'!$A:$AM,30,0),"")) -> 2025 | AG7: =IF(B7="","",IFERROR(VLOOKUP(B7,'ANÁLISE DE DADOS'!$A:$AM,31,0),"")) -> 45802 | AH7: =IF(B7="","",IFERROR(VLOOKUP(B7,'ANÁLISE DE DADOS'!$A:$AM,32,0),"")) -> mai-25 | AI7: =IF(B7="","",IFERROR(VLOOKUP(B7,'ANÁLISE DE DADOS'!$A:$AM,33,0),"")) -> 2025 | AJ7: =IF(B7="","",IFERROR(VLOOKUP(B7,'ANÁLISE DE DADOS'!$A:$AM,34,0),"")) -> Acompanhando | AK7: =IF(B7="","",IFERROR(VLOOKUP(B7,'ANÁLISE DE DADOS'!$A:$AM,35,0),"")) -> 2500 | AL7: =IF(B7="","",IFERROR(VLOOKUP(B7,'ANÁLISE DE DADOS'!$A:$AM,36,0),"")) -> 0
B8: 4 | C8: =IF(B8="","",IFERROR(VLOOKUP(B8,'ANÁLISE DE DADOS'!$A:$AM,1,0),"")) -> 4 | D8: =IF(B8="","",IFERROR(VLOOKUP(B8,'ANÁLISE DE DADOS'!$A:$AM,2,0),"")) -> Filial | E8: =IF(B8="","",IFERROR(VLOOKUP(B8,'ANÁLISE DE DADOS'!$A:$AM,3,0),"")) -> Alpha & CIA | F8: =IF(B8="","",IFERROR(VLOOKUP(B8,'ANÁLISE DE DADOS'!$A:$AM,4,0),"")) -> Delta | G8: =IF(B8="","",IFERROR(VLOOKUP(B8,'ANÁLISE DE DADOS'!$A:$AM,5,0),"")) -> 45659 | H8: =IF(B8="","",IFERROR(VLOOKUP(B8,'ANÁLISE DE DADOS'!$A:$AM,6,0),"")) -> jan-25 | I8: =IF(B8="","",IFERROR(VLOOKUP(B8,'ANÁLISE DE DADOS'!$A:$AM,7,0),"")) -> 2025 | J8: =IF(B8="","",IFERROR(VLOOKUP(B8,'ANÁLISE DE DADOS'!$A:$AM,8,0),"")) -> 45690 | K8: =IF(B8="","",IFERROR(VLOOKUP(B8,'ANÁLISE DE DADOS'!$A:$AM,9,0),"")) -> fev-25 | L8: =IF(B8="","",IFERROR(VLOOKUP(B8,'ANÁLISE DE DADOS'!$A:$AM,10,0),"")) -> 2025 | M8: =IF(B8="","",IFERROR(VLOOKUP(B8,'ANÁLISE DE DADOS'!$A:$AM,11,0),"")) -> 45737 | N8: =IF(B8="","",IFERROR(VLOOKUP(B8,'ANÁLISE DE DADOS'!$A:$AM,12,0),"")) -> mar-25 | O8: =IF(B8="","",IFERROR(VLOOKUP(B8,'ANÁLISE DE DADOS'!$A:$AM,13,0),"")) -> 2025 | P8: =IF(B8="","",IFERROR(VLOOKUP(B8,'ANÁLISE DE DADOS'!$A:$AM,14,0),"")) -> 2500 | Q8: =IF(B8="","",IFERROR(VLOOKUP(B8,'ANÁLISE DE DADOS'!$A:$AM,15,0),"")) -> Maria | R8: =IF(B8="","",IFERROR(VLOOKUP(B8,'ANÁLISE DE DADOS'!$A:$AM,16,0),"")) -> ANALISTA SIMONE | S8: =IF(B8="","",IFERROR(VLOOKUP(B8,'ANÁLISE DE DADOS'!$A:$AM,17,0),"")) -> NÃO | T8: =IF(B8="","",IFERROR(VLOOKUP(B8,'ANÁLISE DE DADOS'!$A:$AM,18,0),"")) -> Promessa de pagamento refeito | U8: =IF(B8="","",IFERROR(VLOOKUP(B8,'ANÁLISE DE DADOS'!$A:$AM,19,0),"")) -> Vencido | V8: =IF(B8="","",IFERROR(VLOOKUP(B8,'ANÁLISE DE DADOS'!$A:$AM,20,0),"")) -> 105 | W8: =IF(B8="","",IFERROR(VLOOKUP(B8,'ANÁLISE DE DADOS'!$A:$AM,21,0),"")) -> 61+ dias | X8: =IF(B8="","",IFERROR(VLOOKUP(B8,'ANÁLISE DE DADOS'!$A:$AM,22,0),"")) -> Atraso Crítico | Y8: =IF(B8="","",IFERROR(VLOOKUP(B8,'ANÁLISE DE DADOS'!$A:$AM,23,0),"")) -> - | Z8: =IF(B8="","",IFERROR(VLOOKUP(B8,'ANÁLISE DE DADOS'!$A:$AM,24,0),"")) -> Sim | AA8: =IF(B8="","",IFERROR(VLOOKUP(B8,'ANÁLISE DE DADOS'!$A:$AM,25,0),"")) -> 0 | AB8: =IF(B8="","",IFERROR(VLOOKUP(B8,'ANÁLISE DE DADOS'!$A:$AM,26,0),"")) -> 1 | AC8: =IF(B8="","",IFERROR(VLOOKUP(B8,'ANÁLISE DE DADOS'!$A:$AM,27,0),"")) -> Sim | AD8: =IF(B8="","",IFERROR(VLOOKUP(B8,'ANÁLISE DE DADOS'!$A:$AM,28,0),"")) -> 45740 | AE8: =IF(B8="","",IFERROR(VLOOKUP(B8,'ANÁLISE DE DADOS'!$A:$AM,29,0),"")) -> mar-25 | AF8: =IF(B8="","",IFERROR(VLOOKUP(B8,'ANÁLISE DE DADOS'!$A:$AM,30,0),"")) -> 2025 | AG8: =IF(B8="","",IFERROR(VLOOKUP(B8,'ANÁLISE DE DADOS'!$A:$AM,31,0),"")) -> 45802 | AH8: =IF(B8="","",IFERROR(VLOOKUP(B8,'ANÁLISE DE DADOS'!$A:$AM,32,0),"")) -> mai-25 | AI8: =IF(B8="","",IFERROR(VLOOKUP(B8,'ANÁLISE DE DADOS'!$A:$AM,33,0),"")) -> 2025 | AJ8: =IF(B8="","",IFERROR(VLOOKUP(B8,'ANÁLISE DE DADOS'!$A:$AM,34,0),"")) -> Acompanhando | AK8: =IF(B8="","",IFERROR(VLOOKUP(B8,'ANÁLISE DE DADOS'!$A:$AM,35,0),"")) -> 2500 | AL8: =IF(B8="","",IFERROR(VLOOKUP(B8,'ANÁLISE DE DADOS'!$A:$AM,36,0),"")) -> 0
B9: 5 | C9: =IF(B9="","",IFERROR(VLOOKUP(B9,'ANÁLISE DE DADOS'!$A:$AM,1,0),"")) -> 5 | D9: =IF(B9="","",IFERROR(VLOOKUP(B9,'ANÁLISE DE DADOS'!$A:$AM,2,0),"")) -> Matriz | E9: =IF(B9="","",IFERROR(VLOOKUP(B9,'ANÁLISE DE DADOS'!$A:$AM,3,0),"")) -> Alpha & CIA | F9: =IF(B9="","",IFERROR(VLOOKUP(B9,'ANÁLISE DE DADOS'!$A:$AM,4,0),"")) -> Theta | G9: =IF(B9="","",IFERROR(VLOOKUP(B9,'ANÁLISE DE DADOS'!$A:$AM,5,0),"")) -> 45662 | H9: =IF(B9="","",IFERROR(VLOOKUP(B9,'ANÁLISE DE DADOS'!$A:$AM,6,0),"")) -> jan-25 | I9: =IF(B9="","",IFERROR(VLOOKUP(B9,'ANÁLISE DE DADOS'!$A:$AM,7,0),"")) -> 2025 | J9: =IF(B9="","",IFERROR(VLOOKUP(B9,'ANÁLISE DE DADOS'!$A:$AM,8,0),"")) -> 45690 | K9: =IF(B9="","",IFERROR(VLOOKUP(B9,'ANÁLISE DE DADOS'!$A:$AM,9,0),"")) -> fev-25 | L9: =IF(B9="","",IFERROR(VLOOKUP(B9,'ANÁLISE DE DADOS'!$A:$AM,10,0),"")) -> 2025 | M9: =IF(B9="","",IFERROR(VLOOKUP(B9,'ANÁLISE DE DADOS'!$A:$AM,11,0),"")) -> 45737 | N9: =IF(B9="","",IFERROR(VLOOKUP(B9,'ANÁLISE DE DADOS'!$A:$AM,12,0),"")) -> mar-25 | O9: =IF(B9="","",IFERROR(VLOOKUP(B9,'ANÁLISE DE DADOS'!$A:$AM,13,0),"")) -> 2025 | P9: =IF(B9="","",IFERROR(VLOOKUP(B9,'ANÁLISE DE DADOS'!$A:$AM,14,0),"")) -> 3000 | Q9: =IF(B9="","",IFERROR(VLOOKUP(B9,'ANÁLISE DE DADOS'!$A:$AM,15,0),"")) -> Carlos | R9: =IF(B9="","",IFERROR(VLOOKUP(B9,'ANÁLISE DE DADOS'!$A:$AM,16,0),"")) -> ANALISTA SIMONE | S9: =IF(B9="","",IFERROR(VLOOKUP(B9,'ANÁLISE DE DADOS'!$A:$AM,17,0),"")) -> NÃO | T9: =IF(B9="","",IFERROR(VLOOKUP(B9,'ANÁLISE DE DADOS'!$A:$AM,18,0),"")) -> Proposta de renegociação pendente | U9: =IF(B9="","",IFERROR(VLOOKUP(B9,'ANÁLISE DE DADOS'!$A:$AM,19,0),"")) -> Vencido | V9: =IF(B9="","",IFERROR(VLOOKUP(B9,'ANÁLISE DE DADOS'!$A:$AM,20,0),"")) -> 105 | W9: =IF(B9="","",IFERROR(VLOOKUP(B9,'ANÁLISE DE DADOS'!$A:$AM,21,0),"")) -> 61+ dias | X9: =IF(B9="","",IFERROR(VLOOKUP(B9,'ANÁLISE DE DADOS'!$A:$AM,22,0),"")) -> Atraso Crítico | Y9: =IF(B9="","",IFERROR(VLOOKUP(B9,'ANÁLISE DE DADOS'!$A:$AM,23,0),"")) -> - | Z9: =IF(B9="","",IFERROR(VLOOKUP(B9,'ANÁLISE DE DADOS'!$A:$AM,24,0),"")) -> Sim | AA9: =IF(B9="","",IFERROR(VLOOKUP(B9,'ANÁLISE DE DADOS'!$A:$AM,25,0),"")) -> 0 | AB9: =IF(B9="","",IFERROR(VLOOKUP(B9,'ANÁLISE DE DADOS'!$A:$AM,26,0),"")) -> 1 | AC9: =IF(B9="","",IFERROR(VLOOKUP(B9,'ANÁLISE DE DADOS'!$A:$AM,27,0),"")) -> Sim | AD9: =IF(B9="","",IFERROR(VLOOKUP(B9,'ANÁLISE DE DADOS'!$A:$AM,28,0),"")) -> 45740 | AE9: =IF(B9="","",IFERROR(VLOOKUP(B9,'ANÁLISE DE DADOS'!$A:$AM,29,0),"")) -> mar-25 | AF9: =IF(B9="","",IFERROR(VLOOKUP(B9,'ANÁLISE DE DADOS'!$A:$AM,30,0),"")) -> 2025 | AG9: =IF(B9="","",IFERROR(VLOOKUP(B9,'ANÁLISE DE DADOS'!$A:$AM,31,0),"")) -> 45802 | AH9: =IF(B9="","",IFERROR(VLOOKUP(B9,'ANÁLISE DE DADOS'!$A:$AM,32,0),"")) -> mai-25 | AI9: =IF(B9="","",IFERROR(VLOOKUP(B9,'ANÁLISE DE DADOS'!$A:$AM,33,0),"")) -> 2025 | AJ9: =IF(B9="","",IFERROR(VLOOKUP(B9,'ANÁLISE DE DADOS'!$A:$AM,34,0),"")) -> Acompanhando | AK9: =IF(B9="","",IFERROR(VLOOKUP(B9,'ANÁLISE DE DADOS'!$A:$AM,35,0),"")) -> 3000 | AL9: =IF(B9="","",IFERROR(VLOOKUP(B9,'ANÁLISE DE DADOS'!$A:$AM,36,0),"")) -> 0
