Workbook

Sheet PRODUTOS
B5: Produto | C5: Preço de Venda | D5: Quantidade Vendida/Mês | E5: Receita bruta Mensal | F5: % de Participação
B6: Sofá de Couro Italiano | C6: 3500 | D6: 80 | E6: =VLOOKUP(B6,B6:D15,2,FALSE)*VLOOKUP(B6,B6:D15,3,FALSE) -> 280000 | F6: =E6/$E$17 -> 0.12235088
B7: Máquina de Café Expresso | C7: 1200 | D7: 100 | E7: =VLOOKUP(B7,B7:D15,2,FALSE)*VLOOKUP(B7,B7:D15,3,FALSE) -> 120000 | F7: =E7/$E$17 -> 0.052436094
B8: Luminária de Cristal (1,5m) | C8: 850 | D8: 50 | E8: =VLOOKUP(B8,B8:D15,2,FALSE)*VLOOKUP(B8,B8:D15,3,FALSE) -> 42500 | F8: =E8/$E$17 -> 0.018571116
B9: Conjunto de Talheres de Prata | C9: 450 | D9: 80 | E9: =VLOOKUP(B9,B9:D15,2,FALSE)*VLOOKUP(B9,B9:D15,3,FALSE) -> 36000 | F9: =E9/$E$17 -> 0.015730828
B10: Tapete Persa (3x4m) | C10: 2000 | D10: 100 | E10: =VLOOKUP(B10,B10:D16,2,FALSE)*VLOOKUP(B10,B10:D16,3,FALSE) -> 200000 | F10: =E10/$E$17 -> 0.087393489
B11: Cama King Size de Madeira | C11: 2500 | D11: 100 | E11: =VLOOKUP(B11,B11:D17,2,FALSE)*VLOOKUP(B11,B11:D17,3,FALSE) -> 250000 | F11: =E11/$E$17 -> 0.10924186
B12: TV LED 100 | C12: 3000 | D12: 100 | E12: =VLOOKUP(B12,B12:D18,2,FALSE)*VLOOKUP(B12,B12:D18,3,FALSE) -> 300000 | F12: =E12/$E$17 -> 0.13109023
B13: Frigobar de Inox | C13: 900 | D13: 400 | E13: =VLOOKUP(B13,B13:D19,2,FALSE)*VLOOKUP(B13,B13:D19,3,FALSE) -> 360000 | F13: =E13/$E$17 -> 0.15730828
B14: Ventilador de Design Moderno | C14: 600 | D14: 500 | E14: =VLOOKUP(B14,B14:D20,2,FALSE)*VLOOKUP(B14,B14:D20,3,FALSE) -> 300000 | F14: =E14/$E$17 -> 0.13109023
B15: Jogo de Cama de Seda (Queen) | C15: 800 | D15: 500 | E15: =VLOOKUP(B15,B15:D21,2,FALSE)*VLOOKUP(B15,B15:D21,3,FALSE) -> 400000 | F15: =E15/$E$17 -> 0.17478698
D17: TOTAL | E17: =SUM(E6:E15) -> 2288500 | F17: =SUM(F6:F15) -> 1

Sheet CUSTOS DIRETOS x CUSTOS FIXOS
B5: Produto | C5: Custo com Matéria Prima | D5: Comissões% | E5: Impostos% | F5: Outros Gastos | G5: Total Custo direrto/ Por produto | I5: Comissões % | J5: Impostos % | K5: Margem de Contribuição (U.N) | L5: IMC% | M5: Receita no ponto de Equilíbrio | N5: Quantidade a ser vendida | O5: Outros Gastos | P5: Matéria Prima | U5: Auxiliar01 | V5: Auxiliar02
B6: Sofá de Couro Italiano | C6: 1750 | D6: 0.05 | E6: 0.18 | F6: 500 | G6: ='CUSTOS DIRETOS x CUSTOS FIXOS'!C6+PRODUTOS!C6*('CUSTOS DIRETOS x CUSTOS FIXOS'!D6+'CUSTOS DIRETOS x CUSTOS FIXOS'!E6)+'CUSTOS DIRETOS x CUSTOS FIXOS'!F6 -> 3055 | I6: =IF(ISERROR(PRODUTOS!E6*'CUSTOS DIRETOS x CUSTOS FIXOS'!D6),"",(PRODUTOS!E6*'CUSTOS DIRETOS x CUSTOS FIXOS'!D6)) -> 14000 | J6: =IF(ISERROR(PRODUTOS!E6*'CUSTOS DIRETOS x CUSTOS FIXOS'!E6),"",(PRODUTOS!E6*'CUSTOS DIRETOS x CUSTOS FIXOS'!E6)) -> 50400 | K6: =IF(ISERROR(PRODUTOS!C6:C12-'CUSTOS DIRETOS x CUSTOS FIXOS'!G6:G12),"",PRODUTOS!C6:C12-'CUSTOS DIRETOS x CUSTOS FIXOS'!G6:G12) -> 445 | L6: =IF(ISERROR(K6/PRODUTOS!C6),"",('CUSTOS DIRETOS x CUSTOS FIXOS'!K6/PRODUTOS!C6)) -> 0.12714286 | M6: =IF(ISERROR( (N6*PRODUTOS!C6)),"",('CUSTOS DIRETOS x CUSTOS FIXOS'!N6*PRODUTOS!C6)) -> 44468.52 | N6: =IF(ISERROR('PONTO DE EQUILÍBRIO'!$F$9*PRODUTOS!F6),"",'PONTO DE EQUILÍBRIO'!$F$9*PRODUTOS!F6) -> 12.705291 | O6: =IF(ISERROR(PRODUTOS!D6*'CUSTOS DIRETOS x CUSTOS FIXOS'!F6),"",PRODUTOS!D6*'CUSTOS DIRETOS x CUSTOS FIXOS'!F6) -> 40000 | P6: =IF(ISERROR(PRODUTOS!D6*'CUSTOS DIRETOS x CUSTOS FIXOS'!C6),"",PRODUTOS!D6*'CUSTOS DIRETOS x CUSTOS FIXOS'!C6) -> 140000 | S6: =B6 -> Sofá de Couro Italiano | T6: =L6 -> 0.12714286 | U6: =COUNTIF(T6:T$6,T6) -> 1 | V6: =T6&U6 -> 0,1271428571428571
B7: Máquina de Café Expresso | C7: 310 | D7: 0.05 | E7: 0.18 | F7: 600 | G7: ='CUSTOS DIRETOS x CUSTOS FIXOS'!C7+PRODUTOS!C7*('CUSTOS DIRETOS x CUSTOS FIXOS'!D7+'CUSTOS DIRETOS x CUSTOS FIXOS'!E7)+'CUSTOS DIRETOS x CUSTOS FIXOS'!F7 -> 1186 | I7: =IF(ISERROR(PRODUTOS!E7*'CUSTOS DIRETOS x CUSTOS FIXOS'!D7),"",(PRODUTOS!E7*'CUSTOS DIRETOS x CUSTOS FIXOS'!D7)) -> 6000 | J7: =IF(ISERROR(PRODUTOS!E7*'CUSTOS DIRETOS x CUSTOS FIXOS'!E7),"",(PRODUTOS!E7*'CUSTOS DIRETOS x CUSTOS FIXOS'!E7)) -> 21600 | K7: =IF(ISERROR(PRODUTOS!C7:C13-'CUSTOS DIRETOS x CUSTOS FIXOS'!G7:G13),"",PRODUTOS!C7:C13-'CUSTOS DIRETOS x CUSTOS FIXOS'!G7:G13) -> 14 | L7: =IF(ISERROR(K7/PRODUTOS!C7),"",('CUSTOS DIRETOS x CUSTOS FIXOS'!K7/PRODUTOS!C7)) -> 0.011666667 | M7: =IF(ISERROR( (N7*PRODUTOS!C7)),"",('CUSTOS DIRETOS x CUSTOS FIXOS'!N7*PRODUTOS!C7)) -> 6534.1499 | N7: =IF(ISERROR('PONTO DE EQUILÍBRIO'!$F$9*PRODUTOS!F7),"",'PONTO DE EQUILÍBRIO'!$F$9*PRODUTOS!F7) -> 5.4451249 | O7: =IF(ISERROR(PRODUTOS!D7*'CUSTOS DIRETOS x CUSTOS FIXOS'!F7),"",PRODUTOS!D7*'CUSTOS DIRETOS x CUSTOS FIXOS'!F7) -> 60000 | P7: =IF(ISERROR(PRODUTOS!D7*'CUSTOS DIRETOS x CUSTOS FIXOS'!C7),"",PRODUTOS!D7*'CUSTOS DIRETOS x CUSTOS FIXOS'!C7) -> 31000 | S7: =B7 -> Máquina de Café Expresso | T7: =L7 -> 0.011666667 | U7: =COUNTIF(T$6:T7,T7) -> 1 | V7: =T7&U7 -> 0,01166666666666671
B8: Luminária de Cristal (1,5m) | C8: 50 | D8: 0.05 | E8: 0.18 | F8: 500 | G8: ='CUSTOS DIRETOS x CUSTOS FIXOS'!C8+PRODUTOS!C8*('CUSTOS DIRETOS x CUSTOS FIXOS'!D8+'CUSTOS DIRETOS x CUSTOS FIXOS'!E8)+'CUSTOS DIRETOS x CUSTOS FIXOS'!F8 -> 745.5 | I8: =IF(ISERROR(PRODUTOS!E8*'CUSTOS DIRETOS x CUSTOS FIXOS'!D8),"",(PRODUTOS!E8*'CUSTOS DIRETOS x CUSTOS FIXOS'!D8)) -> 2125 | J8: =IF(ISERROR(PRODUTOS!E8*'CUSTOS DIRETOS x CUSTOS FIXOS'!E8),"",(PRODUTOS!E8*'CUSTOS DIRETOS x CUSTOS FIXOS'!E8)) -> 7650 | K8: =IF(ISERROR(PRODUTOS!C8:C14-'CUSTOS DIRETOS x CUSTOS FIXOS'!G8:G14),"",PRODUTOS!C8:C14-'CUSTOS DIRETOS x CUSTOS FIXOS'!G8:G14) -> 104.5 | L8: =IF(ISERROR(K8/PRODUTOS!C8),"",('CUSTOS DIRETOS x CUSTOS FIXOS'!K8/PRODUTOS!C8)) -> 0.12294118 | M8: =IF(ISERROR( (N8*PRODUTOS!C8)),"",('CUSTOS DIRETOS x CUSTOS FIXOS'!N8*PRODUTOS!C8)) -> 1639.2095 | N8: =IF(ISERROR('PONTO DE EQUILÍBRIO'!$F$9*PRODUTOS!F8),"",'PONTO DE EQUILÍBRIO'!$F$9*PRODUTOS!F8) -> 1.9284817 | O8: =IF(ISERROR(PRODUTOS!D8*'CUSTOS DIRETOS x CUSTOS FIXOS'!F8),"",PRODUTOS!D8*'CUSTOS DIRETOS x CUSTOS FIXOS'!F8) -> 25000 | P8: =IF(ISERROR(PRODUTOS!D8*'CUSTOS DIRETOS x CUSTOS FIXOS'!C8),"",PRODUTOS!D8*'CUSTOS DIRETOS x CUSTOS FIXOS'!C8) -> 2500 | S8: =B8 -> Luminária de Cristal (1,5m) | T8: =L8 -> 0.12294118 | U8: =COUNTIF(T$6:T8,T8) -> 1 | V8: =T8&U8 -> 0,1229411764705881
B9: Conjunto de Talheres de Prata | C9: 225 | D9: 0.05 | E9: 0.18 | F9: 500 | G9: ='CUSTOS DIRETOS x CUSTOS FIXOS'!C9+PRODUTOS!C9*('CUSTOS DIRETOS x CUSTOS FIXOS'!D9+'CUSTOS DIRETOS x CUSTOS FIXOS'!E9)+'CUSTOS DIRETOS x CUSTOS FIXOS'!F9 -> 828.5 | I9: =IF(ISERROR(PRODUTOS!E9*'CUSTOS DIRETOS x CUSTOS FIXOS'!D9),"",(PRODUTOS!E9*'CUSTOS DIRETOS x CUSTOS FIXOS'!D9)) -> 1800 | J9: =IF(ISERROR(PRODUTOS!E9*'CUSTOS DIRETOS x CUSTOS FIXOS'!E9),"",(PRODUTOS!E9*'CUSTOS DIRETOS x CUSTOS FIXOS'!E9)) -> 6480 | K9: =IF(ISERROR(PRODUTOS!C9:C15-'CUSTOS DIRETOS x CUSTOS FIXOS'!G9:G15),"",PRODUTOS!C9:C15-'CUSTOS DIRETOS x CUSTOS FIXOS'!G9:G15) -> -378.5 | L9: =IF(ISERROR(K9/PRODUTOS!C9),"",('CUSTOS DIRETOS x CUSTOS FIXOS'!K9/PRODUTOS!C9)) -> -0.84111111 | M9: =IF(ISERROR( (N9*PRODUTOS!C9)),"",('CUSTOS DIRETOS x CUSTOS FIXOS'!N9*PRODUTOS!C9)) -> 735.09186 | N9: =IF(ISERROR('PONTO DE EQUILÍBRIO'!$F$9*PRODUTOS!F9),"",'PONTO DE EQUILÍBRIO'!$F$9*PRODUTOS!F9) -> 1.6335375 | O9: =IF(ISERROR(PRODUTOS!D9*'CUSTOS DIRETOS x CUSTOS FIXOS'!F9),"",PRODUTOS!D9*'CUSTOS DIRETOS x CUSTOS FIXOS'!F9) -> 40000 | P9: =IF(ISERROR(PRODUTOS!D9*'CUSTOS DIRETOS x CUSTOS FIXOS'!C9),"",PRODUTOS!D9*'CUSTOS DIRETOS x CUSTOS FIXOS'!C9) -> 18000 | S9: =B9 -> Conjunto de Talheres de Prata | T9: =L9 -> -0.84111111 | U9: =COUNTIF(T$6:T9,T9) -> 1 | V9: =T9&U9 -> -0,8411111111111111
B10: Tapete Persa (3x4m) | C10: 50 | D10: 0.05 | E10: 0.18 | F10: 500 | G10: ='CUSTOS DIRETOS x CUSTOS FIXOS'!C10+PRODUTOS!C10*('CUSTOS DIRETOS x CUSTOS FIXOS'!D10+'CUSTOS DIRETOS x CUSTOS FIXOS'!E10)+'CUSTOS DIRETOS x CUSTOS FIXOS'!F10 -> 1010 | I10: =IF(ISERROR(PRODUTOS!E10*'CUSTOS DIRETOS x CUSTOS FIXOS'!D10),"",(PRODUTOS!E10*'CUSTOS DIRETOS x CUSTOS FIXOS'!D10)) -> 10000 | J10: =IF(ISERROR(PRODUTOS!E10*'CUSTOS DIRETOS x CUSTOS FIXOS'!E10),"",(PRODUTOS!E10*'CUSTOS DIRETOS x CUSTOS FIXOS'!E10)) -> 36000 | K10: =IF(ISERROR(PRODUTOS!C10:C15-'CUSTOS DIRETOS x CUSTOS FIXOS'!G10:G16),"",PRODUTOS!C10:C15-'CUSTOS DIRETOS x CUSTOS FIXOS'!G10:G16) -> 990 | L10: =IF(ISERROR(K10/PRODUTOS!C10),"",('CUSTOS DIRETOS x CUSTOS FIXOS'!K10/PRODUTOS!C10)) -> 0.495 | M10: =IF(ISERROR( (N10*PRODUTOS!C10)),"",('CUSTOS DIRETOS x CUSTOS FIXOS'!N10*PRODUTOS!C10)) -> 18150.416 | N10: =IF(ISERROR('PONTO DE EQUILÍBRIO'!$F$9*PRODUTOS!F10),"",'PONTO DE EQUILÍBRIO'!$F$9*PRODUTOS!F10) -> 9.0752082 | O10: =IF(ISERROR(PRODUTOS!D10*'CUSTOS DIRETOS x CUSTOS FIXOS'!F10),"",PRODUTOS!D10*'CUSTOS DIRETOS x CUSTOS FIXOS'!F10) -> 50000 | P10: =IF(ISERROR(PRODUTOS!D10*'CUSTOS DIRETOS x CUSTOS FIXOS'!C10),"",PRODUTOS!D10*'CUSTOS DIRETOS x CUSTOS FIXOS'!C10) -> 5000 | S10: =B10 -> Tapete Persa (3x4m) | T10: =L10 -> 0.495 | U10: =COUNTIF(T$6:T10,T10) -> 1 | V10: =T10&U10 -> 0,4951
B11: Cama King Size de Madeira | C11: 1000 | D11: 0.05 | E11: 0.18 | F11: 500 | G11: ='CUSTOS DIRETOS x CUSTOS FIXOS'!C11+PRODUTOS!C11*('CUSTOS DIRETOS x CUSTOS FIXOS'!D11+'CUSTOS DIRETOS x CUSTOS FIXOS'!E11)+'CUSTOS DIRETOS x CUSTOS FIXOS'!F11 -> 2075 | I11: =IF(ISERROR(PRODUTOS!E11*'CUSTOS DIRETOS x CUSTOS FIXOS'!D11),"",(PRODUTOS!E11*'CUSTOS DIRETOS x CUSTOS FIXOS'!D11)) -> 12500 | J11: =IF(ISERROR(PRODUTOS!E11*'CUSTOS DIRETOS x CUSTOS FIXOS'!E11),"",(PRODUTOS!E11*'CUSTOS DIRETOS x CUSTOS FIXOS'!E11)) -> 45000 | K11: =IF(ISERROR(PRODUTOS!C11:C15-'CUSTOS DIRETOS x CUSTOS FIXOS'!G11:G16),"",PRODUTOS!C11:C15-'CUSTOS DIRETOS x CUSTOS FIXOS'!G11:G16) -> 425 | L11: =IF(ISERROR(K11/PRODUTOS!C11),"",('CUSTOS DIRETOS x CUSTOS FIXOS'!K11/PRODUTOS!C11)) -> 0.17 | M11: =IF(ISERROR( (N11*PRODUTOS!C11)),"",('CUSTOS DIRETOS x CUSTOS FIXOS'!N11*PRODUTOS!C11)) -> 28360.026 | N11: =IF(ISERROR('PONTO DE EQUILÍBRIO'!$F$9*PRODUTOS!F11),"",'PONTO DE EQUILÍBRIO'!$F$9*PRODUTOS!F11) -> 11.34401 | O11: =IF(ISERROR(PRODUTOS!D11*'CUSTOS DIRETOS x CUSTOS FIXOS'!F11),"",PRODUTOS!D11*'CUSTOS DIRETOS x CUSTOS FIXOS'!F11) -> 50000 | P11: =IF(ISERROR(PRODUTOS!D11*'CUSTOS DIRETOS x CUSTOS FIXOS'!C11),"",PRODUTOS!D11*'CUSTOS DIRETOS x CUSTOS FIXOS'!C11) -> 100000 | S11: =B11 -> Cama King Size de Madeira | T11: =L11 -> 0.17 | U11: =COUNTIF(T$6:T11,T11) -> 1 | V11: =T11&U11 -> 0,171
B12: TV LED 100 | C12: 1000 | D12: 0.05 | E12: 0.18 | F12: 500 | G12: ='CUSTOS DIRETOS x CUSTOS FIXOS'!C12+PRODUTOS!C12*('CUSTOS DIRETOS x CUSTOS FIXOS'!D12+'CUSTOS DIRETOS x CUSTOS FIXOS'!E12)+'CUSTOS DIRETOS x CUSTOS FIXOS'!F12 -> 2190 | I12: =IF(ISERROR(PRODUTOS!E12*'CUSTOS DIRETOS x CUSTOS FIXOS'!D12),"",(PRODUTOS!E12*'CUSTOS DIRETOS x CUSTOS FIXOS'!D12)) -> 15000 | J12: =IF(ISERROR(PRODUTOS!E12*'CUSTOS DIRETOS x CUSTOS FIXOS'!E12),"",(PRODUTOS!E12*'CUSTOS DIRETOS x CUSTOS FIXOS'!E12)) -> 54000 | K12: =IF(ISERROR(PRODUTOS!C12:C15-'CUSTOS DIRETOS x CUSTOS FIXOS'!G12:G16),"",PRODUTOS!C12:C15-'CUSTOS DIRETOS x CUSTOS FIXOS'!G12:G16) -> 810 | L12: =IF(ISERROR(K12/PRODUTOS!C12),"",('CUSTOS DIRETOS x CUSTOS FIXOS'!K12/PRODUTOS!C12)) -> 0.27 | M12: =IF(ISERROR( (N12*PRODUTOS!C12)),"",('CUSTOS DIRETOS x CUSTOS FIXOS'!N12*PRODUTOS!C12)) -> 40838.437 | N12: =IF(ISERROR('PONTO DE EQUILÍBRIO'!$F$9*PRODUTOS!F12),"",'PONTO DE EQUILÍBRIO'!$F$9*PRODUTOS!F12) -> 13.612812 | O12: =IF(ISERROR(PRODUTOS!D12*'CUSTOS DIRETOS x CUSTOS FIXOS'!F12),"",PRODUTOS!D12*'CUSTOS DIRETOS x CUSTOS FIXOS'!F12) -> 50000 | P12: =IF(ISERROR(PRODUTOS!D12*'CUSTOS DIRETOS x CUSTOS FIXOS'!C12),"",PRODUTOS!D12*'CUSTOS DIRETOS x CUSTOS FIXOS'!C12) -> 100000 | S12: =B12 -> TV LED 100 | T12: =L12 -> 0.27 | U12: =COUNTIF(T$6:T12,T12) -> 1 | V12: =T12&U12 -> 0,271
B13: Frigobar de Inox | C13: 100 | D13: 0.05 | E13: 0.18 | F13: 500 | G13: =C13+'CUSTOS DIRETOS x CUSTOS FIXOS'!C13*('CUSTOS DIRETOS x CUSTOS FIXOS'!D13+'CUSTOS DIRETOS x CUSTOS FIXOS'!E13)+'CUSTOS DIRETOS x CUSTOS FIXOS'!F13 -> 623 | I13: =IF(ISERROR(PRODUTOS!E13*'CUSTOS DIRETOS x CUSTOS FIXOS'!D13),"",(PRODUTOS!E13*'CUSTOS DIRETOS x CUSTOS FIXOS'!D13)) -> 18000 | J13: =IF(ISERROR(PRODUTOS!E13*'CUSTOS DIRETOS x CUSTOS FIXOS'!E13),"",(PRODUTOS!E13*'CUSTOS DIRETOS x CUSTOS FIXOS'!E13)) -> 64800 | K13: =IF(ISERROR(PRODUTOS!C13-'CUSTOS DIRETOS x CUSTOS FIXOS'!G13),"",(PRODUTOS!C13-'CUSTOS DIRETOS x CUSTOS FIXOS'!G13)) -> 277 | L13: =IF(ISERROR(K13/PRODUTOS!C13),"",('CUSTOS DIRETOS x CUSTOS FIXOS'!K13/PRODUTOS!C13)) -> 0.30777778 | M13: =IF(ISERROR((N13*PRODUTOS!C13)),"",('CUSTOS DIRETOS x CUSTOS FIXOS'!N13*PRODUTOS!C13)) -> 14701.837 | N13: =IF(ISERROR('PONTO DE EQUILÍBRIO'!$F$9*PRODUTOS!F13),"",'PONTO DE EQUILÍBRIO'!$F$9*PRODUTOS!F13) -> 16.335375 | O13: =IF(ISERROR(PRODUTOS!D13*'CUSTOS DIRETOS x CUSTOS FIXOS'!F13),"",PRODUTOS!D13*'CUSTOS DIRETOS x CUSTOS FIXOS'!F13) -> 200000 | P13: =IF(ISERROR(PRODUTOS!D13*'CUSTOS DIRETOS x CUSTOS FIXOS'!C13),"",PRODUTOS!D13*'CUSTOS DIRETOS x CUSTOS FIXOS'!C13) -> 40000 | S13: =B13 -> Frigobar de Inox | T13: =L13 -> 0.30777778 | U13: =COUNTIF(T$6:T13,T13) -> 1 | V13: =T13&U13 -> 0,3077777777777781
B14: Ventilador de Design Moderno | C14: 50 | D14: 0.05 | E14: 0.18 | F14: 500 | G14: =C14+'CUSTOS DIRETOS x CUSTOS FIXOS'!C14*('CUSTOS DIRETOS x CUSTOS FIXOS'!D14+'CUSTOS DIRETOS x CUSTOS FIXOS'!E14)+'CUSTOS DIRETOS x CUSTOS FIXOS'!F14 -> 561.5 | I14: =IF(ISERROR(PRODUTOS!E14*'CUSTOS DIRETOS x CUSTOS FIXOS'!D14),"",(PRODUTOS!E14*'CUSTOS DIRETOS x CUSTOS FIXOS'!D14)) -> 15000 | J14: =IF(ISERROR(PRODUTOS!E14*'CUSTOS DIRETOS x CUSTOS FIXOS'!E14),"",(PRODUTOS!E14*'CUSTOS DIRETOS x CUSTOS FIXOS'!E14)) -> 54000 | K14: =IF(ISERROR(PRODUTOS!C14-'CUSTOS DIRETOS x CUSTOS FIXOS'!G14),"",(PRODUTOS!C14-'CUSTOS DIRETOS x CUSTOS FIXOS'!G14)) -> 38.5 | L14: =IF(ISERROR(K14/PRODUTOS!C14),"",('CUSTOS DIRETOS x CUSTOS FIXOS'!K14/PRODUTOS!C14)) -> 0.064166667 | M14: =IF(ISERROR((N14*PRODUTOS!C14)),"",('CUSTOS DIRETOS x CUSTOS FIXOS'!N14*PRODUTOS!C14)) -> 8167.6874 | N14: =IF(ISERROR('PONTO DE EQUILÍBRIO'!$F$9*PRODUTOS!F14),"",'PONTO DE EQUILÍBRIO'!$F$9*PRODUTOS!F14) -> 13.612812 | O14: =IF(ISERROR(PRODUTOS!D14*'CUSTOS DIRETOS x CUSTOS FIXOS'!F14),"",PRODUTOS!D14*'CUSTOS DIRETOS x CUSTOS FIXOS'!F14) -> 250000 | P14: =IF(ISERROR(PRODUTOS!D14*'CUSTOS DIRETOS x CUSTOS FIXOS'!C14),"",PRODUTOS!D14*'CUSTOS DIRETOS x CUSTOS FIXOS'!C14) -> 25000 | S14: =B14 -> Ventilador de Design Moderno | T14: =L14 -> 0.064166667 | U14: =COUNTIF(T$6:T14,T14) -> 1 | V14: =T14&U14 -> 0,06416666666666671
B15: Jogo de Cama de Seda (Queen) | C15: 30 | D15: 0.05 | E15: 0.18 | F15: 500 | G15: =C15+'CUSTOS DIRETOS x CUSTOS FIXOS'!C15*('CUSTOS DIRETOS x CUSTOS FIXOS'!D15+'CUSTOS DIRETOS x CUSTOS FIXOS'!E15)+'CUSTOS DIRETOS x CUSTOS FIXOS'!F15 -> 536.9 | I15: =IF(ISERROR(PRODUTOS!E15*'CUSTOS DIRETOS x CUSTOS FIXOS'!D15),"",(PRODUTOS!E15*'CUSTOS DIRETOS x CUSTOS FIXOS'!D15)) -> 20000 | J15: =IF(ISERROR(PRODUTOS!E15*'CUSTOS DIRETOS x CUSTOS FIXOS'!E15),"",(PRODUTOS!E15*'CUSTOS DIRETOS x CUSTOS FIXOS'!E15)) -> 72000 | K15: =IF(ISERROR(PRODUTOS!C15-'CUSTOS DIRETOS x CUSTOS FIXOS'!G15),"",(PRODUTOS!C15-'CUSTOS DIRETOS x CUSTOS FIXOS'!G15)) -> 263.1 | L15: =IF(ISERROR(K15/PRODUTOS!C15),"",('CUSTOS DIRETOS x CUSTOS FIXOS'!K15/PRODUTOS!C15)) -> 0.328875 | M15: =IF(ISERROR((N15*PRODUTOS!C15)),"",('CUSTOS DIRETOS x CUSTOS FIXOS'!N15*PRODUTOS!C15)) -> 14520.333 | N15: =IF(ISERROR('PONTO DE EQUILÍBRIO'!$F$9*PRODUTOS!F15),"",'PONTO DE EQUILÍBRIO'!$F$9*PRODUTOS!F15) -> 18.150416 | O15: =IF(ISERROR(PRODUTOS!D15*'CUSTOS DIRETOS x CUSTOS FIXOS'!F15),"",PRODUTOS!D15*'CUSTOS DIRETOS x CUSTOS FIXOS'!F15) -> 250000 | P15: =IF(ISERROR(PRODUTOS!D15*'CUSTOS DIRETOS x CUSTOS FIXOS'!C15),"",PRODUTOS!D15*'CUSTOS DIRETOS x CUSTOS FIXOS'!C15) -> 15000 | S15: =B15 -> Jogo de Cama de Seda (Queen) | T15: =L15 -> 0.328875 | U15: =COUNTIF(T$6:T15,T15) -> 1 | V15: =T15&U15 -> 0,3288751
B18: Custos Fixos | C18: Valor
B19: Software e Licenças de Sistemas | C19: 12000
B20: Marketing e Publicidade de Longo Prazo | C20: 10000
B21: Aluguel de Móveis | C21: 6500
B22: Água e Saneamento | C22: 2300
B23: Licenças e Taxas Governamentais | C23: 2000
B24: Manutenção de Equipamentos | C24: 1900
B25: Seguros | C25: 1350
B26: Contas de Energia Elétrica | C26: 1220
B27: Depreciação de Equipamentos | C27: 980
B28: Salários e Benefícios | C28: 600

Sheet RELATÓRIO
B5: Custos Diretos | G5: Custos Fixos | L5: Produtos | M5: Quantidade a ser vendida | N5: Receita Gerada | S5: AUXILIAR01 | U5: AUXILIAR02
B6: Matéria Prima | D6: =SUM('CUSTOS DIRETOS x CUSTOS FIXOS'!P6:P1048576) -> 476500 | E6: =B6 -> Matéria Prima | G6: =IF('CUSTOS DIRETOS x CUSTOS FIXOS'!B19="", "", 'CUSTOS DIRETOS x CUSTOS FIXOS'!B19) -> Software e Licenças de Sistemas | I6: =IFERROR(VLOOKUP(G6,'CUSTOS DIRETOS x CUSTOS FIXOS'!$B$19:$C$1048576,2,0),"") -> 12000 | L6: =IF(PRODUTOS!B14="", "", PRODUTOS!B14) -> Ventilador de Design Moderno | M6: =IFERROR(VLOOKUP($L6,'CUSTOS DIRETOS x CUSTOS FIXOS'!$B$14:$N$21,13,0),"") -> 13.612812 | N6: =IFERROR(VLOOKUP(L6,'CUSTOS DIRETOS x CUSTOS FIXOS'!$B$14:$M$21,12,0),"") -> 8167.6874 | Q6: =L6 -> Ventilador de Design Moderno | R6: =M6 -> 13.612812 | S6: =COUNTIF(R6:R$6,R6) -> 1 | U6: =R6&S6 -> 13,61281228366611
B7: Impostos % | D7: =SUM('CUSTOS DIRETOS x CUSTOS FIXOS'!$J$6:$J$1048576) -> 411930 | E7: =B7 -> Impostos % | G7: =IF('CUSTOS DIRETOS x CUSTOS FIXOS'!B20="", "", 'CUSTOS DIRETOS x CUSTOS FIXOS'!B20) -> Marketing e Publicidade de Longo Prazo | I7: =IFERROR(VLOOKUP(G7,'CUSTOS DIRETOS x CUSTOS FIXOS'!$B$19:$C$1048576,2,0),"") -> 10000 | L7: =IF(PRODUTOS!B12="", "", PRODUTOS!B12) -> TV LED 100 | M7: =IFERROR(VLOOKUP(L7,'CUSTOS DIRETOS x CUSTOS FIXOS'!B12:N19,13,0),"") -> 13.612812 | N7: =IFERROR(VLOOKUP(L7,'CUSTOS DIRETOS x CUSTOS FIXOS'!$B$12:$M$19,12,0),"") -> 40838.437 | Q7: =L7 -> TV LED 100 | R7: =M7 -> 13.612812 | S7: =COUNTIF(R$6:R7,R7) -> 2 | U7: =R7&S7 -> 13,61281228366612
B8: Comissões % | D8: =SUM('CUSTOS DIRETOS x CUSTOS FIXOS'!$I$6:$I$1048576) -> 114425 | E8: =B8 -> Comissões % | G8: =IF('CUSTOS DIRETOS x CUSTOS FIXOS'!B21="", "", 'CUSTOS DIRETOS x CUSTOS FIXOS'!B21) -> Aluguel de Móveis | I8: =IFERROR(VLOOKUP(G8,'CUSTOS DIRETOS x CUSTOS FIXOS'!$B$19:$C$1048576,2,0),"") -> 6500 | L8: =IF(PRODUTOS!B10="", "", PRODUTOS!B10) -> Tapete Persa (3x4m) | M8: =IFERROR(VLOOKUP(L8,'CUSTOS DIRETOS x CUSTOS FIXOS'!B10:N17,13,0),"") -> 9.0752082 | N8: =IFERROR(VLOOKUP(L8,'CUSTOS DIRETOS x CUSTOS FIXOS'!$B$10:$M$17,12,0),"") -> 18150.416 | Q8: =L8 -> Tapete Persa (3x4m) | R8: =M8 -> 9.0752082 | S8: =COUNTIF(R$6:R8,R8) -> 1 | U8: =R8&S8 -> 9,075208189110731
B9: Outros Gastos | D9: =IFERROR(SUM('CUSTOS DIRETOS x CUSTOS FIXOS'!$F$6:$F$1048576),"") -> 5100 | E9: =B9 -> Outros Gastos | G9: =IF('CUSTOS DIRETOS x CUSTOS FIXOS'!B22="", "", 'CUSTOS DIRETOS x CUSTOS FIXOS'!B22) -> Água e Saneamento | I9: =IFERROR(VLOOKUP(G9,'CUSTOS DIRETOS x CUSTOS FIXOS'!$B$19:$C$1048576,2,0),"") -> 2300 | L9: =IF(PRODUTOS!B6="", "", PRODUTOS!B6) -> Sofá de Couro Italiano | M9: =IFERROR(VLOOKUP(L9,'CUSTOS DIRETOS x CUSTOS FIXOS'!B6:N15,13,0),"") -> 12.705291 | N9: =IFERROR(VLOOKUP(L9,'CUSTOS DIRETOS x CUSTOS FIXOS'!$B$6:$M$15,12,0),"") -> 44468.52 | Q9: =L9 -> Sofá de Couro Italiano | R9: =M9 -> 12.705291 | S9: =COUNTIF(R$6:R9,R9) -> 1 | U9: =R9&S9 -> 12,7052914647551
G10: =IF('CUSTOS DIRETOS x CUSTOS FIXOS'!B23="", "", 'CUSTOS DIRETOS x CUSTOS FIXOS'!B23) -> Licenças e Taxas Governamentais | I10: =IFERROR(VLOOKUP(G10,'CUSTOS DIRETOS x CUSTOS FIXOS'!$B$19:$C$1048576,2,0),"") -> 2000 | L10: =IF(PRODUTOS!B7="", "", PRODUTOS!B7) -> Máquina de Café Expresso | M10: =IFERROR(VLOOKUP(L10,'CUSTOS DIRETOS x CUSTOS FIXOS'!B7:N16,13,0),"") -> 5.4451249 | N10: =IFERROR(VLOOKUP(L10,'CUSTOS DIRETOS x CUSTOS FIXOS'!$B$7:$M$16,12,0),"") -> 6534.1499 | Q10: =L10 -> Máquina de Café Expresso | R10: =M10 -> 5.4451249 | S10: =COUNTIF(R$6:R10,R10) -> 1 | U10: =R10&S10 -> 5,445124913466441
G11: =IF('CUSTOS DIRETOS x CUSTOS FIXOS'!B24="", "", 'CUSTOS DIRETOS x CUSTOS FIXOS'!B24) -> Manutenção de Equipamentos | I11: =IFERROR(VLOOKUP(G11,'CUSTOS DIRETOS x CUSTOS FIXOS'!$B$19:$C$1048576,2,0),"") -> 1900 | L11: =IF(PRODUTOS!B8="", "", PRODUTOS!B8) -> Luminária de Cristal (1,5m) | M11: =IFERROR(VLOOKUP(L11,'CUSTOS DIRETOS x CUSTOS FIXOS'!B8:N16,13,0),"") -> 1.9284817 | N11: =IFERROR(VLOOKUP(L11,'CUSTOS DIRETOS x CUSTOS FIXOS'!$B$8:$M$16,12,0),"") -> 1639.2095 | Q11: =L11 -> Luminária de Cristal (1,5m) | R11: =M11 -> 1.9284817 | S11: =COUNTIF(R$6:R11,R11) -> 1 | U11: =R11&S11 -> 1,928481740186031
G12: =IF('CUSTOS DIRETOS x CUSTOS FIXOS'!B25="", "", 'CUSTOS DIRETOS x CUSTOS FIXOS'!B25) -> Seguros | I12: =IFERROR(VLOOKUP(G12,'CUSTOS DIRETOS x CUSTOS FIXOS'!$B$19:$C$1048576,2,0),"") -> 1350 | L12: =IF(PRODUTOS!B15="", "", PRODUTOS!B15) -> Jogo de Cama de Seda (Queen) | M12: =IFERROR(VLOOKUP(L12,'CUSTOS DIRETOS x CUSTOS FIXOS'!B15:N22,13,0),"") -> 18.150416 | N12: =IFERROR(VLOOKUP(L12,'CUSTOS DIRETOS x CUSTOS FIXOS'!$B$15:$M$22,12,0),"") -> 14520.333 | Q12: =L12 -> Jogo de Cama de Seda (Queen) | R12: =M12 -> 18.150416 | S12: =COUNTIF(R$6:R12,R12) -> 1 | U12: =R12&S12 -> 18,15041637822151
G13: =IF('CUSTOS DIRETOS x CUSTOS FIXOS'!B26="", "", 'CUSTOS DIRETOS x CUSTOS FIXOS'!B26) -> Contas de Energia Elétrica | I13: =IFERROR(VLOOKUP(G13,'CUSTOS DIRETOS x CUSTOS FIXOS'!$B$19:$C$1048576,2,0),"") -> 1220 | L13: =IF(PRODUTOS!B13="", "", PRODUTOS!B13) -> Frigobar de Inox | M13: =IFERROR(VLOOKUP(L13,'CUSTOS DIRETOS x CUSTOS FIXOS'!B13:N20,13,0),"") -> 16.335375 | N13: =IFERROR(VLOOKUP(L13,'CUSTOS DIRETOS x CUSTOS FIXOS'!$B$13:$M$20,12,0),"") -> 14701.837 | Q13: =L13 -> Frigobar de Inox | R13: =M13 -> 16.335375 | S13: =COUNTIF(R$6:R13,R13) -> 1 | U13: =R13&S13 -> 16,33537474039931
G14: =IF('CUSTOS DIRETOS x CUSTOS FIXOS'!B27="", "", 'CUSTOS DIRETOS x CUSTOS FIXOS'!B27) -> Depreciação de Equipamentos | I14: =IFERROR(VLOOKUP(G14,'CUSTOS DIRETOS x CUSTOS FIXOS'!$B$19:$C$1048576,2,0),"") -> 980 | L14: =IF(PRODUTOS!B9="", "", PRODUTOS!B9) -> Conjunto de Talheres de Prata | M14: =IFERROR(VLOOKUP(L14,'CUSTOS DIRETOS x CUSTOS FIXOS'!B9:N16,13,0),"") -> 1.6335375 | N14: =IFERROR(VLOOKUP(L14,'CUSTOS DIRETOS x CUSTOS FIXOS'!$B$9:$M$16,12,0),"") -> 735.09186 | Q14: =L14 -> Conjunto de Talheres de Prata | R14: =M14 -> 1.6335375 | S14: =COUNTIF(R$6:R14,R14) -> 1 | U14: =R14&S14 -> 1,633537474039931
G15: =IF('CUSTOS DIRETOS x CUSTOS FIXOS'!B28="", "", 'CUSTOS DIRETOS x CUSTOS FIXOS'!B28) -> Salários e Benefícios | I15: =IFERROR(VLOOKUP(G15,'CUSTOS DIRETOS x CUSTOS FIXOS'!$B$19:$C$1048576,2,0),"") -> 600 | L15: =IF(PRODUTOS!B11="", "", PRODUTOS!B11) -> Cama King Size de Madeira | M15: =IFERROR(VLOOKUP(L15,'CUSTOS DIRETOS x CUSTOS FIXOS'!B11:N18,13,0),"") -> 11.34401 | N15: =IFERROR(VLOOKUP(L15,'CUSTOS DIRETOS x CUSTOS FIXOS'!$B$11:$M$18,12,0),"") -> 28360.026 | Q15: =L15 -> Cama King Size de Madeira | R15: =M15 -> 11.34401 | S15: =COUNTIF(R$6:R15,R15) -> 1 | U15: =R15&S15 -> 11,34401023638841
G16: =IF('CUSTOS DIRETOS x CUSTOS FIXOS'!B29="", "", 'CUSTOS DIRETOS x CUSTOS FIXOS'!B29) | I16: =IFERROR(VLOOKUP(G16,'CUSTOS DIRETOS x CUSTOS FIXOS'!$B$19:$C$1048576,2,0),"") | L16: =IF(PRODUTOS!B24="", "", PRODUTOS!B24) | M16: =IFERROR(VLOOKUP(L16,'CUSTOS DIRETOS x CUSTOS FIXOS'!B16:N23,13,0),"") | N16: =IFERROR(VLOOKUP(L16,'CUSTOS DIRETOS x CUSTOS FIXOS'!B16:M23,12,0),"")
G17: =IF('CUSTOS DIRETOS x CUSTOS FIXOS'!B30="", "", 'CUSTOS DIRETOS x CUSTOS FIXOS'!B30) | I17: =IFERROR(VLOOKUP(G17,'CUSTOS DIRETOS x CUSTOS FIXOS'!$B$19:$C$1048576,2,0),"") | L17: =IF(PRODUTOS!B22="", "", PRODUTOS!B22) | M17: =IFERROR(VLOOKUP(L17,'CUSTOS DIRETOS x CUSTOS FIXOS'!B17:N24,13,0),"") | N17: =IFERROR(VLOOKUP(L17,'CUSTOS DIRETOS x CUSTOS FIXOS'!B17:M24,12,0),"")
G18: =IF('CUSTOS DIRETOS x CUSTOS FIXOS'!B31="", "", 'CUSTOS DIRETOS x CUSTOS FIXOS'!B31) | I18: =IFERROR(VLOOKUP(G18,'CUSTOS DIRETOS x CUSTOS FIXOS'!$B$19:$C$1048576,2,0),"") | L18: =IF(PRODUTOS!B20="", "", PRODUTOS!B20) | M18: =IFERROR(VLOOKUP(L18,'CUSTOS DIRETOS x CUSTOS FIXOS'!B17:N25,13,0),"") | N18: =IFERROR(VLOOKUP(L18,'CUSTOS DIRETOS x CUSTOS FIXOS'!B17:M25,12,0),"")
G19: =IF('CUSTOS DIRETOS x CUSTOS FIXOS'!B32="", "", 'CUSTOS DIRETOS x CUSTOS FIXOS'!B32) | I19: =IFERROR(VLOOKUP(G19,'CUSTOS DIRETOS x CUSTOS FIXOS'!$B$19:$C$1048576,2,0),"") | L19: =IF(PRODUTOS!B16="", "", PRODUTOS!B16) | M19: =IFERROR(VLOOKUP(L19,'CUSTOS DIRETOS x CUSTOS FIXOS'!B17:N26,13,0),"") | N19: =IFERROR(VLOOKUP(L19,'CUSTOS DIRETOS x CUSTOS FIXOS'!B17:M26,12,0),"")
G20: =IF('CUSTOS DIRETOS x CUSTOS FIXOS'!B33="", "", 'CUSTOS DIRETOS x CUSTOS FIXOS'!B33) | I20: =IFERROR(VLOOKUP(G20,'CUSTOS DIRETOS x CUSTOS FIXOS'!$B$19:$C$1048576,2,0),"") | L20: =IF(PRODUTOS!B17="", "", PRODUTOS!B17) | M20: =IFERROR(VLOOKUP(L20,'CUSTOS DIRETOS x CUSTOS FIXOS'!B18:N27,13,0),"") | N20: =IFERROR(VLOOKUP(L20,'CUSTOS DIRETOS x CUSTOS FIXOS'!B18:M27,12,0),"")
G21: =IF('CUSTOS DIRETOS x CUSTOS FIXOS'!B34="", "", 'CUSTOS DIRETOS x CUSTOS FIXOS'!B34) | I21: =IFERROR(VLOOKUP(G21,'CUSTOS DIRETOS x CUSTOS FIXOS'!$B$19:$C$1048576,2,0),"") | L21: =IF(PRODUTOS!B18="", "", PRODUTOS!B18) | M21: =IFERROR(VLOOKUP(L21,'CUSTOS DIRETOS x CUSTOS FIXOS'!B19:N28,13,0),"") | N21: =IFERROR(VLOOKUP(L21,'CUSTOS DIRETOS x CUSTOS FIXOS'!B19:M28,12,0),"")
G22: =IF('CUSTOS DIRETOS x CUSTOS FIXOS'!B35="", "", 'CUSTOS DIRETOS x CUSTOS FIXOS'!B35) | I22: =IFERROR(VLOOKUP(G22,'CUSTOS DIRETOS x CUSTOS FIXOS'!$B$19:$C$1048576,2,0),"") | L22: =IF(PRODUTOS!B25="", "", PRODUTOS!B25) | M22: =IFERROR(VLOOKUP(L22,'CUSTOS DIRETOS x CUSTOS FIXOS'!B20:N29,13,0),"") | N22: =IFERROR(VLOOKUP(L22,'CUSTOS DIRETOS x CUSTOS FIXOS'!B20:M29,12,0),"")
G23: =IF('CUSTOS DIRETOS x CUSTOS FIXOS'!B36="", "", 'CUSTOS DIRETOS x CUSTOS FIXOS'!B36) | I23: =IFERROR(VLOOKUP(G23,'CUSTOS DIRETOS x CUSTOS FIXOS'!$B$19:$C$1048576,2,0),"") | L23: =IF(PRODUTOS!B23="", "", PRODUTOS!B23) | M23: =IFERROR(VLOOKUP(L23,'CUSTOS DIRETOS x CUSTOS FIXOS'!B21:N30,13,0),"") | N23: =IFERROR(VLOOKUP(L23,'CUSTOS DIRETOS x CUSTOS FIXOS'!B21:M30,12,0),"")
G24: =IF('CUSTOS DIRETOS x CUSTOS FIXOS'!B37="", "", 'CUSTOS DIRETOS x CUSTOS FIXOS'!B37) | I24: =IFERROR(VLOOKUP(G24,'CUSTOS DIRETOS x CUSTOS FIXOS'!$B$19:$C$1048576,2,0),"") | L24: =IF(PRODUTOS!B19="", "", PRODUTOS!B19) | M24: =IFERROR(VLOOKUP(L24,'CUSTOS DIRETOS x CUSTOS FIXOS'!B22:N31,13,0),"") | N24: =IFERROR(VLOOKUP(L24,'CUSTOS DIRETOS x CUSTOS FIXOS'!B22:M31,12,0),"")
C25: Total | D25: =SUM(D6:D24) -> 1007955 | H25: Total | I25: =SUM(I6:I24) -> 38850 | L25: =IF(PRODUTOS!B21="", "", PRODUTOS!B21) | M25: =IFERROR(VLOOKUP(L25,'CUSTOS DIRETOS x CUSTOS FIXOS'!B23:N32,13,0),"") | N25: =IFERROR(VLOOKUP(L25,'CUSTOS DIRETOS x CUSTOS FIXOS'!B23:M32,12,0),"")

Sheet PONTO DE EQUILÍBRIO
B5: MARGEM DE CONTRIBUÇÃO | E5: PONTO DE EQUILÍBRIO | H5: Selecione o Produto:
B6: DESCRIÇÃO | C6: VALOR | E6: Ponto de Equilíbrio por CUSTOS FIXOS | H6: Ponto de equilíbrio por PRODUTO | I6: Jogo de Cama de Seda (Queen)
B7: Preço de venda médio de produtos | C7: =IF(ISERROR(AVERAGEIF(PRODUTOS!$C$6:$C$1048576,">0")),"",AVERAGEIF(PRODUTOS!$C$6:$C$1048576,">0")) -> 1580 | E7: Valor total de CUSTOS FIXOS | F7: =SUM('CUSTOS DIRETOS x CUSTOS FIXOS'!C19:C28) -> 38850 | H7: ="Receita do(a) "&I6&" no Ponto de Equilíbrio" -> Receita do(a) Jogo de Cama de Seda (Queen) no Ponto de Equilíbrio | I7: =VLOOKUP(I6,'CUSTOS DIRETOS x CUSTOS FIXOS'!$B$6:$M$15,12,0) -> 14520.333
B8: Margem de contribuição média de produtos | C8: =IF(ISERROR( AVERAGEIF('CUSTOS DIRETOS x CUSTOS FIXOS'!$K$6:$K$15,">0")),"",AVERAGEIF('CUSTOS DIRETOS x CUSTOS FIXOS'!$K$6:$K$15,">0")) -> 374.12222 | E8: Faturamento para não ter prejuízo | F8: =IF(ISERROR(F7/('PONTO DE EQUILÍBRIO'!C8/'PONTO DE EQUILÍBRIO'!C7)),"",'PONTO DE EQUILÍBRIO'!F7/('PONTO DE EQUILÍBRIO'!C8/'PONTO DE EQUILÍBRIO'!C7)) -> 164072.05 | H8: Unidades | I8: =VLOOKUP(I6,'CUSTOS DIRETOS x CUSTOS FIXOS'!B6:N1048576,13,0) -> 18.150416
B9: Custos diretos totais | C9: =SUM('CUSTOS DIRETOS x CUSTOS FIXOS'!$G$6:$G$15) -> 12811.4 | E9: Quantidade produtos devem ser vendidos para não ter prejuízo? | F9: =IF(ISERROR(F8/'PONTO DE EQUILÍBRIO'!C7),"",'PONTO DE EQUILÍBRIO'!F8/'PONTO DE EQUILÍBRIO'!C7) -> 103.84307 | H9: Total de despesas diretas | I9: =VLOOKUP(I6,'CUSTOS DIRETOS x CUSTOS FIXOS'!B6:G1048576,6,0)*I8 -> 9744.9586
H10: MC unitária | I10: =VLOOKUP(I6,'CUSTOS DIRETOS x CUSTOS FIXOS'!B6:K15,10,0) -> 263.1
H11: MC ponderada | I11: =IF(ISERROR(I10*VLOOKUP(I6,PRODUTOS!B6:F15,5,0)),"",I10*VLOOKUP(I6,PRODUTOS!B6:F15,5,0)) -> 45.986454

Sheet GRÁFICOS
AI4: Receita
AI5: Ranking | AJ5: Valor | AK5: Produto | AL5: Valor
AI6: 1 | AJ6: =LARGE(RELATÓRIO!$N$6:$N$15,GRÁFICOS!AI6) -> 44468.52 | AK6: =INDEX(RELATÓRIO!$L$6:$L$25, MATCH(LARGE(RELATÓRIO!$N$6:$N$25, ROW(1:1)), RELATÓRIO!$N$6:$N$25, 0)) -> Sofá de Couro Italiano | AL6: =AJ6 -> 44468.52
AI7: 2 | AJ7: =LARGE(RELATÓRIO!$N$6:$N$15,GRÁFICOS!AI7) -> 40838.437 | AK7: =INDEX(RELATÓRIO!$L$6:$L$25, MATCH(LARGE(RELATÓRIO!$N$6:$N$25, ROW(2:2)), RELATÓRIO!$N$6:$N$25, 0)) -> TV LED 100 | AL7: =AJ7 -> 40838.437
AI8: 3 | AJ8: =LARGE(RELATÓRIO!$N$6:$N$15,GRÁFICOS!AI8) -> 28360.026 | AK8: =INDEX(RELATÓRIO!$L$6:$L$25, MATCH(LARGE(RELATÓRIO!$N$6:$N$25, ROW(3:3)), RELATÓRIO!$N$6:$N$25, 0)) -> Cama King Size de Madeira | AL8: =AJ8 -> 28360.026
AI9: 4 | AJ9: =LARGE(RELATÓRIO!$N$6:$N$15,GRÁFICOS!AI9) -> 18150.416 | AK9: =INDEX(RELATÓRIO!$L$6:$L$25, MATCH(LARGE(RELATÓRIO!$N$6:$N$25, ROW(4:4)), RELATÓRIO!$N$6:$N$25, 0)) -> Tapete Persa (3x4m) | AL9: =AJ9 -> 18150.416
AI10: 5 | AJ10: =LARGE(RELATÓRIO!$N$6:$N$15,GRÁFICOS!AI10) -> 14701.837 | AK10: =INDEX(RELATÓRIO!$L$6:$L$25, MATCH(LARGE(RELATÓRIO!$N$6:$N$25, ROW(5:5)), RELATÓRIO!$N$6:$N$25, 0)) -> Frigobar de Inox | AL10: =AJ10 -> 14701.837
AI12: Quantidade
AI13: Ranking | AJ13: Quantidade | AK13: Produto | AL13: auxiliar01 | AM13: auxiliar02
AI14: 1 | AJ14: =LARGE(RELATÓRIO!$R$6:$R$15,ROW(A1)) -> 18.150416 | AK14: =INDEX(RELATÓRIO!$Q$6:$Q$15, MATCH(LARGE(RELATÓRIO!$R$6:$R$15, ROW(1:1)), RELATÓRIO!$R$6:$R$15, 0)) -> Jogo de Cama de Seda (Queen) | AL14: =COUNTIF(AJ14:$AJ$14,AJ14) -> 1 | AM14: =AJ14&AL14 -> 18,15041637822151 | AN14: =INDEX(RELATÓRIO!$Q$6:$Q$15, MATCH(GRÁFICOS!AM14, RELATÓRIO!$U$6:$U$15, 0)) -> Jogo de Cama de Seda (Queen) | AO14: =AJ14 -> 18.150416
AI15: 2 | AJ15: =LARGE(RELATÓRIO!$R$6:$R$15,ROW(A2)) -> 16.335375 | AK15: =INDEX(RELATÓRIO!$Q$6:$Q$15, MATCH(LARGE(RELATÓRIO!$R$6:$R$15, ROW(2:2)), RELATÓRIO!$R$6:$R$15, 0)) -> Frigobar de Inox | AL15: =COUNTIF(AJ$14:$AJ15,AJ15) -> 1 | AM15: =AJ15&AL15 -> 16,33537474039931 | AN15: =INDEX(RELATÓRIO!$Q$6:$Q$15, MATCH(GRÁFICOS!AM15, RELATÓRIO!$U$6:$U$15, 0)) -> Frigobar de Inox | AO15: =AJ15 -> 16.335375
AI16: 3 | AJ16: =LARGE(RELATÓRIO!$R$6:$R$15,ROW(A3)) -> 13.612812 | AK16: =INDEX(RELATÓRIO!$Q$6:$Q$15, MATCH(LARGE(RELATÓRIO!$R$6:$R$15, ROW(3:3)), RELATÓRIO!$R$6:$R$15, 0)) -> Ventilador de Design Moderno | AL16: =COUNTIF(AJ$14:$AJ16,AJ16) -> 1 | AM16: =AJ16&AL16 -> 13,61281228366611 | AN16: =INDEX(RELATÓRIO!$Q$6:$Q$15, MATCH(GRÁFICOS!AM16, RELATÓRIO!$U$6:$U$15, 0)) -> Ventilador de Design Moderno | AO16: =AJ16 -> 13.612812
AI17: 4 | AJ17: =LARGE(RELATÓRIO!$R$6:$R$15,ROW(A4)) -> 13.612812 | AK17: =INDEX(RELATÓRIO!$Q$6:$Q$15, MATCH(LARGE(RELATÓRIO!$R$6:$R$15, ROW(4:4)), RELATÓRIO!$R$6:$R$15, 0)) -> Ventilador de Design Moderno | AL17: =COUNTIF(AJ$14:$AJ17,AJ17) -> 2 | AM17: =AJ17&AL17 -> 13,61281228366612 | AN17: =INDEX(RELATÓRIO!$Q$6:$Q$15, MATCH(GRÁFICOS!AM17, RELATÓRIO!$U$6:$U$15, 0)) -> TV LED 100 | AO17: =AJ17 -> 13.612812
AI18: 5 | AJ18: =LARGE(RELATÓRIO!$R$6:$R$15,ROW(A5)) -> 12.705291 | AK18: =INDEX(RELATÓRIO!$Q$6:$Q$15, MATCH(LARGE(RELATÓRIO!$R$6:$R$15, ROW(5:5)), RELATÓRIO!$R$6:$R$15, 0)) -> Sofá de Couro Italiano | AL18: =COUNTIF(AJ$14:$AJ18,AJ18) -> 1 | AM18: =AJ18&AL18 -> 12,7052914647551 | AN18: =INDEX(RELATÓRIO!$Q$6:$Q$15, MATCH(GRÁFICOS!AM18, RELATÓRIO!$U$6:$U$15, 0)) -> Sofá de Couro Italiano | AO18: =AJ18 -> 12.705291
AI19: 6 | AJ19: =LARGE(RELATÓRIO!$R$6:$R$15,ROW(A6)) -> 11.34401 | AK19: =INDEX(RELATÓRIO!$Q$6:$Q$15, MATCH(LARGE(RELATÓRIO!$R$6:$R$15, ROW(6:6)), RELATÓRIO!$R$6:$R$15, 0)) -> Cama King Size de Madeira | AL19: =COUNTIF(AJ$14:$AJ19,AJ19) -> 1 | AM19: =AJ19&AL19 -> 11,34401023638841 | AN19: =INDEX(RELATÓRIO!$Q$6:$Q$15, MATCH(GRÁFICOS!AM19, RELATÓRIO!$U$6:$U$15, 0)) -> Cama King Size de Madeira | AO19: =AJ19 -> 11.34401
AI20: 7 | AJ20: =LARGE(RELATÓRIO!$R$6:$R$15,ROW(A7)) -> 9.0752082 | AK20: =INDEX(RELATÓRIO!$Q$6:$Q$15, MATCH(LARGE(RELATÓRIO!$R$6:$R$15, ROW(7:7)), RELATÓRIO!$R$6:$R$15, 0)) -> Tapete Persa (3x4m) | AL20: =COUNTIF(AJ$14:$AJ20,AJ20) -> 1 | AM20: =AJ20&AL20 -> 9,075208189110731 | AN20: =INDEX(RELATÓRIO!$Q$6:$Q$15, MATCH(GRÁFICOS!AM20, RELATÓRIO!$U$6:$U$15, 0)) -> Tapete Persa (3x4m) | AO20: =AJ20 -> 9.0752082
AI21: 8 | AJ21: =LARGE(RELATÓRIO!$R$6:$R$15,ROW(A8)) -> 5.4451249 | AK21: =INDEX(RELATÓRIO!$Q$6:$Q$15, MATCH(LARGE(RELATÓRIO!$R$6:$R$15, ROW(8:8)), RELATÓRIO!$R$6:$R$15, 0)) -> Máquina de Café Expresso | AL21: =COUNTIF(AJ$14:$AJ21,AJ21) -> 1 | AM21: =AJ21&AL21 -> 5,445124913466441 | AN21: =INDEX(RELATÓRIO!$Q$6:$Q$15, MATCH(GRÁFICOS!AM21, RELATÓRIO!$U$6:$U$15, 0)) -> Máquina de Café Expresso | AO21: =AJ21 -> 5.4451249
AI22: 9 | AJ22: =LARGE(RELATÓRIO!$R$6:$R$15,ROW(A9)) -> 1.9284817 | AK22: =INDEX(RELATÓRIO!$Q$6:$Q$15, MATCH(LARGE(RELATÓRIO!$R$6:$R$15, ROW(9:9)), RELATÓRIO!$R$6:$R$15, 0)) -> Luminária de Cristal (1,5m) | AL22: =COUNTIF(AJ$14:$AJ22,AJ22) -> 1 | AM22: =AJ22&AL22 -> 1,928481740186031 | AN22: =INDEX(RELATÓRIO!$Q$6:$Q$15, MATCH(GRÁFICOS!AM22, RELATÓRIO!$U$6:$U$15, 0)) -> Luminária de Cristal (1,5m) | AO22: =AJ22 -> 1.9284817
AI23: 10 | AJ23: =LARGE(RELATÓRIO!$R$6:$R$15,ROW(A10)) -> 1.6335375 | AK23: =INDEX(RELATÓRIO!$Q$6:$Q$15, MATCH(LARGE(RELATÓRIO!$R$6:$R$15, ROW(10:10)), RELATÓRIO!$R$6:$R$15, 0)) -> Conjunto de Talheres de Prata | AL23: =COUNTIF(AJ$14:$AJ23,AJ23) -> 1 | AM23: =AJ23&AL23 -> 1,633537474039931 | AN23: =INDEX(RELATÓRIO!$Q$6:$Q$15, MATCH(GRÁFICOS!AM23, RELATÓRIO!$U$6:$U$15, 0)) -> Conjunto de Talheres de Prata | AO23: =AJ23 -> 1.6335375
AI25: IMC
AI26: Ranking | AJ26: % | AK26: Produto
AI27: 1 | AJ27: =LARGE('CUSTOS DIRETOS x CUSTOS FIXOS'!$T$6:$T$15,1) -> 0.495 | AK27: =INDEX('CUSTOS DIRETOS x CUSTOS FIXOS'!$S$6:$S$15, MATCH(LARGE('CUSTOS DIRETOS x CUSTOS FIXOS'!$T$6:$T$15, ROW(1:1)),'CUSTOS DIRETOS x CUSTOS FIXOS'!$T$6:$T$15, 0)) -> Tapete Persa (3x4m) | AL27: =AJ27 -> 0.495
AI28: 2 | AJ28: =LARGE('CUSTOS DIRETOS x CUSTOS FIXOS'!$T$6:$T$15,2) -> 0.328875 | AK28: =INDEX('CUSTOS DIRETOS x CUSTOS FIXOS'!$S$6:$S$15, MATCH(LARGE('CUSTOS DIRETOS x CUSTOS FIXOS'!$T$6:$T$15, ROW(2:2)),'CUSTOS DIRETOS x CUSTOS FIXOS'!$T$6:$T$15, 0)) -> Jogo de Cama de Seda (Queen) | AL28: =AJ28 -> 0.328875
AI29: 3 | AJ29: =LARGE('CUSTOS DIRETOS x CUSTOS FIXOS'!$T$6:$T$15,3) -> 0.30777778 | AK29: =INDEX('CUSTOS DIRETOS x CUSTOS FIXOS'!$S$6:$S$15, MATCH(LARGE('CUSTOS DIRETOS x CUSTOS FIXOS'!$T$6:$T$15, ROW(3:3)),'CUSTOS DIRETOS x CUSTOS FIXOS'!$T$6:$T$15, 0)) -> Frigobar de Inox | AL29: =AJ29 -> 0.30777778
AI30: 4 | AJ30: =LARGE('CUSTOS DIRETOS x CUSTOS FIXOS'!$T$6:$T$15,4) -> 0.27 | AK30: =INDEX('CUSTOS DIRETOS x CUSTOS FIXOS'!$S$6:$S$15, MATCH(LARGE('CUSTOS DIRETOS x CUSTOS FIXOS'!$T$6:$T$15, ROW(4:4)),'CUSTOS DIRETOS x CUSTOS FIXOS'!$T$6:$T$15, 0)) -> TV LED 100 | AL30: =AJ30 -> 0.27
AI31: 5 | AJ31: =LARGE('CUSTOS DIRETOS x CUSTOS FIXOS'!$T$6:$T$15,5) -> 0.17 | AK31: =INDEX('CUSTOS DIRETOS x CUSTOS FIXOS'!$S$6:$S$15, MATCH(LARGE('CUSTOS DIRETOS x CUSTOS FIXOS'!$T$6:$T$15, ROW(5:5)),'CUSTOS DIRETOS x CUSTOS FIXOS'!$T$6:$T$15, 0)) -> Cama King Size de Madeira | AL31: =AJ31 -> 0.17
AI32: 6 | AJ32: =LARGE('CUSTOS DIRETOS x CUSTOS FIXOS'!$T$6:$T$15,6) -> 0.12714286 | AK32: =INDEX('CUSTOS DIRETOS x CUSTOS FIXOS'!$S$6:$S$15, MATCH(LARGE('CUSTOS DIRETOS x CUSTOS FIXOS'!$T$6:$T$15, ROW(6:6)),'CUSTOS DIRETOS x CUSTOS FIXOS'!$T$6:$T$15, 0)) -> Sofá de Couro Italiano | AL32: =AJ32 -> 0.12714286
AI33: 7 | AJ33: =LARGE('CUSTOS DIRETOS x CUSTOS FIXOS'!$T$6:$T$15,7) -> 0.12294118 | AK33: =INDEX('CUSTOS DIRETOS x CUSTOS FIXOS'!$S$6:$S$15, MATCH(LARGE('CUSTOS DIRETOS x CUSTOS FIXOS'!$T$6:$T$15, ROW(7:7)),'CUSTOS DIRETOS x CUSTOS FIXOS'!$T$6:$T$15, 0)) -> Luminária de Cristal (1,5m) | AL33: =AJ33 -> 0.12294118
AI34: 8 | AJ34: =LARGE('CUSTOS DIRETOS x CUSTOS FIXOS'!$T$6:$T$15,8) -> 0.064166667 | AK34: =INDEX('CUSTOS DIRETOS x CUSTOS FIXOS'!$S$6:$S$15, MATCH(LARGE('CUSTOS DIRETOS x CUSTOS FIXOS'!$T$6:$T$15, ROW(8:8)),'CUSTOS DIRETOS x CUSTOS FIXOS'!$T$6:$T$15, 0)) -> Ventilador de Design Moderno | AL34: =AJ34 -> 0.064166667
AI35: 9 | AJ35: =LARGE('CUSTOS DIRETOS x CUSTOS FIXOS'!$T$6:$T$15,9) -> 0.011666667 | AK35: =INDEX('CUSTOS DIRETOS x CUSTOS FIXOS'!$S$6:$S$15, MATCH(LARGE('CUSTOS DIRETOS x CUSTOS FIXOS'!$T$6:$T$15, ROW(9:9)),'CUSTOS DIRETOS x CUSTOS FIXOS'!$T$6:$T$15, 0)) -> Máquina de Café Expresso | AL35: =AJ35 -> 0.011666667
AI36: 10 | AJ36: =LARGE('CUSTOS DIRETOS x CUSTOS FIXOS'!$T$6:$T$15,10) -> -0.84111111 | AK36: =INDEX('CUSTOS DIRETOS x CUSTOS FIXOS'!$S$6:$S$15, MATCH(LARGE('CUSTOS DIRETOS x CUSTOS FIXOS'!$T$6:$T$15, ROW(10:10)),'CUSTOS DIRETOS x CUSTOS FIXOS'!$T$6:$T$15, 0)) -> Conjunto de Talheres de Prata | AL36: =AJ36 -> -0.84111111
AI39: Custos Fixos
AI40: Ranking | AJ40: Valor | AK40: Custos
AI41: 1 | AJ41: =LARGE('CUSTOS DIRETOS x CUSTOS FIXOS'!$C$19:$C$28,AI41) -> 12000 | AK41: =INDEX('CUSTOS DIRETOS x CUSTOS FIXOS'!$B$19:$B$28,MATCH(LARGE('CUSTOS DIRETOS x CUSTOS FIXOS'!$C$19:$C$28,ROW(1:1)),'CUSTOS DIRETOS x CUSTOS FIXOS'!$C$19:$C$28,0)) -> Software e Licenças de Sistemas | AL41: =AJ41 -> 12000
AI42: 2 | AJ42: =LARGE('CUSTOS DIRETOS x CUSTOS FIXOS'!$C$19:$C$28,AI42) -> 10000 | AK42: =INDEX('CUSTOS DIRETOS x CUSTOS FIXOS'!$B$19:$B$28,MATCH(LARGE('CUSTOS DIRETOS x CUSTOS FIXOS'!$C$19:$C$28,ROW(2:2)),'CUSTOS DIRETOS x CUSTOS FIXOS'!$C$19:$C$28,0)) -> Marketing e Publicidade de Longo Prazo | AL42: =AJ42 -> 10000
AI43: 3 | AJ43: =LARGE('CUSTOS DIRETOS x CUSTOS FIXOS'!$C$19:$C$28,AI43) -> 6500 | AK43: =INDEX('CUSTOS DIRETOS x CUSTOS FIXOS'!$B$19:$B$28,MATCH(LARGE('CUSTOS DIRETOS x CUSTOS FIXOS'!$C$19:$C$28,ROW(3:3)),'CUSTOS DIRETOS x CUSTOS FIXOS'!$C$19:$C$28,0)) -> Aluguel de Móveis | AL43: =AJ43 -> 6500
AI44: 4 | AJ44: =LARGE('CUSTOS DIRETOS x CUSTOS FIXOS'!$C$19:$C$28,AI44) -> 2300 | AK44: =INDEX('CUSTOS DIRETOS x CUSTOS FIXOS'!$B$19:$B$28,MATCH(LARGE('CUSTOS DIRETOS x CUSTOS FIXOS'!$C$19:$C$28,ROW(4:4)),'CUSTOS DIRETOS x CUSTOS FIXOS'!$C$19:$C$28,0)) -> Água e Saneamento | AL44: =AJ44 -> 2300
AI45: 5 | AJ45: =LARGE('CUSTOS DIRETOS x CUSTOS FIXOS'!$C$19:$C$28,AI45) -> 2000 | AK45: =INDEX('CUSTOS DIRETOS x CUSTOS FIXOS'!$B$19:$B$28,MATCH(LARGE('CUSTOS DIRETOS x CUSTOS FIXOS'!$C$19:$C$28,ROW(5:5)),'CUSTOS DIRETOS x CUSTOS FIXOS'!$C$19:$C$28,0)) -> Licenças e Taxas Governamentais | AL45: =AJ45 -> 2000
AI46: 6 | AJ46: =LARGE('CUSTOS DIRETOS x CUSTOS FIXOS'!$C$19:$C$28,AI46) -> 1900 | AK46: =INDEX('CUSTOS DIRETOS x CUSTOS FIXOS'!$B$19:$B$28,MATCH(LARGE('CUSTOS DIRETOS x CUSTOS FIXOS'!$C$19:$C$28,ROW(6:6)),'CUSTOS DIRETOS x CUSTOS FIXOS'!$C$19:$C$28,0)) -> Manutenção de Equipamentos | AL46: =AJ46 -> 1900
AI47: 7 | AJ47: =LARGE('CUSTOS DIRETOS x CUSTOS FIXOS'!$C$19:$C$28,AI47) -> 1350 | AK47: =INDEX('CUSTOS DIRETOS x CUSTOS FIXOS'!$B$19:$B$28,MATCH(LARGE('CUSTOS DIRETOS x CUSTOS FIXOS'!$C$19:$C$28,ROW(7:7)),'CUSTOS DIRETOS x CUSTOS FIXOS'!$C$19:$C$28,0)) -> Seguros | AL47: =AJ47 -> 1350
...
