Workbook
Name Tabela10: #REF!

Sheet Tabela de Natureza Jurídica 
A1: Código | B1: Natureza Jurídica | C1: Categoria | D1: Integrantes do Quadro de Sócios e Administradores (QSA)
A2: 101-5 | B2: Órgão Público do Poder Executivo Federal | C2: Administração pública | D2: Administrador
A3: 102-3 | B3: Órgão Público do Poder Executivo Estadual ou do Distrito Federal | C3: Administração pública | D3: Administrador
A4: 103-1 | B4: Órgão Público do Poder Executivo Municipal | C4: Administração pública | D4: Administrador
A5: 104-0 | B5: Órgão Público do Poder Legislativo Federal | C5: Administração pública | D5: Administrador
A6: 105-8 | B6: Órgão Público do Poder Legislativo Estadual ou do Distrito Federal | C6: Administração pública | D6: Administrador
A7: 106-6 | B7: Órgão Público do Poder Legislativo Municipal | C7: Administração pública | D7: Administrador
A8: 107-4 | B8: Órgão Público do Poder Judiciário Federal | C8: Administração pública | D8: Administrador
A9: 108-2 | B9: Órgão Público do Poder Judiciário Estadual | C9: Administração pública | D9: Administrador
A10: 110-4 | B10: Autarquia Federal | C10: Administração pública | D10: Administrador ou Presidente
A11: 111-2 | B11: Autarquia Estadual ou do Distrito Federal | C11: Administração pública | D11: Administrador ou Presidente
A12: 112-0 | B12: Autarquia Municipal | C12: Administração pública | D12: Administrador ou Presidente
... A83: 503-7 | B83: Outras Instituições Extraterritoriais | C83: Organizações internacionais e outras instituições extraterritorial | D83: Representante da Instituição Extraterritorial

Sheet CNAE_Cód.Atividade Econômica
A1: CNAE | B1: Descrição | C1: Atividade Econômica
A2: 161-0/03 | B2: Serviço de preparação de terreno, cultivo e colheita | C2: =CÓDIGO_CNAE[[#This Row],[CNAE]] & " - " & CÓDIGO_CNAE[[#This Row],[Descrição]] -> 161-0/03 - Serviço de preparação de terreno, cultivo e colheita
A3: 162-8/03 | B3: Serviço de manejo de animais | C3: =CÓDIGO_CNAE[[#This Row],[CNAE]] & " - " & CÓDIGO_CNAE[[#This Row],[Descrição]] -> 162-8/03 - Serviço de manejo de animais
A4: 322-1/07 | B4: Atividades de apoio à aqüicultura em água doce | C4: =CÓDIGO_CNAE[[#This Row],[CNAE]] & " - " & CÓDIGO_CNAE[[#This Row],[Descrição]] -> 322-1/07 - Atividades de apoio à aqüicultura em água doce
A5: 1099-6/04 | B5: Fabricação de gelo comum | C5: =CÓDIGO_CNAE[[#This Row],[CNAE]] & " - " & CÓDIGO_CNAE[[#This Row],[Descrição]] -> 1099-6/04 - Fabricação de gelo comum
A6: 3250-7/06 | B6: Serviços de prótese dentária | C6: =CÓDIGO_CNAE[[#This Row],[CNAE]] & " - " & CÓDIGO_CNAE[[#This Row],[Descrição]] -> 3250-7/06 - Serviços de prótese dentária
A7: 3250-7/09 | B7: Serviço de laboratório óptico | C7: =CÓDIGO_CNAE[[#This Row],[CNAE]] & " - " & CÓDIGO_CNAE[[#This Row],[Descrição]] -> 3250-7/09 - Serviço de laboratório óptico
A8: 3312-1/02 | B8: Manutenção e reparação de aparelhos e instrumentos de medida, teste e controle | C8: =CÓDIGO_CNAE[[#This Row],[CNAE]] & " - " & CÓDIGO_CNAE[[#This Row],[Descrição]] -> 3312-1/02 - Manutenção e reparação de aparelhos e instrumentos de medida, teste e controle
A9: 3312-1/03 | B9: Manutenção e reparação de aparelhos eletromédicos e eletroterapêuticos e equipamentos de irradiação | C9: =CÓDIGO_CNAE[[#This Row],[CNAE]] & " - " & CÓDIGO_CNAE[[#This Row],[Descrição]] -> 3312-1/03 - Manutenção e reparação de aparelhos eletromédicos e eletroterapêuticos e equipamentos de irradiação
A10: 3312-1/04 | B10: Manutenção e reparação de equipamentos e instrumentos ópticos | C10: =CÓDIGO_CNAE[[#This Row],[CNAE]] & " - " & CÓDIGO_CNAE[[#This Row],[Descrição]] -> 3312-1/04 - Manutenção e reparação de equipamentos e instrumentos ópticos
A11: 3313-9/01 | B11: Manutenção e reparação de geradores, transformadores e motores elétricos | C11: =CÓDIGO_CNAE[[#This Row],[CNAE]] & " - " & CÓDIGO_CNAE[[#This Row],[Descrição]] -> 3313-9/01 - Manutenção e reparação de geradores, transformadores e motores elétricos
A12: 3313-9/02 | B12: Manutenção e reparação de baterias e acumuladores elétricos, exceto para veículos | C12: =CÓDIGO_CNAE[[#This Row],[CNAE]] & " - " & CÓDIGO_CNAE[[#This Row],[Descrição]] -> 3313-9/02 - Manutenção e reparação de baterias e acumuladores elétricos, exceto para veículos
A13: 3313-9/99 | B13: Manutenção e reparação de máquinas, aparelhos e materiais elétricos não especificados anteriormente | C13: =CÓDIGO_CNAE[[#This Row],[CNAE]] & " - " & CÓDIGO_CNAE[[#This Row],[Descrição]] -> 3313-9/99 - Manutenção e reparação de máquinas, aparelhos e materiais elétricos não especificados anteriormente
... A392: 9609-2/99 | B392: Outras atividades de serviços pessoais não especificadas anteriormente | C392: =CÓDIGO_CNAE[[#This Row],[CNAE]] & " - " & CÓDIGO_CNAE[[#This Row],[Descrição]] -> 9609-2/99 - Outras atividades de serviços pessoais não especificadas anteriormente

Sheet TAB.AUXILIAR
B5: VENDEDORES | C5: Percentual de Consultas por Solicitante – Setor de Vendas | F5: Pontuação para Empresas (CNPJ) e Pessoa Física (PF)
B6: Maria | C6: =COUNTIF('CONTROLE DIÁRIO DE CONSULTAS'!$I$10:$I$1048576,TAB.AUXILIAR!B5:B6) -> 1 | F6: MEI (Microempreendedor Individual): | G6: Pontuação 70-80, pois normalmente são negócios pequenos com menor risco, mas dependem da saúde financeira do empreendedor.
B7: José | C7: =COUNTIF('CONTROLE DIÁRIO DE CONSULTAS'!$I$10:$I$1048576,TAB.AUXILIAR!B6:B7) -> 5 | F7: ME (Microempresa): | G7: Pontuação 80-90, um pouco mais estruturada e com maior estabilidade financeira.
B8: João | C8: =COUNTIF('CONTROLE DIÁRIO DE CONSULTAS'!$I$10:$I$1048576,TAB.AUXILIAR!B7:B8) -> 3 | F8: EPP (Empresa de Pequeno Porte): | G8: Pontuação 90-95, empresas maiores têm mais estabilidade, porém ainda apresentam algum risco.
B9: Carla | C9: =COUNTIF('CONTROLE DIÁRIO DE CONSULTAS'!$I$10:$I$1048576,TAB.AUXILIAR!B8:B9) -> 14 | F9: LTDA (Sociedade Limitada): | G9: Pontuação 95-100, empresas com boa estrutura e capacidade de gestão financeira.
B10: Larissa | C10: =COUNTIF('CONTROLE DIÁRIO DE CONSULTAS'!$I$10:$I$1048576,TAB.AUXILIAR!B9:B10) -> 3 | F10: S/A (Sociedade Anônima): | G10: Pontuação 100, empresas grandes e com boa reputação no mercado.
B12: SEGMENTO DA INCLUSÃO | F12: Faixa de Pontuação e Classificação de Risco (serasa)
B13: LOJA | F13: Pontuação (0 a 1000) | G13: Classificação de Risco | H13: Descrição
B14: TELEFONIA | F14: 901 - 1000 | G14: Baixo | H14: Risco muito baixo de inadimplência.
B15: OUTROS | F15: 701 - 900 | G15: Médio-Baixo | H15: Risco moderado, mas com boa chance de pagamento.
F16: 501 - 700 | G16: Médio | H16: Risco médio, possibilidade de inadimplência.
B17: STATUS DE APROVAÇÃO | F17: 301 - 500 | G17: Médio-Alto | H17: Risco elevado de inadimplência.
B18: Aprovado | F18: 0 - 300 | G18: Alto | H18: Risco muito alto, grande chance de inadimplência.
B19: Reprovado
B20: Em Análise | F20: Para Pessoa Física (PF)
F21: Pontuação de Crédito no Serasa
B22: SETORES | F22: 300 → Risco Alto (alta chance de inadimplência)
B23: Departamento de Crédito/Análise de Crédito | F23: 301 a 500 → Risco Médio (risco moderado de inadimplência)
B24: Departamento de Cobrança | F24: 501 a 700 → Bom (risco baixo, mas ainda pode melhorar)
B25: Financeiro (Contas a Receber) | F25: 701 a 1000 → Muito Bom (ótima reputação financeira, alta chance de crédito aprovado)
B26: Jurídico
B27: Vendas
B28: Direção

Sheet CONTROLE DIÁRIO DE CONSULTAS
A1: CONTROLE DIÁRIO DE CONSULTAS
D5: DATA ATUAL | N5: Aprovado | O5: =COUNTIF(A:K,N5) -> 20
N6: Reprovado | O6: =COUNTIF(A:K,N6) -> 1
D7: =TODAY() -> 45738 | N7: Em Análise | O7: =COUNTIF(A:K,N7) -> 5
D9: DATA DE CONSULTA | E9: EMPRESA / CLIENTE | F9: CNPJ / CPF | G9: CLASSIFICAÇÃO | H9: DESCRIÇÃO DA ATIVIDADE ECONÔMICA (SETOR) | I9: SOLICITAÇÃO | J9: SETOR SOLICITANTE | K9: Status de Aprovação | M9: Mês | N9: Setor | O9: Setor | Q9: Setor | R9: Quantidade | U9: auxiliar01 | V9: auxiliar02 | Y9: RANKING | AB9: AUX01 | AC9: auxiliar02
D10: 45293 | E10: EMPRESA A | F10: 00.111.222/0001-00 | G10: EPP (Empresa de Pequeno Porte) | H10: 4783-1/02 - Comércio varejista de artigos de relojoaria | I10: Maria | J10: Vendas | K10: Reprovado | M10: =IF(ISBLANK(D10), "", IFERROR(PROPER(TEXT(D10,"mmmm")),"")) -> Janeiro | N10: =H10 -> 4783-1/02 - Comércio varejista de artigos de relojoaria | O10: =IFERROR(RIGHT(N10,LEN(N10)-SEARCH("- ",N10)-1),"") -> Comércio varejista de artigos de relojoaria | Q10: ='CNAE_Cód.Atividade Econômica'!B152 -> Comércio varejista de plantas e flores naturais | R10: =COUNTIF($O:$O,Q10) -> 8 | S10: =Q10 -> Comércio varejista de plantas e flores naturais | U10: =COUNTIF(R$10:R10,R10) -> 1 | V10: =R10&U10 -> 81 | W10: =INDEX($S$10:$S$401, MATCH(V10,$V$10:$V$1048576, 0)) -> Comércio varejista de plantas e flores naturais | Y10: 1 | Z10: =LARGE($R$10:$R$1048576,Y10) -> 8 | AA10: =INDEX(S$10:S$1000, MATCH(R10, R$10:R$1000, 0)) -> Comércio varejista de plantas e flores naturais | AB10: =COUNTIF(R$10:R10,R10) -> 1 | AC10: =R10&U10 -> 81 | AD10: =INDEX($S$10:$S$1048576, MATCH(AC10, $V$10:$V$1048576, 0)) -> Comércio varejista de plantas e flores naturais | AE10: =Z10 -> 8
D11: 45293 | E11: EMPRESA B | F11: 00.111.222/0001-01 | G11: ME (Microempresa) | H11: 4783-1/02 - Comércio varejista de artigos de relojoaria | I11: José | J11: Vendas | K11: Aprovado | M11: =IF(ISBLANK(D11), "", IFERROR(PROPER(TEXT(D11,"mmmm")),"")) -> Janeiro | N11: =H11 -> 4783-1/02 - Comércio varejista de artigos de relojoaria | O11: =IFERROR(RIGHT(N11,LEN(N11)-SEARCH("- ",N11)-1),"") -> Comércio varejista de artigos de relojoaria | Q11: ='CNAE_Cód.Atividade Econômica'!B149 -> Comércio varejista de antigüidades | R11: =COUNTIF($O:$O,Q11) -> 7 | S11: =Q11 -> Comércio varejista de antigüidades | U11: =COUNTIF(R$10:R11,R11) -> 1 | V11: =R11&U11 -> 71 | W11: =INDEX($S$10:$S$401, MATCH(V11,$V$10:$V$1048576, 0)) -> Comércio varejista de antigüidades | Y11: 2 | Z11: =LARGE($R$10:$R$1048576,Y11) -> 7 | AA11: =INDEX(S$10:S$1000, MATCH(R11, R$10:R$1000, 0)) -> Comércio varejista de antigüidades | AB11: =COUNTIF(R$10:R11,R11) -> 1 | AC11: =R11&U11 -> 71 | AD11: =INDEX($S$10:$S$1048576, MATCH(AC11, $V$10:$V$1048576, 0)) -> Comércio varejista de antigüidades | AE11: =Z11 -> 7
D12: 45293 | E12: EMPRESA C | F12: 00.111.222/0001-02 | G12: S/A (Sociedade Anônima) | H12: 4789-0/02 - Comércio varejista de plantas e flores naturais | I12: José | J12: Vendas | K12: Em Análise | M12: =IF(ISBLANK(D12), "", IFERROR(PROPER(TEXT(D12,"mmmm")),"")) -> Janeiro | N12: =H12 -> 4789-0/02 - Comércio varejista de plantas e flores naturais | O12: =IFERROR(RIGHT(N12,LEN(N12)-SEARCH("- ",N12)-1),"") -> Comércio varejista de plantas e flores naturais | Q12: ='CNAE_Cód.Atividade Econômica'!B148 -> Comércio varejista de artigos de relojoaria | R12: =COUNTIF($O:$O,Q12) -> 4 | S12: =Q12 -> Comércio varejista de artigos de relojoaria | U12: =COUNTIF(R$10:R12,R12) -> 1 | V12: =R12&U12 -> 41 | W12: =INDEX($S$10:$S$401, MATCH(V12,$V$10:$V$1048576, 0)) -> Comércio varejista de artigos de relojoaria | Y12: 3 | Z12: =LARGE($R$10:$R$1048576,Y12) -> 4 | AA12: =INDEX(S$10:S$1000, MATCH(R12, R$10:R$1000, 0)) -> Comércio varejista de artigos de relojoaria | AB12: =COUNTIF(R$10:R12,R12) -> 1 | AC12: =R12&U12 -> 41 | AD12: =INDEX($S$10:$S$1048576, MATCH(AC12, $V$10:$V$1048576, 0)) -> Comércio varejista de artigos de relojoaria | AE12: =Z12 -> 4
D13: 45294 | E13: EMPRESA D | F13: 00.111.222/0001-03 | G13: S/A (Sociedade Anônima) | H13: 4789-0/02 - Comércio varejista de plantas e flores naturais | I13: José | J13: Vendas | K13: Aprovado | M13: =IF(ISBLANK(D13), "", IFERROR(PROPER(TEXT(D13,"mmmm")),"")) -> Janeiro | N13: =H13 -> 4789-0/02 - Comércio varejista de plantas e flores naturais | O13: =IFERROR(RIGHT(N13,LEN(N13)-SEARCH("- ",N13)-1),"") -> Comércio varejista de plantas e flores naturais | Q13: ='CNAE_Cód.Atividade Econômica'!B68 -> Serviços de capotaria | R13: =COUNTIF($O:$O,Q13) -> 2 | S13: =Q13 -> Serviços de capotaria | U13: =COUNTIF(R$10:R13,R13) -> 1 | V13: =R13&U13 -> 21 | W13: =INDEX($S$10:$S$401, MATCH(V13,$V$10:$V$1048576, 0)) -> Serviços de capotaria | Y13: 4 | Z13: =LARGE($R$10:$R$1048576,Y13) -> 2 | AA13: =INDEX(S$10:S$1000, MATCH(R13, R$10:R$1000, 0)) -> Serviços de capotaria | AB13: =COUNTIF(R$10:R13,R13) -> 1 | AC13: =R13&U13 -> 21 | AD13: =INDEX($S$10:$S$1048576, MATCH(AC13, $V$10:$V$1048576, 0)) -> Serviços de capotaria | AE13: =Z13 -> 2
D14: 45323 | E14: EMPRESA E | F14: 00.111.222/0001-04 | G14: MEI (Microempreendedor Individual) | H14: 4789-0/02 - Comércio varejista de plantas e flores naturais | I14: José | J14: Vendas | K14: Aprovado | M14: =IF(ISBLANK(D14), "", IFERROR(PROPER(TEXT(D14,"mmmm")),"")) -> Fevereiro | N14: =H14 -> 4789-0/02 - Comércio varejista de plantas e flores naturais | O14: =IFERROR(RIGHT(N14,LEN(N14)-SEARCH("- ",N14)-1),"") -> Comércio varejista de plantas e flores naturais | Q14: ='CNAE_Cód.Atividade Econômica'!B167 -> Campings | R14: =COUNTIF($O:$O,Q14) -> 2 | S14: =Q14 -> Campings | U14: =COUNTIF(R$10:R14,R14) -> 2 | V14: =R14&U14 -> 22 | W14: =INDEX($S$10:$S$401, MATCH(V14,$V$10:$V$1048576, 0)) -> Campings | Y14: 5 | Z14: =LARGE($R$10:$R$1048576,Y14) -> 2 | AA14: =INDEX(S$10:S$1000, MATCH(R14, R$10:R$1000, 0)) -> Serviços de capotaria | AB14: =COUNTIF(R$10:R14,R14) -> 2 | AC14: =R14&U14 -> 22 | AD14: =INDEX($S$10:$S$1048576, MATCH(AC14, $V$10:$V$1048576, 0)) -> Campings | AE14: =Z14 -> 2
D15: 45323 | E15: EMPRESA F | F15: 00.111.222/0001-05 | G15: MEI (Microempreendedor Individual) | H15: 4789-0/02 - Comércio varejista de plantas e flores naturais | I15: José | J15: Vendas | K15: Aprovado | M15: =IF(ISBLANK(D15), "", IFERROR(PROPER(TEXT(D15,"mmmm")),"")) -> Fevereiro | N15: =H15 -> 4789-0/02 - Comércio varejista de plantas e flores naturais | O15: =IFERROR(RIGHT(N15,LEN(N15)-SEARCH("- ",N15)-1),"") -> Comércio varejista de plantas e flores naturais | Q15: ='CNAE_Cód.Atividade Econômica'!B160 -> Guarda-móveis | R15: =COUNTIF($O:$O,Q15) -> 0 | S15: =Q15 -> Guarda-móveis | U15: =COUNTIF(R$10:R15,R15) -> 1 | V15: =R15&U15 -> 01 | W15: =INDEX($S$10:$S$401, MATCH(V15,$V$10:$V$1048576, 0)) -> Guarda-móveis | Y15: 6 | Z15: =LARGE($R$10:$R$1048576,Y15) -> 1 | AA15: =INDEX(S$10:S$1000, MATCH(R15, R$10:R$1000, 0)) -> Guarda-móveis | AB15: =COUNTIF(R$10:R15,R15) -> 1 | AC15: =R15&U15 -> 01 | AD15: =INDEX($S$10:$S$1048576, MATCH(AC15, $V$10:$V$1048576, 0)) -> Guarda-móveis | AE15: =Z15 -> 1
D16: 45323 | E16: EMPRESA G | F16: 00.111.222/0001-06 | G16: MEI (Microempreendedor Individual) | H16: 4789-0/02 - Comércio varejista de plantas e flores naturais | I16: João | J16: Vendas | K16: Aprovado | M16: =IF(ISBLANK(D16), "", IFERROR(PROPER(TEXT(D16,"mmmm")),"")) -> Fevereiro | N16: =H16 -> 4789-0/02 - Comércio varejista de plantas e flores naturais | O16: =IFERROR(RIGHT(N16,LEN(N16)-SEARCH("- ",N16)-1),"") -> Comércio varejista de plantas e flores naturais | Q16: ='CNAE_Cód.Atividade Econômica'!B150 -> Comércio varejista de outros artigos usados | R16: =COUNTIF($O:$O,Q16) -> 1 | S16: =Q16 -> Comércio varejista de outros artigos usados | U16: =COUNTIF(R$10:R16,R16) -> 1 | V16: =R16&U16 -> 11 | W16: =INDEX($S$10:$S$401, MATCH(V16,$V$10:$V$1048576, 0)) -> Comércio varejista de outros artigos usados | Y16: 7 | Z16: =LARGE($R$10:$R$1048576,Y16) -> 1 | AA16: =INDEX(S$10:S$1000, MATCH(R16, R$10:R$1000, 0)) -> Comércio varejista de outros artigos usados | AB16: =COUNTIF(R$10:R16,R16) -> 1 | AC16: =R16&U16 -> 11 | AD16: =INDEX($S$10:$S$1048576, MATCH(AC16, $V$10:$V$1048576, 0)) -> Comércio varejista de outros artigos usados | AE16: =Z16 -> 1
D17: 45323 | E17: EMPRESA H | F17: 00.111.222/0001-07 | G17: MEI (Microempreendedor Individual) | H17: 4789-0/02 - Comércio varejista de plantas e flores naturais | I17: João | J17: Vendas | K17: Aprovado | M17: =IF(ISBLANK(D17), "", IFERROR(PROPER(TEXT(D17,"mmmm")),"")) -> Fevereiro | N17: =H17 -> 4789-0/02 - Comércio varejista de plantas e flores naturais | O17: =IFERROR(RIGHT(N17,LEN(N17)-SEARCH("- ",N17)-1),"") -> Comércio varejista de plantas e flores naturais | Q17: ='CNAE_Cód.Atividade Econômica'!B151 -> Comércio varejista de suvenires, bijuterias e artesanatos | R17: =COUNTIF($O:$O,Q17) -> 1 | S17: =Q17 -> Comércio varejista de suvenires, bijuterias e artesanatos | U17: =COUNTIF(R$10:R17,R17) -> 2 | V17: =R17&U17 -> 12 | W17: =INDEX($S$10:$S$401, MATCH(V17,$V$10:$V$1048576, 0)) -> Comércio varejista de suvenires, bijuterias e artesanatos | Y17: 8 | Z17: =LARGE($R$10:$R$1048576,Y17) -> 1 | AA17: =INDEX(S$10:S$1000, MATCH(R17, R$10:R$1000, 0)) -> Comércio varejista de outros artigos usados | AB17: =COUNTIF(R$10:R17,R17) -> 2 | AC17: =R17&U17 -> 12 | AD17: =INDEX($S$10:$S$1048576, MATCH(AC17, $V$10:$V$1048576, 0)) -> Comércio varejista de suvenires, bijuterias e artesanatos | AE17: =Z17 -> 1
D18: 45323 | E18: EMPRESA I | F18: 00.111.222/0001-08 | G18: MEI (Microempreendedor Individual) | H18: 4789-0/02 - Comércio varejista de plantas e flores naturais | I18: João | J18: Vendas | K18: Aprovado | M18: =IF(ISBLANK(D18), "", IFERROR(PROPER(TEXT(D18,"mmmm")),"")) -> Fevereiro | N18: =H18 -> 4789-0/02 - Comércio varejista de plantas e flores naturais | O18: =IFERROR(RIGHT(N18,LEN(N18)-SEARCH("- ",N18)-1),"") -> Comércio varejista de plantas e flores naturais | Q18: ='CNAE_Cód.Atividade Econômica'!B153 -> Comércio varejista de objetos de arte | R18: =COUNTIF($O:$O,Q18) -> 1 | S18: =Q18 -> Comércio varejista de objetos de arte | U18: =COUNTIF(R$10:R18,R18) -> 3 | V18: =R18&U18 -> 13 | W18: =INDEX($S$10:$S$401, MATCH(V18,$V$10:$V$1048576, 0)) -> Comércio varejista de objetos de arte | Y18: 9 | Z18: =LARGE($R$10:$R$1048576,Y18) -> 0 | AA18: =INDEX(S$10:S$1000, MATCH(R18, R$10:R$1000, 0)) -> Comércio varejista de outros artigos usados | AB18: =COUNTIF(R$10:R18,R18) -> 3 | AC18: =R18&U18 -> 13 | AD18: =INDEX($S$10:$S$1048576, MATCH(AC18, $V$10:$V$1048576, 0)) -> Comércio varejista de objetos de arte | AE18: =Z18 -> 0
D19: 45356 | E19: EMPRESA J | F19: 00.111.222/0001-09 | G19: EPP (Empresa de Pequeno Porte) | H19: 4785-7/99 - Comércio varejista de outros artigos usados | I19: Larissa | J19: Vendas | K19: Aprovado | M19: =IF(ISBLANK(D19), "", IFERROR(PROPER(TEXT(D19,"mmmm")),"")) -> Março | N19: =H19 -> 4785-7/99 - Comércio varejista de outros artigos usados | O19: =IFERROR(RIGHT(N19,LEN(N19)-SEARCH("- ",N19)-1),"") -> Comércio varejista de outros artigos usados | Q19: ='CNAE_Cód.Atividade Econômica'!B2 -> Serviço de preparação de terreno, cultivo e colheita | R19: =COUNTIF($O:$O,Q19) -> 0 | S19: =Q19 -> Serviço de preparação de terreno, cultivo e colheita | U19: =COUNTIF(R$10:R19,R19) -> 2 | V19: =R19&U19 -> 02 | W19: =INDEX($S$10:$S$401, MATCH(V19,$V$10:$V$1048576, 0)) -> Serviço de preparação de terreno, cultivo e colheita | Y19: 10 | Z19: =LARGE($R$10:$R$1048576,Y19) -> 0 | AA19: =INDEX(S$10:S$1000, MATCH(R19, R$10:R$1000, 0)) -> Guarda-móveis | AB19: =COUNTIF(R$10:R19,R19) -> 2 | AC19: =R19&U19 -> 02 | AD19: =INDEX($S$10:$S$1048576, MATCH(AC19, $V$10:$V$1048576, 0)) -> Serviço de preparação de terreno, cultivo e colheita | AE19: =Z19 -> 0
D20: 45356 | E20: EMPRESA K | F20: 00.111.222/0001-10 | G20: EPP (Empresa de Pequeno Porte) | H20: 5590-6/02 - Campings | I20: Larissa | J20: Vendas | K20: Aprovado | M20: =IF(ISBLANK(D20), "", IFERROR(PROPER(TEXT(D20,"mmmm")),"")) -> Março | N20: =H20 -> 5590-6/02 - Campings | O20: =IFERROR(RIGHT(N20,LEN(N20)-SEARCH("- ",N20)-1),"") -> Campings | Q20: ='CNAE_Cód.Atividade Econômica'!B386 -> Atividades de Estética e outros serviços de cuidados com a beleza | R20: =COUNTIF($O:$O,Q20) -> 0 | S20: =Q20 -> Atividades de Estética e outros serviços de cuidados com a beleza | U20: =COUNTIF(R$10:R20,R20) -> 3 | V20: =R20&U20 -> 03 | W20: =INDEX($S$10:$S$401, MATCH(V20,$V$10:$V$1048576, 0)) -> Atividades de Estética e outros serviços de cuidados com a beleza | Y20: 11 | Z20: =LARGE($R$10:$R$1048576,Y20) -> 0 | AA20: =INDEX(S$10:S$1000, MATCH(R20, R$10:R$1000, 0)) -> Guarda-móveis | AB20: =COUNTIF(R$10:R20,R20) -> 3 | AC20: =R20&U20 -> 03 | AD20: =INDEX($S$10:$S$1048576, MATCH(AC20, $V$10:$V$1048576, 0)) -> Atividades de Estética e outros serviços de cuidados com a beleza | AE20: =Z20 -> 0
D21: 45383 | E21: EMPRESA L | F21: 00.111.222/0001-11 | G21: EPP (Empresa de Pequeno Porte) | H21: 4789-0/01 - Comércio varejista de suvenires, bijuterias e artesanatos | I21: Larissa | J21: Vendas | K21: Aprovado | M21: =IF(ISBLANK(D21), "", IFERROR(PROPER(TEXT(D21,"mmmm")),"")) -> Abril | N21: =H21 -> 4789-0/01 - Comércio varejista de suvenires, bijuterias e artesanatos | O21: =IFERROR(RIGHT(N21,LEN(N21)-SEARCH("- ",N21)-1),"") -> Comércio varejista de suvenires, bijuterias e artesanatos | Q21: ='CNAE_Cód.Atividade Econômica'!B388 -> Atividades de sauna e banhos | R21: =COUNTIF($O:$O,Q21) -> 0 | S21: =Q21 -> Atividades de sauna e banhos | U21: =COUNTIF(R$10:R21,R21) -> 4 | V21: =R21&U21 -> 04 | W21: =INDEX($S$10:$S$401, MATCH(V21,$V$10:$V$1048576, 0)) -> Atividades de sauna e banhos | Y21: 12 | Z21: =LARGE($R$10:$R$1048576,Y21) -> 0 | AA21: =INDEX(S$10:S$1000, MATCH(R21, R$10:R$1000, 0)) -> Guarda-móveis | AB21: =COUNTIF(R$10:R21,R21) -> 4 | AC21: =R21&U21 -> 04 | AD21: =INDEX($S$10:$S$1048576, MATCH(AC21, $V$10:$V$1048576, 0)) -> Atividades de sauna e banhos | AE21: =Z21 -> 0
D22: 45383 | E22: EMPRESA M | F22: 00.111.222/0001-12 | G22: EPP (Empresa de Pequeno Porte) | H22: 4785-7/01 - Comércio varejista de antigüidades | I22: Carla | J22: Vendas | K22: Aprovado | M22: =IF(ISBLANK(D22), "", IFERROR(PROPER(TEXT(D22,"mmmm")),"")) -> Abril | N22: =H22 -> 4785-7/01 - Comércio varejista de antigüidades | O22: =IFERROR(RIGHT(N22,LEN(N22)-SEARCH("- ",N22)-1),"") -> Comércio varejista de antigüidades | Q22: ='CNAE_Cód.Atividade Econômica'!B7 -> Serviço de laboratório óptico | R22: =COUNTIF($O:$O,Q22) -> 0 | S22: =Q22 -> Serviço de laboratório óptico | U22: =COUNTIF(R$10:R22,R22) -> 5 | V22: =R22&U22 -> 05 | W22: =INDEX($S$10:$S$401, MATCH(V22,$V$10:$V$1048576, 0)) -> Serviço de laboratório óptico | Y22: 13 | Z22: =LARGE($R$10:$R$1048576,Y22) -> 0 | AA22: =INDEX(S$10:S$1000, MATCH(R22, R$10:R$1000, 0)) -> Guarda-móveis | AB22: =COUNTIF(R$10:R22,R22) -> 5 | AC22: =R22&U22 -> 05 | AD22: =INDEX($S$10:$S$1048576, MATCH(AC22, $V$10:$V$1048576, 0)) -> Serviço de laboratório óptico | AE22: =Z22 -> 0
D23: 45413 | E23: EMPRESA N | F23: 00.111.222/0001-13 | G23: LTDA (Sociedade Limitada) | H23: 4785-7/01 - Comércio varejista de antigüidades | I23: Carla | J23: Vendas | K23: Em Análise | M23: =IF(ISBLANK(D23), "", IFERROR(PROPER(TEXT(D23,"mmmm")),"")) -> Maio | N23: =IF(H23="","",H23) -> 4785-7/01 - Comércio varejista de antigüidades | O23: =IFERROR(RIGHT(N23,LEN(N23)-SEARCH("- ",N23)-1),"") -> Comércio varejista de antigüidades | Q23: ='CNAE_Cód.Atividade Econômica'!B389 -> Serviços de tatuagem e colocação de piercing | R23: =COUNTIF($O:$O,Q23) -> 0 | S23: =Q23 -> Serviços de tatuagem e colocação de piercing | U23: =COUNTIF(R$10:R23,R23) -> 6 | V23: =R23&U23 -> 06 | W23: =INDEX($S$10:$S$401, MATCH(V23,$V$10:$V$1048576, 0)) -> Serviços de tatuagem e colocação de piercing | Y23: 14 | Z23: =LARGE($R$10:$R$1048576,Y23) -> 0 | AA23: =INDEX(S$10:S$1000, MATCH(R23, R$10:R$1000, 0)) -> Guarda-móveis | AB23: =COUNTIF(R$10:R23,R23) -> 6 | AC23: =R23&U23 -> 06 | AD23: =INDEX($S$10:$S$1048576, MATCH(AC23, $V$10:$V$1048576, 0)) -> Serviços de tatuagem e colocação de piercing | AE23: =Z23 -> 0
D24: 45413 | E24: EMPRESA O | F24: 00.111.222/0001-14 | G24: LTDA (Sociedade Limitada) | H24: 4785-7/01 - Comércio varejista de antigüidades | I24: Carla | J24: Vendas | K24: Em Análise | M24: =IF(ISBLANK(D24), "", IFERROR(PROPER(TEXT(D24,"mmmm")),"")) -> Maio | N24: =IF(H24="","",H24) -> 4785-7/01 - Comércio varejista de antigüidades | O24: =IFERROR(RIGHT(N24,LEN(N24)-SEARCH("- ",N24)-1),"") -> Comércio varejista de antigüidades | Q24: ='CNAE_Cód.Atividade Econômica'!B158 -> Comércio varejista de armas e munições | R24: =COUNTIF($O:$O,Q24) -> 0 | S24: =Q24 -> Comércio varejista de armas e munições | U24: =COUNTIF(R$10:R24,R24) -> 7 | V24: =R24&U24 -> 07 | W24: =INDEX($S$10:$S$401, MATCH(V24,$V$10:$V$1048576, 0)) -> Comércio varejista de armas e munições | Y24: 15 | Z24: =LARGE($R$10:$R$1048576,Y24) -> 0 | AA24: =INDEX(S$10:S$1000, MATCH(R24, R$10:R$1000, 0)) -> Guarda-móveis | AB24: =COUNTIF(R$10:R24,R24) -> 7 | AC24: =R24&U24 -> 07 | AD24: =INDEX($S$10:$S$1048576, MATCH(AC24, $V$10:$V$1048576, 0)) -> Comércio varejista de armas e munições | AE24: =Z24 -> 0
D25: 45413 | E25: EMPRESA P | F25: 00.111.222/0001-15 | G25: LTDA (Sociedade Limitada) | H25: 4785-7/01 - Comércio varejista de antigüidades | I25: Carla | J25: Vendas | K25: Em Análise | M25: =IF(ISBLANK(D25), "", IFERROR(PROPER(TEXT(D25,"mmmm")),"")) -> Maio | N25: =IF(H25="","",H25) -> 4785-7/01 - Comércio varejista de antigüidades | O25: =IFERROR(RIGHT(N25,LEN(N25)-SEARCH("- ",N25)-1),"") -> Comércio varejista de antigüidades | Q25: ='CNAE_Cód.Atividade Econômica'!B3 -> Serviço de manejo de animais | R25: =COUNTIF($O:$O,Q25) -> 0 | S25: =Q25 -> Serviço de manejo de animais | U25: =COUNTIF(R$10:R25,R25) -> 8 | V25: =R25&U25 -> 08 | W25: =INDEX($S$10:$S$401, MATCH(V25,$V$10:$V$1048576, 0)) -> Serviço de manejo de animais | Y25: 16 | Z25: =LARGE($R$10:$R$1048576,Y25) -> 0 | AA25: =INDEX(S$10:S$1000, MATCH(R25, R$10:R$1000, 0)) -> Guarda-móveis | AB25: =COUNTIF(R$10:R25,R25) -> 8 | AC25: =R25&U25 -> 08 | AD25: =INDEX($S$10:$S$1048576, MATCH(AC25, $V$10:$V$1048576, 0)) -> Serviço de manejo de animais | AE25: =Z25 -> 0
D26: 45414 | E26: EMPRESA Q | F26: 00.111.222/0001-16 | G26: LTDA (Sociedade Limitada) | H26: 4785-7/01 - Comércio varejista de antigüidades | I26: Carla | J26: Vendas | K26: Em Análise | M26: =IF(ISBLANK(D26), "", IFERROR(PROPER(TEXT(D26,"mmmm")),"")) -> Maio | N26: =IF(H26="","",H26) -> 4785-7/01 - Comércio varejista de antigüidades | O26: =IFERROR(RIGHT(N26,LEN(N26)-SEARCH("- ",N26)-1),"") -> Comércio varejista de antigüidades | Q26: ='CNAE_Cód.Atividade Econômica'!B4 -> Atividades de apoio à aqüicultura em água doce | R26: =COUNTIF($O:$O,Q26) -> 0 | S26: =Q26 -> Atividades de apoio à aqüicultura em água doce | U26: =COUNTIF(R$10:R26,R26) -> 9 | V26: =R26&U26 -> 09 | W26: =INDEX($S$10:$S$401, MATCH(V26,$V$10:$V$1048576, 0)) -> Atividades de apoio à aqüicultura em água doce | Y26: 17 | Z26: =LARGE($R$10:$R$1048576,Y26) -> 0 | AA26: =INDEX(S$10:S$1000, MATCH(R26, R$10:R$1000, 0)) -> Guarda-móveis | AB26: =COUNTIF(R$10:R26,R26) -> 9 | AC26: =R26&U26 -> 09 | AD26: =INDEX($S$10:$S$1048576, MATCH(AC26, $V$10:$V$1048576, 0)) -> Atividades de apoio à aqüicultura em água doce | AE26: =Z26 -> 0
D27: 45446 | E27: EMPRESA R | F27: 00.111.222/0001-17 | G27: EPP (Empresa de Pequeno Porte) | H27: 4785-7/01 - Comércio varejista de antigüidades | I27: Carla | J27: Vendas | K27: Aprovado | M27: =IF(ISBLANK(D27), "", IFERROR(PROPER(TEXT(D27,"mmmm")),"")) -> Junho | N27: =IF(H27="","",H27) -> 4785-7/01 - Comércio varejista de antigüidades | O27: =IFERROR(RIGHT(N27,LEN(N27)-SEARCH("- ",N27)-1),"") -> Comércio varejista de antigüidades | Q27: ='CNAE_Cód.Atividade Econômica'!B5 -> Fabricação de gelo comum | R27: =COUNTIF($O:$O,Q27) -> 0 | S27: =Q27 -> Fabricação de gelo comum | U27: =COUNTIF(R$10:R27,R27) -> 10 | V27: =R27&U27 -> 010 | W27: =INDEX($S$10:$S$401, MATCH(V27,$V$10:$V$1048576, 0)) -> Fabricação de gelo comum | Y27: 18 | Z27: =LARGE($R$10:$R$1048576,Y27) -> 0 | AA27: =INDEX(S$10:S$1000, MATCH(R27, R$10:R$1000, 0)) -> Guarda-móveis | AB27: =COUNTIF(R$10:R27,R27) -> 10 | AC27: =R27&U27 -> 010 | AD27: =INDEX($S$10:$S$1048576, MATCH(AC27, $V$10:$V$1048576, 0)) -> Fabricação de gelo comum | AE27: =Z27 -> 0
D28: 45446 | E28: EMPRESA S | F28: 00.111.222/0001-18 | G28: EPP (Empresa de Pequeno Porte) | H28: 4785-7/01 - Comércio varejista de antigüidades | I28: Carla | J28: Vendas | K28: Aprovado | M28: =IF(ISBLANK(D28), "", IFERROR(PROPER(TEXT(D28,"mmmm")),"")) -> Junho | N28: =IF(H28="","",H28) -> 4785-7/01 - Comércio varejista de antigüidades | O28: =IFERROR(RIGHT(N28,LEN(N28)-SEARCH("- ",N28)-1),"") -> Comércio varejista de antigüidades | Q28: ='CNAE_Cód.Atividade Econômica'!B6 -> Serviços de prótese dentária | R28: =COUNTIF($O:$O,Q28) -> 0 | S28: =Q28 -> Serviços de prótese dentária | U28: =COUNTIF(R$10:R28,R28) -> 11 | V28: =R28&U28 -> 011 | W28: =INDEX($S$10:$S$401, MATCH(V28,$V$10:$V$1048576, 0)) -> Serviços de prótese dentária | Y28: 19 | Z28: =LARGE($R$10:$R$1048576,Y28) -> 0 | AA28: =INDEX(S$10:S$1000, MATCH(R28, R$10:R$1000, 0)) -> Guarda-móveis | AB28: =COUNTIF(R$10:R28,R28) -> 11 | AC28: =R28&U28 -> 011 | AD28: =INDEX($S$10:$S$1048576, MATCH(AC28, $V$10:$V$1048576, 0)) -> Serviços de prótese dentária | AE28: =Z28 -> 0
D29: 45478 | E29: EMPRESA T | F29: 00.111.222/0001-19 | G29: EPP (Empresa de Pequeno Porte) | H29: 4783-1/02 - Comércio varejista de artigos de relojoaria | I29: Carla | J29: Vendas | K29: Aprovado | M29: =IF(ISBLANK(D29), "", IFERROR(PROPER(TEXT(D29,"mmmm")),"")) -> Julho | N29: =IF(H29="","",H29) -> 4783-1/02 - Comércio varejista de artigos de relojoaria | O29: =IFERROR(RIGHT(N29,LEN(N29)-SEARCH("- ",N29)-1),"") -> Comércio varejista de artigos de relojoaria | Q29: ='CNAE_Cód.Atividade Econômica'!B8 -> Manutenção e reparação de aparelhos e instrumentos de medida, teste e controle | R29: =COUNTIF($O:$O,Q29) -> 0 | S29: =Q29 -> Manutenção e reparação de aparelhos e instrumentos de medida, teste e controle | U29: =COUNTIF(R$10:R29,R29) -> 12 | V29: =R29&U29 -> 012 | W29: =INDEX($S$10:$S$401, MATCH(V29,$V$10:$V$1048576, 0)) -> Manutenção e reparação de aparelhos e instrumentos de medida, teste e controle | Y29: 20 | Z29: =LARGE($R$10:$R$1048576,Y29) -> 0 | AA29: =INDEX(S$10:S$1000, MATCH(R29, R$10:R$1000, 0)) -> Guarda-móveis | AB29: =COUNTIF(R$10:R29,R29) -> 12 | AC29: =R29&U29 -> 012 | AD29: =INDEX($S$10:$S$1048576, MATCH(AC29, $V$10:$V$1048576, 0)) -> Manutenção e reparação de aparelhos e instrumentos de medida, teste e controle | AE29: =Z29 -> 0
D30: 45478 | E30: EMPRESA U | F30: 00.111.222/0001-20 | G30: EPP (Empresa de Pequeno Porte) | H30: 4783-1/02 - Comércio varejista de artigos de relojoaria | I30: Carla | J30: Vendas | K30: Aprovado | M30: =IF(ISBLANK(D30), "", IFERROR(PROPER(TEXT(D30,"mmmm")),"")) -> Julho | N30: =IF(H30="","",H30) -> 4783-1/02 - Comércio varejista de artigos de relojoaria | O30: =IFERROR(RIGHT(N30,LEN(N30)-SEARCH("- ",N30)-1),"") -> Comércio varejista de artigos de relojoaria | Q30: ='CNAE_Cód.Atividade Econômica'!B9 -> Manutenção e reparação de aparelhos eletromédicos e eletroterapêuticos e equipamentos de irradiação | R30: =COUNTIF($O:$O,Q30) -> 0 | S30: =Q30 -> Manutenção e reparação de aparelhos eletromédicos e eletroterapêuticos e equipamentos de irradiação | U30: =COUNTIF(R$10:R30,R30) -> 13 | V30: =R30&U30 -> 013 | W30: =INDEX($S$10:$S$401, MATCH(V30,$V$10:$V$1048576, 0)) -> Manutenção e reparação de aparelhos eletromédicos e eletroterapêuticos e equipamentos de irradiação | Y30: 21 | Z30: =LARGE($R$10:$R$1048576,Y30) -> 0 | AA30: =INDEX(S$10:S$1000, MATCH(R30, R$10:R$1000, 0)) -> Guarda-móveis | AB30: =COUNTIF(R$10:R30,R30) -> 13 | AC30: =R30&U30 -> 013 | AD30: =INDEX($S$10:$S$1048576, MATCH(AC30, $V$10:$V$1048576, 0)) -> Manutenção e reparação de aparelhos eletromédicos e eletroterapêuticos e equipamentos de irradiação | AE30: =Z30 -> 0
D31: 45511 | E31: EMPRESA V | F31: 00.111.222/0001-21 | G31: S/A (Sociedade Anônima)Sociedade Anônima | H31: 4789-0/03 - Comércio varejista de objetos de arte | I31: Carla | J31: Vendas | K31: Aprovado | M31: =IF(ISBLANK(D31), "", IFERROR(PROPER(TEXT(D31,"mmmm")),"")) -> Agosto | N31: =IF(H31="","",H31) -> 4789-0/03 - Comércio varejista de objetos de arte | O31: =IFERROR(RIGHT(N31,LEN(N31)-SEARCH("- ",N31)-1),"") -> Comércio varejista de objetos de arte | Q31: ='CNAE_Cód.Atividade Econômica'!B10 -> Manutenção e reparação de equipamentos e instrumentos ópticos | R31: =COUNTIF($O:$O,Q31) -> 0 | S31: =Q31 -> Manutenção e reparação de equipamentos e instrumentos ópticos | U31: =COUNTIF(R$10:R31,R31) -> 14 | V31: =R31&U31 -> 014 | W31: =INDEX($S$10:$S$401, MATCH(V31,$V$10:$V$1048576, 0)) -> Manutenção e reparação de equipamentos e instrumentos ópticos | Y31: 22 | Z31: =LARGE($R$10:$R$1048576,Y31) -> 0 | AA31: =INDEX(S$10:S$1000, MATCH(R31, R$10:R$1000, 0)) -> Guarda-móveis | AB31: =COUNTIF(R$10:R31,R31) -> 14 | AC31: =R31&U31 -> 014 | AD31: =INDEX($S$10:$S$1048576, MATCH(AC31, $V$10:$V$1048576, 0)) -> Manutenção e reparação de equipamentos e instrumentos ópticos | AE31: =Z31 -> 0
D32: 45511 | E32: EMPRESA W | F32: 00.111.222/0001-22 | G32: S/A (Sociedade Anônima)Sociedade Anônima | H32: 4789-0/02 - Comércio varejista de plantas e flores naturais | I32: Carla | J32: Vendas | K32: Aprovado | M32: =IF(ISBLANK(D32), "", IFERROR(PROPER(TEXT(D32,"mmmm")),"")) -> Agosto | N32: =IF(H32="","",H32) -> 4789-0/02 - Comércio varejista de plantas e flores naturais | O32: =IFERROR(RIGHT(N32,LEN(N32)-SEARCH("- ",N32)-1),"") -> Comércio varejista de plantas e flores naturais | Q32: ='CNAE_Cód.Atividade Econômica'!B11 -> Manutenção e reparação de geradores, transformadores e motores elétricos | R32: =COUNTIF($O:$O,Q32) -> 0 | S32: =Q32 -> Manutenção e reparação de geradores, transformadores e motores elétricos | U32: =COUNTIF(R$10:R32,R32) -> 15 | V32: =R32&U32 -> 015 | W32: =INDEX($S$10:$S$401, MATCH(V32,$V$10:$V$1048576, 0)) -> Manutenção e reparação de geradores, transformadores e motores elétricos | Y32: 23 | Z32: =LARGE($R$10:$R$1048576,Y32) -> 0 | AA32: =INDEX(S$10:S$1000, MATCH(R32, R$10:R$1000, 0)) -> Guarda-móveis | AB32: =COUNTIF(R$10:R32,R32) -> 15 | AC32: =R32&U32 -> 015 | AD32: =INDEX($S$10:$S$1048576, MATCH(AC32, $V$10:$V$1048576, 0)) -> Manutenção e reparação de geradores, transformadores e motores elétricos | AE32: =Z32 -> 0
D33: 45544 | E33: EMPRESA X | F33: 00.111.222/0001-23 | G33: S/A (Sociedade Anônima)Sociedade Anônima | H33: 5590-6/02 - Campings | I33: Carla | J33: Vendas | K33: Aprovado | M33: =IF(ISBLANK(D33), "", IFERROR(PROPER(TEXT(D33,"mmmm")),"")) -> Setembro | N33: =IF(H33="","",H33) -> 5590-6/02 - Campings | O33: =IFERROR(RIGHT(N33,LEN(N33)-SEARCH("- ",N33)-1),"") -> Campings | Q33: ='CNAE_Cód.Atividade Econômica'!B12 -> Manutenção e reparação de baterias e acumuladores elétricos, exceto para veículos | R33: =COUNTIF($O:$O,Q33) -> 0 | S33: =Q33 -> Manutenção e reparação de baterias e acumuladores elétricos, exceto para veículos | U33: =COUNTIF(R$10:R33,R33) -> 16 | V33: =R33&U33 -> 016 | W33: =INDEX($S$10:$S$401, MATCH(V33,$V$10:$V$1048576, 0)) -> Manutenção e reparação de baterias e acumuladores elétricos, exceto para veículos | Y33: 24 | Z33: =LARGE($R$10:$R$1048576,Y33) -> 0 | AA33: =INDEX(S$10:S$1000, MATCH(R33, R$10:R$1000, 0)) -> Guarda-móveis | AB33: =COUNTIF(R$10:R33,R33) -> 16 | AC33: =R33&U33 -> 016 | AD33: =INDEX($S$10:$S$1048576, MATCH(AC33, $V$10:$V$1048576, 0)) -> Manutenção e reparação de baterias e acumuladores elétricos, exceto para veículos | AE33: =Z33 -> 0
D34: 45544 | E34: EMPRESA Y | F34: 00.111.222/0001-24 | G34: S/A (Sociedade Anônima)Sociedade Anônima | H34: 4520-0/08 - Serviços de capotaria | I34: Carla | J34: Vendas | K34: Aprovado | M34: =IF(ISBLANK(D34), "", IFERROR(PROPER(TEXT(D34,"mmmm")),"")) -> Setembro | N34: =IF(H34="","",H34) -> 4520-0/08 - Serviços de capotaria | O34: =IFERROR(RIGHT(N34,LEN(N34)-SEARCH("- ",N34)-1),"") -> Serviços de capotaria | Q34: ='CNAE_Cód.Atividade Econômica'!B13 -> Manutenção e reparação de máquinas, aparelhos e materiais elétricos não especificados anteriormente | R34: =COUNTIF($O:$O,Q34) -> 0 | S34: =Q34 -> Manutenção e reparação de máquinas, aparelhos e materiais elétricos não especificados anteriormente | U34: =COUNTIF(R$10:R34,R34) -> 17 | V34: =R34&U34 -> 017 | W34: =INDEX($S$10:$S$401, MATCH(V34,$V$10:$V$1048576, 0)) -> Manutenção e reparação de máquinas, aparelhos e materiais elétricos não especificados anteriormente | Y34: 25 | Z34: =LARGE($R$10:$R$1048576,Y34) -> 0 | AA34: =INDEX(S$10:S$1000, MATCH(R34, R$10:R$1000, 0)) -> Guarda-móveis | AB34: =COUNTIF(R$10:R34,R34) -> 17 | AC34: =R34&U34 -> 017 | AD34: =INDEX($S$10:$S$1048576, MATCH(AC34, $V$10:$V$1048576, 0)) -> Manutenção e reparação de máquinas, aparelhos e materiais elétricos não especificados anteriormente | AE34: =Z34 -> 0
D35: 45545 | E35: EMPRESA Z | F35: 00.111.222/0001-25 | G35: LTDA (Sociedade Limitada) | H35: 4520-0/08 - Serviços de capotaria | I35: Carla | J35: Vendas | K35: Aprovado | M35: =IF(ISBLANK(D35), "", IFERROR(PROPER(TEXT(D35,"mmmm")),"")) -> Setembro | N35: =IF(H35="","",H35) -> 4520-0/08 - Serviços de capotaria | O35: =IFERROR(RIGHT(N35,LEN(N35)-SEARCH("- ",N35)-1),"") -> Serviços de capotaria | Q35: ='CNAE_Cód.Atividade Econômica'!B14 -> Manutenção e reparação de máquinas motrizes não-elétricas | R35: =COUNTIF($O:$O,Q35) -> 0 | S35: =Q35 -> Manutenção e reparação de máquinas motrizes não-elétricas | U35: =COUNTIF(R$10:R35,R35) -> 18 | V35: =R35&U35 -> 018 | W35: =INDEX($S$10:$S$401, MATCH(V35,$V$10:$V$1048576, 0)) -> Manutenção e reparação de máquinas motrizes não-elétricas | Y35: 26 | Z35: =LARGE($R$10:$R$1048576,Y35) -> 0 | AA35: =INDEX(S$10:S$1000, MATCH(R35, R$10:R$1000, 0)) -> Guarda-móveis | AB35: =COUNTIF(R$10:R35,R35) -> 18 | AC35: =R35&U35 -> 018 | AD35: =INDEX($S$10:$S$1048576, MATCH(AC35, $V$10:$V$1048576, 0)) -> Manutenção e reparação de máquinas motrizes não-elétricas | AE35: =Z35 -> 0
M36: =IF(ISBLANK(D36), "", IFERROR(PROPER(TEXT(D36,"mmmm")),"")) | N36: =IF(H36="","",H36) | O36: =IFERROR(RIGHT(N36,LEN(N36)-SEARCH("- ",N36)-1),"") | Q36: ='CNAE_Cód.Atividade Econômica'!B15 -> Manutenção e reparação de equipamentos hidráulicos e pneumáticos, exceto válvulas | R36: =COUNTIF($O:$O,Q36) -> 0 | S36: =Q36 -> Manutenção e reparação de equipamentos hidráulicos e pneumáticos, exceto válvulas | U36: =COUNTIF(R$10:R36,R36) -> 19 | V36: =R36&U36 -> 019 | W36: =INDEX($S$10:$S$401, MATCH(V36,$V$10:$V$1048576, 0)) -> Manutenção e reparação de equipamentos hidráulicos e pneumáticos, exceto válvulas | Y36: 27 | Z36: =LARGE($R$10:$R$1048576,Y36) -> 0 | AA36: =INDEX(S$10:S$1000, MATCH(R36, R$10:R$1000, 0)) -> Guarda-móveis | AB36: =COUNTIF(R$10:R36,R36) -> 19 | AC36: =R36&U36 -> 019 | AD36: =INDEX($S$10:$S$1048576, MATCH(AC36, $V$10:$V$1048576, 0)) -> Manutenção e reparação de equipamentos hidráulicos e pneumáticos, exceto válvulas | AE36: =Z36 -> 0
M37: =IF(ISBLANK(D37), "", IFERROR(PROPER(TEXT(D37,"mmmm")),"")) | N37: =IF(H37="","",H37) | O37: =IFERROR(RIGHT(N37,LEN(N37)-SEARCH("- ",N37)-1),"") | Q37: ='CNAE_Cód.Atividade Econômica'!B16 -> Manutenção e reparação de válvulas industriais | R37: =COUNTIF($O:$O,Q37) -> 0 | S37: =Q37 -> Manutenção e reparação de válvulas industriais | U37: =COUNTIF(R$10:R37,R37) -> 20 | V37: =R37&U37 -> 020 | W37: =INDEX($S$10:$S$401, MATCH(V37,$V$10:$V$1048576, 0)) -> Manutenção e reparação de válvulas industriais | Y37: 28 | Z37: =LARGE($R$10:$R$1048576,Y37) -> 0 | AA37: =INDEX(S$10:S$1000, MATCH(R37, R$10:R$1000, 0)) -> Guarda-móveis | AB37: =COUNTIF(R$10:R37,R37) -> 20 | AC37: =R37&U37 -> 020 | AD37: =INDEX($S$10:$S$1048576, MATCH(AC37, $V$10:$V$1048576, 0)) -> Manutenção e reparação de válvulas industriais | AE37: =Z37 -> 0
M38: =IF(ISBLANK(D38), "", IFERROR(PROPER(TEXT(D38,"mmmm")),"")) | N38: =IF(H38="","",H38) | O38: =IFERROR(RIGHT(N38,LEN(N38)-SEARCH("- ",N38)-1),"") | Q38: ='CNAE_Cód.Atividade Econômica'!B17 -> Manutenção e reparação de compressores | R38: =COUNTIF($O:$O,Q38) -> 0 | S38: =Q38 -> Manutenção e reparação de compressores | U38: =COUNTIF(R$10:R38,R38) -> 21 | V38: =R38&U38 -> 021 | W38: =INDEX($S$10:$S$401, MATCH(V38,$V$10:$V$1048576, 0)) -> Manutenção e reparação de compressores | Y38: 29 | Z38: =LARGE($R$10:$R$1048576,Y38) -> 0 | AA38: =INDEX(S$10:S$1000, MATCH(R38, R$10:R$1000, 0)) -> Guarda-móveis | AB38: =COUNTIF(R$10:R38,R38) -> 21 | AC38: =R38&U38 -> 021 | AD38: =INDEX($S$10:$S$1048576, MATCH(AC38, $V$10:$V$1048576, 0)) -> Manutenção e reparação de compressores | AE38: =Z38 -> 0
M39: =IF(ISBLANK(D39), "", IFERROR(PROPER(TEXT(D39,"mmmm")),"")) | N39: =IF(H39="","",H39) | O39: =IFERROR(RIGHT(N39,LEN(N39)-SEARCH("- ",N39)-1),"") | Q39: ='CNAE_Cód.Atividade Econômica'!B18 -> Manutenção e reparação de equipamentos de transmissão para fins industriais | R39: =COUNTIF($O:$O,Q39) -> 0 | S39: =Q39 -> Manutenção e reparação de equipamentos de transmissão para fins industriais | U39: =COUNTIF(R$10:R39,R39) -> 22 | V39: =R39&U39 -> 022 | W39: =INDEX($S$10:$S$401, MATCH(V39,$V$10:$V$1048576, 0)) -> Manutenção e reparação de equipamentos de transmissão para fins industriais | Y39: 30 | Z39: =LARGE($R$10:$R$1048576,Y39) -> 0 | AA39: =INDEX(S$10:S$1000, MATCH(R39, R$10:R$1000, 0)) -> Guarda-móveis | AB39: =COUNTIF(R$10:R39,R39) -> 22 | AC39: =R39&U39 -> 022 | AD39: =INDEX($S$10:$S$1048576, MATCH(AC39, $V$10:$V$1048576, 0)) -> Manutenção e reparação de equipamentos de transmissão para fins industriais | AE39: =Z39 -> 0
M40: =IF(ISBLANK(D40), "", IFERROR(PROPER(TEXT(D40,"mmmm")),"")) | N40: =IF(H40="","",H40) | O40: =IFERROR(RIGHT(N40,LEN(N40)-SEARCH("- ",N40)-1),"") | Q40: ='CNAE_Cód.Atividade Econômica'!B19 -> Manutenção e reparação de máquinas, aparelhos e equipamentos para instalações térmicas | R40: =COUNTIF($O:$O,Q40) -> 0 | S40: =Q40 -> Manutenção e reparação de máquinas, aparelhos e equipamentos para instalações térmicas | U40: =COUNTIF(R$10:R40,R40) -> 23 | V40: =R40&U40 -> 023 | W40: =INDEX($S$10:$S$401, MATCH(V40,$V$10:$V$1048576, 0)) -> Manutenção e reparação de máquinas, aparelhos e equipamentos para instalações térmicas | Y40: 31 | Z40: =LARGE($R$10:$R$1048576,Y40) -> 0 | AA40: =INDEX(S$10:S$1000, MATCH(R40, R$10:R$1000, 0)) -> Guarda-móveis | AB40: =COUNTIF(R$10:R40,R40) -> 23 | AC40: =R40&U40 -> 023 | AD40: =INDEX($S$10:$S$1048576, MATCH(AC40, $V$10:$V$1048576, 0)) -> Manutenção e reparação de máquinas, aparelhos e equipamentos para instalações térmicas | AE40: =Z40 -> 0
M41: =IF(ISBLANK(D41), "", IFERROR(PROPER(TEXT(D41,"mmmm")),"")) | N41: =IF(H41="","",H41) | O41: =IFERROR(RIGHT(N41,LEN(N41)-SEARCH("- ",N41)-1),"") | Q41: ='CNAE_Cód.Atividade Econômica'!B20 -> Manutenção e reparação de máquinas e aparelhos de refrigeração e ventilação para uso industrial e comercial | R41: =COUNTIF($O:$O,Q41) -> 0 | S41: =Q41 -> Manutenção e reparação de máquinas e aparelhos de refrigeração e ventilação para uso industrial e comercial | U41: =COUNTIF(R$10:R41,R41) -> 24 | V41: =R41&U41 -> 024 | W41: =INDEX($S$10:$S$401, MATCH(V41,$V$10:$V$1048576, 0)) -> Manutenção e reparação de máquinas e aparelhos de refrigeração e ventilação para uso industrial e comercial | Y41: 32 | Z41: =LARGE($R$10:$R$1048576,Y41) -> 0 | AA41: =INDEX(S$10:S$1000, MATCH(R41, R$10:R$1000, 0)) -> Guarda-móveis | AB41: =COUNTIF(R$10:R41,R41) -> 24 | AC41: =R41&U41 -> 024 | AD41: =INDEX($S$10:$S$1048576, MATCH(AC41, $V$10:$V$1048576, 0)) -> Manutenção e reparação de máquinas e aparelhos de refrigeração e ventilação para uso industrial e comercial | AE41: =Z41 -> 0
M42: =IF(ISBLANK(D42), "", IFERROR(PROPER(TEXT(D42,"mmmm")),"")) | N42: =IF(H42="","",H42) | O42: =IFERROR(RIGHT(N42,LEN(N42)-SEARCH("- ",N42)-1),"") | Q42: ='CNAE_Cód.Atividade Econômica'!B21 -> Manutenção e reparação de máquinas, equipamentos e aparelhos para transporte e elevação de cargas | R42: =COUNTIF($O:$O,Q42) -> 0 | S42: =Q42 -> Manutenção e reparação de máquinas, equipamentos e aparelhos para transporte e elevação de cargas | U42: =COUNTIF(R$10:R42,R42) -> 25 | V42: =R42&U42 -> 025 | W42: =INDEX($S$10:$S$401, MATCH(V42,$V$10:$V$1048576, 0)) -> Manutenção e reparação de máquinas, equipamentos e aparelhos para transporte e elevação de cargas | Y42: 33 | Z42: =LARGE($R$10:$R$1048576,Y42) -> 0 | AA42: =INDEX(S$10:S$1000, MATCH(R42, R$10:R$1000, 0)) -> Guarda-móveis | AB42: =COUNTIF(R$10:R42,R42) -> 25 | AC42: =R42&U42 -> 025 | AD42: =INDEX($S$10:$S$1048576, MATCH(AC42, $V$10:$V$1048576, 0)) -> Manutenção e reparação de máquinas, equipamentos e aparelhos para transporte e elevação de cargas | AE42: =Z42 -> 0
M43: =IF(ISBLANK(D43), "", IFERROR(PROPER(TEXT(D43,"mmmm")),"")) | N43: =IF(H43="","",H43) | O43: =IFERROR(RIGHT(N43,LEN(N43)-SEARCH("- ",N43)-1),"") | Q43: ='CNAE_Cód.Atividade Econômica'!B22 -> Manutenção e reparação de máquinas de escrever, calcular e de outros equipamentos não-eletrônicos para escritório | R43: =COUNTIF($O:$O,Q43) -> 0 | S43: =Q43 -> Manutenção e reparação de máquinas de escrever, calcular e de outros equipamentos não-eletrônicos para escritório | U43: =COUNTIF(R$10:R43,R43) -> 26 | V43: =R43&U43 -> 026 | W43: =INDEX($S$10:$S$401, MATCH(V43,$V$10:$V$1048576, 0)) -> Manutenção e reparação de máquinas de escrever, calcular e de outros equipamentos não-eletrônicos para escritório | Y43: 34 | Z43: =LARGE($R$10:$R$1048576,Y43) -> 0 | AA43: =INDEX(S$10:S$1000, MATCH(R43, R$10:R$1000, 0)) -> Guarda-móveis | AB43: =COUNTIF(R$10:R43,R43) -> 26 | AC43: =R43&U43 -> 026 | AD43: =INDEX($S$10:$S$1048576, MATCH(AC43, $V$10:$V$1048576, 0)) -> Manutenção e reparação de máquinas de escrever, calcular e de outros equipamentos não-eletrônicos para escritório | AE43: =Z43 -> 0
M44: =IF(ISBLANK(D44), "", IFERROR(PROPER(TEXT(D44,"mmmm")),"")) | N44: =IF(H44="","",H44) | O44: =IFERROR(RIGHT(N44,LEN(N44)-SEARCH("- ",N44)-1),"") | Q44: ='CNAE_Cód.Atividade Econômica'!B23 -> Manutenção e reparação de máquinas e equipamentos para uso geral não especificados anteriormente | R44: =COUNTIF($O:$O,Q44) -> 0 | S44: =Q44 -> Manutenção e reparação de máquinas e equipamentos para uso geral não especificados anteriormente | U44: =COUNTIF(R$10:R44,R44) -> 27 | V44: =R44&U44 -> 027 | W44: =INDEX($S$10:$S$401, MATCH(V44,$V$10:$V$1048576, 0)) -> Manutenção e reparação de máquinas e equipamentos para uso geral não especificados anteriormente | Y44: 35 | Z44: =LARGE($R$10:$R$1048576,Y44) -> 0 | AA44: =INDEX(S$10:S$1000, MATCH(R44, R$10:R$1000, 0)) -> Guarda-móveis | AB44: =COUNTIF(R$10:R44,R44) -> 27 | AC44: =R44&U44 -> 027 | AD44: =INDEX($S$10:$S$1048576, MATCH(AC44, $V$10:$V$1048576, 0)) -> Manutenção e reparação de máquinas e equipamentos para uso geral não especificados anteriormente | AE44: =Z44 -> 0
...

Sheet ANÁLISE SERASA
A1: ANÁLISE DE CRÉDITO
B5: DECISÃO NA ANÁLISE DE CRÉDITO | C5: =_xlfn.IFS(B25="REPROVADO","REPROVADO",B44="REPROVADO","REPROVADO",B53="REPROVADO","REPROVADO",B34="REPROVADO","REPROVADO",B58="REPROVADO","REPROVADO",B68="RISCO ALTO","REPROVADO",B68="RISCO MÉDIO","ANÁLISE DA DIRETORIA",B68="BAIXO RISCO","APROVADO") -> REPROVADO
B7: LIBERAÇÃO DO FINANCEIRO | C7: EM ANÁLISE
B9: SOLICITAÇÃO
B11: DATA DE ANÁLISE | C11: =TODAY() -> 45738
B12: SETOR/ SOLICITANTE | C12: Departamento de Crédito/Análise de Crédito
B13: OBSERVAÇÃO | C13: Potencial Cliente do Segmento Agronegócio
E14: Critérios
B15: DADOS CADASTRAIS DA EMPRESA
B17: CNPJ /CPF | C17: 00.111.222/0001-00 | E17: -
B18: DATA ABERTURA | C18: 43831 | E18: =IF(ISBLANK(C18),"",IF(TODAY()-C18>=5*365,"APROVADO","REPROVADO")) -> APROVADO
B19: NOME EMPRESARIAL | C19: Artigos de Radioterapia | E19: -
B20: CÓDIGO E DESCRIÇÃO DA ATIVIDADE ECONÔMICA PRINCIPAL | C20: 161-0/03 - Serviço de preparação de terreno, cultivo e colheita | E20: -
B21: CÓDIGO E DESCRIÇÃO DA NATUREZA JURÍDICA | C21: 206-2 | E21: =IF(VLOOKUP(C21,'Tabela de Natureza Jurídica '!A:C,3,0)="Entidades empresariais","APROVADO","REPROVADO") -> APROVADO
B22: ENDEREÇO ELETRÔNICO | C22: teste@teste.com.br | E22: =IF(ISBLANK(C22),"","APROVADO") -> APROVADO
B23: DOMINIO EMPRESARIAL | C23: Sim | E23: =IF(C23="SIM","APROVADO",IF(C23="NÃO","REPROVADO","")) -> APROVADO
B24: SITUAÇÃO CADASTRAL | C24: Ativa | E24: =IF(C24="ATIVA","APROVADO",IF(C23="NÃO","REPROVADO","")) -> APROVADO
B25: =IF(OR(E18="",E21="",E22="",E23="",E24=""),"",IF(OR(E18="REPROVADO",E21="REPROVADO",E22="REPROVADO",E23="REPROVADO",E24="REPROVADO"),"REPROVADO","ANALISAR SERASA")) -> ANALISAR SERASA | E25: -
B27: PENDÊNCIAS (INTERNA) E LIMITE DE INADIMPLÊNCIA
B29: CONTAS A RECEBER PENDENTES (A Vencer) | C29: Sim | E29: -
B30: COTAS A RECEBER EM ATRASO | C30: Não | E30: =IF(C30="SIM","REPROVADO",IF(C30="NÃO","APROVADO","")) -> APROVADO
B31: LIMITE DE INADIMPLÊNCIA EM VALOR | C31: 0 | E31: =IF(C31=0,"APROVADO",IF(C31>1000,"REPROVADO","ANALISAR PENDÊNCIA")) -> APROVADO
B32: DIAS EM ATRASO | C32: 0 | D32: =IF(C32=1, "Venceu! Faz 1 dia, atenção leve", IF(C32=2, "Venceu!Faz 2 dias, atenção moderada", IF(C32=3, "Venceu! Faz 3 dias, atenção urgente", IF(C32>3, "Venceu! Faz "&C32&" dias, por gentileza verificar!", "Em dia!!!")))) -> Em dia!!! | E32: =IF(C32>0,"REPROVADO",IF(C32=0,"APROVADO")) -> APROVADO
B33: CONTAS A RECEBER COM + DE 30 DIAS EM ATRASO | C33: 0 | D33: =IF(C33>30, "Atenção Imediata, Elegibilidade para Negativação:", "Dentro do prazo!!!") -> Dentro do prazo!!! | E33: =IF(C33=0, "APROVADO", "REPROVADO") -> APROVADO
B34: =IF(OR(E30="REPROVADO",E31="REPROVADO",E32="REPROVADO",E33="REPROVADO"),"REPROVADO","APROVADO") -> APROVADO | E34: -
B36: SERASA
B38: PENDÊNCIAS FINANCEIRAS | C38: Não | E38: =IF(ISBLANK(C38),"",IF(C38="NÃO","LIBERADO","REPROVADO")) -> LIBERADO
B39: PROTESTOS | C39: Não | E39: =IF(ISBLANK(C39),"",IF(C39="NÃO","LIBERADO","REPROVADO")) -> LIBERADO
B40: CHEQUES SEM FUNDO | C40: Não | E40: =IF(ISBLANK(C40),"",IF(C40="NÃO","LIBERADO","REPROVADO")) -> LIBERADO
B41: AÇÕES JUDICIAIS | C41: Não | E41: =IF(ISBLANK(C41),"",IF(C41="NÃO","LIBERADO","REPROVADO")) -> LIBERADO
B42: PARTICIPAÇÃO EM FALÊNCIAS | C42: Não | E42: =IF(ISBLANK(C42),"",IF(C42="NÃO","LIBERADO","REPROVADO")) -> LIBERADO
B43: FALÊNCIA/CONCORDARA/RECUPERAÇÃO JUDICIAL | C43: Não | E43: =IF(ISBLANK(C43),"",IF(C43="NÃO","LIBERADO","REPROVADO")) -> LIBERADO
B44: =IF(SUMPRODUCT((E38:E43="REPROVADO")*1)>0,"ANALISAR PENDÊNCIA",IF(SUMPRODUCT((E38:E43="LIBERADO")*1)>0,"ANALISAR RISCO","")) -> ANALISAR RISCO | E44: -
B46: DETALHAMENTO DAS PÊNDENCIAS
B48: VALOR TOTAL | C48: 0 | E48: =IF((C48/C67)<1%,"LIBERADO","REPROVADO") -> LIBERADO
B49: QUANTIDADE | C49: 0 | E49: =IF(C49<=3,"LIBERADO","REPROVADO") -> LIBERADO
B50: DATA DA INCLUSÃO | C50: 0 | E50: -
B51: SEGMENTO DA INCLUSÃO | C51: TELEFONIA | E51: =IF(C51="LOJA","REPROVADO","LIBERADO") -> LIBERADO
B52: NO CASO DE OUTROS DESCREVER | E52: -
B53: =IF(OR(E48="REPROVADO",E49="REPROVADO",E51="REPROVADO"),"REPROVADO","ANALISAR RISCO") -> ANALISAR RISCO | E53: -
...

Sheet RELATÓRIO DE CONSULTAS - SERASA
A1: RELATÓRIO DE CONSULTAS - SERASA
C5: Janeiro | D5: Fevereiro | E5: Março | F5: Abril | G5: Maio | H5: Junho | I5: Julho | J5: Agosto | K5: Setembro | L5: Outubro | M5: Novembro | N5: Dezembro | O5: TOTAL | Q5: Média de consultas Anual
B6: ME (Microempresa) | C6: =COUNTIFS('CONTROLE DIÁRIO DE CONSULTAS'!$G$10:$G$1048576,$B$6,'CONTROLE DIÁRIO DE CONSULTAS'!$M$10:$M$1048576, C5) -> 1 | D6: =COUNTIFS('CONTROLE DIÁRIO DE CONSULTAS'!$G$10:$G$1048576,'RELATÓRIO DE CONSULTAS - SERASA'!$B$6,'CONTROLE DIÁRIO DE CONSULTAS'!$M$10:$M$1048576, D5) -> 0 | E6: =COUNTIFS('CONTROLE DIÁRIO DE CONSULTAS'!$G$10:$G$1048576,'RELATÓRIO DE CONSULTAS - SERASA'!$B$6,'CONTROLE DIÁRIO DE CONSULTAS'!$M$10:$M$1048576, E5) -> 0 | F6: =COUNTIFS('CONTROLE DIÁRIO DE CONSULTAS'!$G$10:$G$1048576,'RELATÓRIO DE CONSULTAS - SERASA'!$B$6,'CONTROLE DIÁRIO DE CONSULTAS'!$M$10:$M$1048576, F5) -> 0 | G6: =COUNTIFS('CONTROLE DIÁRIO DE CONSULTAS'!$G$10:$G$1048576,'RELATÓRIO DE CONSULTAS - SERASA'!$B$6,'CONTROLE DIÁRIO DE CONSULTAS'!$M$10:$M$1048576, G5) -> 0 | H6: =COUNTIFS('CONTROLE DIÁRIO DE CONSULTAS'!$G$10:$G$1048576,'RELATÓRIO DE CONSULTAS - SERASA'!$B$6,'CONTROLE DIÁRIO DE CONSULTAS'!$M$10:$M$1048576, H5) -> 0 | I6: =COUNTIFS('CONTROLE DIÁRIO DE CONSULTAS'!$G$10:$G$1048576,'RELATÓRIO DE CONSULTAS - SERASA'!$B$6,'CONTROLE DIÁRIO DE CONSULTAS'!$M$10:$M$1048576, I5) -> 0 | J6: =COUNTIFS('CONTROLE DIÁRIO DE CONSULTAS'!$G$10:$G$1048576,'RELATÓRIO DE CONSULTAS - SERASA'!$B$6,'CONTROLE DIÁRIO DE CONSULTAS'!$M$10:$M$1048576, J5) -> 0 | K6: =COUNTIFS('CONTROLE DIÁRIO DE CONSULTAS'!$G$10:$G$1048576,'RELATÓRIO DE CONSULTAS - SERASA'!$B$6,'CONTROLE DIÁRIO DE CONSULTAS'!$M$10:$M$1048576, K5) -> 0 | ... N6: =COUNTIFS('CONTROLE DIÁRIO DE CONSULTAS'!$G$10:$G$1048576,'RELATÓRIO DE CONSULTAS - SERASA'!$B$6,'CONTROLE DIÁRIO DE CONSULTAS'!$M$10:$M$1048576, N5) -> 0 | O6: =SUM($C$6:$N$6) -> 1 | Q6: =AVERAGE($O$13/12) -> 2.1666667
B7: MEI (Microempreendedor Individual) | C7: =COUNTIFS('CONTROLE DIÁRIO DE CONSULTAS'!$G$10:$G$1048576,$B$7,'CONTROLE DIÁRIO DE CONSULTAS'!$M$10:$M$1048576, C5) -> 0 | D7: =COUNTIFS('CONTROLE DIÁRIO DE CONSULTAS'!$G$10:$G$1048576,$B$7,'CONTROLE DIÁRIO DE CONSULTAS'!$M$10:$M$1048576, D5) -> 5 | E7: =COUNTIFS('CONTROLE DIÁRIO DE CONSULTAS'!$G$10:$G$1048576,$B$7,'CONTROLE DIÁRIO DE CONSULTAS'!$M$10:$M$1048576, E5) -> 0 | F7: =COUNTIFS('CONTROLE DIÁRIO DE CONSULTAS'!$G$10:$G$1048576,$B$7,'CONTROLE DIÁRIO DE CONSULTAS'!$M$10:$M$1048576, F5) -> 0 | G7: =COUNTIFS('CONTROLE DIÁRIO DE CONSULTAS'!$G$10:$G$1048576,$B$7,'CONTROLE DIÁRIO DE CONSULTAS'!$M$10:$M$1048576, G5) -> 0 | H7: =COUNTIFS('CONTROLE DIÁRIO DE CONSULTAS'!$G$10:$G$1048576,$B$7,'CONTROLE DIÁRIO DE CONSULTAS'!$M$10:$M$1048576, H5) -> 0 | I7: =COUNTIFS('CONTROLE DIÁRIO DE CONSULTAS'!$G$10:$G$1048576,$B$7,'CONTROLE DIÁRIO DE CONSULTAS'!$M$10:$M$1048576, I5) -> 0 | J7: =COUNTIFS('CONTROLE DIÁRIO DE CONSULTAS'!$G$10:$G$1048576,$B$7,'CONTROLE DIÁRIO DE CONSULTAS'!$M$10:$M$1048576, J5) -> 0 | ... N7: =COUNTIFS('CONTROLE DIÁRIO DE CONSULTAS'!$G$10:$G$1048576,$B$7,'CONTROLE DIÁRIO DE CONSULTAS'!$M$10:$M$1048576, N5) -> 0 | O7: =SUM($C$7:$N$7) -> 5 | Q7: =AVERAGE($O$13/12) -> 2.1666667
B8: EPP (Empresa de Pequeno Porte) | C8: =COUNTIFS('CONTROLE DIÁRIO DE CONSULTAS'!$G$10:$G$1048576,$B$8,'CONTROLE DIÁRIO DE CONSULTAS'!$M$10:$M$1048576, C5) -> 1 | D8: =COUNTIFS('CONTROLE DIÁRIO DE CONSULTAS'!$G$10:$G$1048576,$B$8,'CONTROLE DIÁRIO DE CONSULTAS'!$M$10:$M$1048576, D5) -> 0 | E8: =COUNTIFS('CONTROLE DIÁRIO DE CONSULTAS'!$G$10:$G$1048576,$B$8,'CONTROLE DIÁRIO DE CONSULTAS'!$M$10:$M$1048576, E5) -> 2 | F8: =COUNTIFS('CONTROLE DIÁRIO DE CONSULTAS'!$G$10:$G$1048576,$B$8,'CONTROLE DIÁRIO DE CONSULTAS'!$M$10:$M$1048576, F5) -> 2 | G8: =COUNTIFS('CONTROLE DIÁRIO DE CONSULTAS'!$G$10:$G$1048576,$B$8,'CONTROLE DIÁRIO DE CONSULTAS'!$M$10:$M$1048576, G5) -> 0 | H8: =COUNTIFS('CONTROLE DIÁRIO DE CONSULTAS'!$G$10:$G$1048576,$B$8,'CONTROLE DIÁRIO DE CONSULTAS'!$M$10:$M$1048576, H5) -> 2 | I8: =COUNTIFS('CONTROLE DIÁRIO DE CONSULTAS'!$G$10:$G$1048576,$B$8,'CONTROLE DIÁRIO DE CONSULTAS'!$M$10:$M$1048576, I5) -> 2 | J8: =COUNTIFS('CONTROLE DIÁRIO DE CONSULTAS'!$G$10:$G$1048576,$B$8,'CONTROLE DIÁRIO DE CONSULTAS'!$M$10:$M$1048576, J5) -> 0 | ... N8: =COUNTIFS('CONTROLE DIÁRIO DE CONSULTAS'!$G$10:$G$1048576,$B$8,'CONTROLE DIÁRIO DE CONSULTAS'!$M$10:$M$1048576, N5) -> 0 | O8: =SUM(C8:N8) -> 9 | Q8: =AVERAGE($O$13/12) -> 2.1666667
B9: LTDA (Sociedade Limitada) | C9: =COUNTIFS('CONTROLE DIÁRIO DE CONSULTAS'!$G$10:$G$1048576,$B$9,'CONTROLE DIÁRIO DE CONSULTAS'!$M$10:$M$1048576, C5) -> 0 | D9: =COUNTIFS('CONTROLE DIÁRIO DE CONSULTAS'!$G$10:$G$1048576,$B$9,'CONTROLE DIÁRIO DE CONSULTAS'!$M$10:$M$1048576, D5) -> 0 | E9: =COUNTIFS('CONTROLE DIÁRIO DE CONSULTAS'!$G$10:$G$1048576,$B$9,'CONTROLE DIÁRIO DE CONSULTAS'!$M$10:$M$1048576, E5) -> 0 | F9: =COUNTIFS('CONTROLE DIÁRIO DE CONSULTAS'!$G$10:$G$1048576,$B$9,'CONTROLE DIÁRIO DE CONSULTAS'!$M$10:$M$1048576, F5) -> 0 | G9: =COUNTIFS('CONTROLE DIÁRIO DE CONSULTAS'!$G$10:$G$1048576,$B$9,'CONTROLE DIÁRIO DE CONSULTAS'!$M$10:$M$1048576, G5) -> 4 | H9: =COUNTIFS('CONTROLE DIÁRIO DE CONSULTAS'!$G$10:$G$1048576,$B$9,'CONTROLE DIÁRIO DE CONSULTAS'!$M$10:$M$1048576, H5) -> 0 | I9: =COUNTIFS('CONTROLE DIÁRIO DE CONSULTAS'!$G$10:$G$1048576,$B$9,'CONTROLE DIÁRIO DE CONSULTAS'!$M$10:$M$1048576, I5) -> 0 | J9: =COUNTIFS('CONTROLE DIÁRIO DE CONSULTAS'!$G$10:$G$1048576,$B$9,'CONTROLE DIÁRIO DE CONSULTAS'!$M$10:$M$1048576, J5) -> 0 | ... N9: =COUNTIFS('CONTROLE DIÁRIO DE CONSULTAS'!$G$10:$G$1048576,$B$9,'CONTROLE DIÁRIO DE CONSULTAS'!$M$10:$M$1048576, N5) -> 0 | O9: =SUM(C9:N9) -> 5 | Q9: =AVERAGE($O$13/12) -> 2.1666667
B10: S/A (Sociedade Anônima) | C10: =COUNTIFS('CONTROLE DIÁRIO DE CONSULTAS'!G10:G1048576,$B$10,'CONTROLE DIÁRIO DE CONSULTAS'!$M$10:$M$1048576, C5) -> 2 | D10: =COUNTIFS('CONTROLE DIÁRIO DE CONSULTAS'!$G$10:$G$1048576,$B$10,'CONTROLE DIÁRIO DE CONSULTAS'!$M$10:$M$1048576, D5) -> 0 | E10: =COUNTIFS('CONTROLE DIÁRIO DE CONSULTAS'!$G$10:$G$1048576,$B$10,'CONTROLE DIÁRIO DE CONSULTAS'!$M$10:$M$1048576, E5) -> 0 | F10: =COUNTIFS('CONTROLE DIÁRIO DE CONSULTAS'!$G$10:$G$1048576,$B$10,'CONTROLE DIÁRIO DE CONSULTAS'!$M$10:$M$1048576, F5) -> 0 | G10: =COUNTIFS('CONTROLE DIÁRIO DE CONSULTAS'!$G$10:$G$1048576,$B$10,'CONTROLE DIÁRIO DE CONSULTAS'!$M$10:$M$1048576, G5) -> 0 | H10: =COUNTIFS('CONTROLE DIÁRIO DE CONSULTAS'!$G$10:$G$1048576,$B$10,'CONTROLE DIÁRIO DE CONSULTAS'!$M$10:$M$1048576, H5) -> 0 | I10: =COUNTIFS('CONTROLE DIÁRIO DE CONSULTAS'!$G$10:$G$1048576,$B$10,'CONTROLE DIÁRIO DE CONSULTAS'!$M$10:$M$1048576, I5) -> 0 | J10: =COUNTIFS('CONTROLE DIÁRIO DE CONSULTAS'!$G$10:$G$1048576,$B$10,'CONTROLE DIÁRIO DE CONSULTAS'!$M$10:$M$1048576, J5) -> 0 | K10: =COUNTIFS('CONTROLE DIÁRIO DE CONSULTAS'!$G$10:$G$1048576,$B$10,'CONTROLE DIÁRIO DE CONSULTAS'!$M$10:$M$1048576, K5) -> 0 | ... N10: =COUNTIFS('CONTROLE DIÁRIO DE CONSULTAS'!$G$10:$G$1048576,$B$10,'CONTROLE DIÁRIO DE CONSULTAS'!$M$10:$M$1048576, N5) -> 0 | O10: =SUM(C10:N10) -> 2 | Q10: =AVERAGE($O$13/12) -> 2.1666667
B11: Sociedade Anônima | C11: =COUNTIFS('CONTROLE DIÁRIO DE CONSULTAS'!$G$10:$G$1048576,$B$11,'CONTROLE DIÁRIO DE CONSULTAS'!$M$10:$M$1048576, C5) -> 0 | D11: =COUNTIFS('CONTROLE DIÁRIO DE CONSULTAS'!$G$10:$G$1048576,$B$11,'CONTROLE DIÁRIO DE CONSULTAS'!$M$10:$M$1048576, D5) -> 0 | E11: =COUNTIFS('CONTROLE DIÁRIO DE CONSULTAS'!$G$10:$G$1048576,$B$11,'CONTROLE DIÁRIO DE CONSULTAS'!$M$10:$M$1048576, E5) -> 0 | F11: =COUNTIFS('CONTROLE DIÁRIO DE CONSULTAS'!$G$10:$G$1048576,$B$11,'CONTROLE DIÁRIO DE CONSULTAS'!$M$10:$M$1048576, F5) -> 0 | G11: =COUNTIFS('CONTROLE DIÁRIO DE CONSULTAS'!$G$10:$G$1048576,$B$11,'CONTROLE DIÁRIO DE CONSULTAS'!$M$10:$M$1048576, G5) -> 0 | H11: =COUNTIFS('CONTROLE DIÁRIO DE CONSULTAS'!$G$10:$G$1048576,$B$11,'CONTROLE DIÁRIO DE CONSULTAS'!$M$10:$M$1048576, H5) -> 0 | I11: =COUNTIFS('CONTROLE DIÁRIO DE CONSULTAS'!$G$10:$G$1048576,$B$11,'CONTROLE DIÁRIO DE CONSULTAS'!$M$10:$M$1048576, I5) -> 0 | J11: =COUNTIFS('CONTROLE DIÁRIO DE CONSULTAS'!$G$10:$G$1048576,$B$11,'CONTROLE DIÁRIO DE CONSULTAS'!$M$10:$M$1048576, J5) -> 0 | ... N11: =COUNTIFS('CONTROLE DIÁRIO DE CONSULTAS'!$G$10:$G$1048576,$B$11,'CONTROLE DIÁRIO DE CONSULTAS'!$M$10:$M$1048576, N5) -> 0 | O11: =SUM(C11:N11) -> 0 | Q11: =AVERAGE($O$13/12) -> 2.1666667
B12: PF (Pessoa Física) | C12: =COUNTIFS('CONTROLE DIÁRIO DE CONSULTAS'!$G$10:$G$1048576,$B$12,'CONTROLE DIÁRIO DE CONSULTAS'!$M$10:$M$1048576, C5) -> 0 | D12: =COUNTIFS('CONTROLE DIÁRIO DE CONSULTAS'!$G$10:$G$1048576,$B$12,'CONTROLE DIÁRIO DE CONSULTAS'!$M$10:$M$1048576, D5) -> 0 | E12: =COUNTIFS('CONTROLE DIÁRIO DE CONSULTAS'!$G$10:$G$1048576,$B$12,'CONTROLE DIÁRIO DE CONSULTAS'!$M$10:$M$1048576, E5) -> 0 | F12: =COUNTIFS('CONTROLE DIÁRIO DE CONSULTAS'!$G$10:$G$1048576,$B$12,'CONTROLE DIÁRIO DE CONSULTAS'!$M$10:$M$1048576, F5) -> 0 | G12: =COUNTIFS('CONTROLE DIÁRIO DE CONSULTAS'!$G$10:$G$1048576,$B$12,'CONTROLE DIÁRIO DE CONSULTAS'!$M$10:$M$1048576, G5) -> 0 | H12: =COUNTIFS('CONTROLE DIÁRIO DE CONSULTAS'!$G$10:$G$1048576,$B$12,'CONTROLE DIÁRIO DE CONSULTAS'!$M$10:$M$1048576, H5) -> 0 | I12: =COUNTIFS('CONTROLE DIÁRIO DE CONSULTAS'!$G$10:$G$1048576,$B$12,'CONTROLE DIÁRIO DE CONSULTAS'!$M$10:$M$1048576, I5) -> 0 | J12: =COUNTIFS('CONTROLE DIÁRIO DE CONSULTAS'!$G$10:$G$1048576,$B$12,'CONTROLE DIÁRIO DE CONSULTAS'!$M$10:$M$1048576, J5) -> 0 | ... N12: =COUNTIFS('CONTROLE DIÁRIO DE CONSULTAS'!$G$10:$G$1048576,$B$12,'CONTROLE DIÁRIO DE CONSULTAS'!$M$10:$M$1048576, N5) -> 0 | O12: =SUM(C12:N12) -> 0 | Q12: =AVERAGE($O$13/12) -> 2.1666667
